Workbook

Sheet Resumo
B1: ="SIMULAÇÃO RATEIO FIXO — "&Premissas!$B$13&" × COPASUL | Resumo Executivo" -> SIMULAÇÃO RATEIO FIXO — Cassilândia 03 × COPASUL | Resumo Executivo
B2: ="18 Unidades Consumidoras · Jun/2026–Mai/2031 · Energisa MS · Usina: "&Premissas!$B$13 -> 18 Unidades Consumidoras · Jun/2026–Mai/2031 · Energisa MS · Usina: Cassilândia 03
B4: ⚡ GERAÇÃO INJETADA | D4: 📄 PPA PAGO À HELEXIA | F4: ✅ ECONOMIA LÍQUIDA | H4: 🏦 BANCO RESIDUAL | J4: 🌟 VALOR TOTAL
B5: =Simulacao!B6/1000000 -> 8.3804424 | D5: =Simulacao!B7 -> 3708345.8 | F5: =Simulacao!B252 -> 1930957.3 | H5: =Simulacao!B273*Premissas!$B$17 -> 396994.51 | J5: =Simulacao!B278 -> 2296874.3
B6: 3,375 MWh injetados em 60 meses | D6: Custo total do contrato PPA | F6: Rede evitada menos PPA pago | H6: Banco total Copasul @ PPA | J6: Economia + banco ATRIBUÍVEL a Helexia
B8: A. CUSTO COPASUL — ANÁLISE 24 MESES | I8: B. INDICADORES-CHAVE
B9: COMPONENTE | E9: R$ | F9: % | G9: R$/mês | I9: Usina contratada | K9: =Premissas!$B$13 -> Cassilândia 03
B10: Custo SEM Helexia — baseline 60m | E10: =Simulacao!B249 -> 6111913.8 | F10: =Simulacao!B249/Simulacao!B249 -> 1 | G10: =(Simulacao!B249)/60 -> 101865.23 | I10: Período do contrato | K10: Jun/2026 – Mai/2031 (60 meses)
B11: Custo rede remanescente (COM Helexia) | E11: =Simulacao!B250 -> 472610.77 | F11: =Simulacao!B250/Simulacao!B249 -> 0.077326151 | G11: =(Simulacao!B250)/60 -> 7876.8461 | I11: Potência contratada | K11: =VLOOKUP(Premissas!$B$13,PVSYST_Helexia!$B$5:$F$7,5,0)&" kWac" -> 625 kWac
B12: PPA pago à Helexia | E12: =Simulacao!B7 -> 3708345.8 | F12: =Simulacao!B7/Simulacao!B249 -> 0.60674052 | G12: =(Simulacao!B7)/60 -> 61805.763 | I12: Geração P50 total | K12: =Simulacao!B6/1000 -> 8380.4424
B13: Custo total COM Helexia (rede + PPA) | E13: =Simulacao!B251 -> 4180956.5 | F13: =Simulacao!B251/Simulacao!B249 -> 0.68406667 | G13: =(Simulacao!B251)/60 -> 69682.609 | I13: PPA (R$/kWh) | K13: =Premissas!$B$17 -> 0.4425
B14: ★ ECONOMIA LÍQUIDA (rede − PPA) | E14: =Simulacao!B252 -> 1930957.3 | F14: =Simulacao!B252/Simulacao!B249 -> 0.31593333 | G14: =(Simulacao!B252)/60 -> 32182.621 | I14: Tarifa Grupo A FP | K14: =Premissas!$B$5 -> 0.52647111
B15: + Banco atribuível Helexia @ PPA (net NHS/AMD + Grupo B) | E15: =Simulacao!B285 -> 365917.04 | F15: =IFERROR(Simulacao!B285/Simulacao!B249,0) -> 0.059869471 | G15: =Simulacao!B285/60 -> 6098.6174 | I15: Tarifa Grupo B3 | K15: =Premissas!$B$7 -> 1.1568636
B16: ★ VALOR TOTAL HELEXIA (economia + banco atribuível) | E16: =Simulacao!B278 -> 2296874.3 | F16: =Simulacao!B278/Simulacao!B249 -> 0.3758028 | G16: =(Simulacao!B278)/60 -> 38281.238 | I16: Economia média/mês | K16: =Simulacao!B252/60 -> 32182.621
I17: % redução custo Copasul | K17: =IFERROR(Simulacao!B252/Simulacao!B249,0) -> 0.31593333
I18: Banco residual (kWh) | K18: =Simulacao!B273 -> 897162.74
B20: C. ANÁLISE VISUAL — ECONOMIA E BANCO DE CRÉDITOS
P22: Mês | Q22: SEM Helexia | R22: PPA | S22: Rede COM | T22: Eco mensal | U22: Eco acumulada
P23: Jun/26 | Q23: =Simulacao!D249 -> 29915.013 | R23: =Simulacao!D7 -> 54865.575 | S23: =Simulacao!D250 -> 2940.4293 | T23: =Simulacao!D252 -> -27890.991 | U23: =T23 -> -27890.991
P24: Jul/26 | Q24: =Simulacao!E249 -> 231390.51 | R24: =Simulacao!E7 -> 57750.675 | S24: =Simulacao!E250 -> 82568.136 | T24: =Simulacao!E252 -> 91071.696 | U24: =U23+T24 -> 63180.705
P25: Ago/26 | Q25: =Simulacao!F249 -> 156547.56 | R25: =Simulacao!F7 -> 69326.475 | S25: =Simulacao!F250 -> 1104.9864 | T25: =Simulacao!F252 -> 86116.099 | U25: =U24+T25 -> 149296.8
P26: Set/26 | Q26: =Simulacao!G249 -> 42616.08 | R26: =Simulacao!G7 -> 65051.925 | S26: =Simulacao!G250 -> 2690.9343 | T26: =Simulacao!G252 -> -25126.779 | U26: =U25+T26 -> 124170.02
P27: Out/26 | Q27: =Simulacao!H249 -> 43352.771 | R27: =Simulacao!H7 -> 66852.9 | S27: =Simulacao!H250 -> 0 | T27: =Simulacao!H252 -> -23500.129 | U27: =U26+T27 -> 100669.9
P28: Nov/26 | Q28: =Simulacao!I249 -> 43210.246 | R28: =Simulacao!I7 -> 64640.4 | S28: =Simulacao!I250 -> 0 | T28: =Simulacao!I252 -> -21430.154 | U28: =U27+T28 -> 79239.741
P29: Dez/26 | Q29: =Simulacao!J249 -> 44658.731 | R29: =Simulacao!J7 -> 61379.175 | S29: =Simulacao!J250 -> 0 | T29: =Simulacao!J252 -> -16720.444 | U29: =U28+T29 -> 62519.298
P30: Jan/27 | Q30: =Simulacao!K249 -> 42484.598 | R30: =Simulacao!K7 -> 63022.753 | S30: =Simulacao!K250 -> 0 | T30: =Simulacao!K252 -> -20538.155 | U30: =U29+T30 -> 41981.143
P31: Fev/27 | Q31: =Simulacao!L249 -> 45032.044 | R31: =Simulacao!L7 -> 56158.671 | S31: =Simulacao!L250 -> 0 | T31: =Simulacao!L252 -> -11126.626 | U31: =U30+T31 -> 30854.517
P32: Mar/27 | Q32: =Simulacao!M249 -> 208536.62 | R32: =Simulacao!M7 -> 64414.061 | S32: =Simulacao!M250 -> 0 | T32: =Simulacao!M252 -> 144122.56 | U32: =U31+T32 -> 174977.08
P33: Abr/27 | Q33: =Simulacao!N249 -> 35167.544 | R33: =Simulacao!N7 -> 64273.169 | S33: =Simulacao!N250 -> 0 | T33: =Simulacao!N252 -> -29105.625 | U33: =U32+T33 -> 145871.45
P34: Mai/27 | Q34: =Simulacao!O249 -> 32721.222 | R34: =Simulacao!O7 -> 60152.078 | S34: =Simulacao!O250 -> 0 | T34: =Simulacao!O252 -> -27430.856 | U34: =U33+T34 -> 118440.59
P35: Jun/27 | Q35: =Simulacao!P249 -> 70853.527 | R35: =Simulacao!P7 -> 54591.247 | S35: =Simulacao!P250 -> 0 | T35: =Simulacao!P252 -> 16262.28 | U35: =U34+T35 -> 134702.87
P36: Jul/27 | Q36: =Simulacao!Q249 -> 281671.07 | R36: =Simulacao!Q7 -> 57461.922 | S36: =Simulacao!Q250 -> 0 | T36: =Simulacao!Q252 -> 224209.15 | U36: =U35+T36 -> 358912.03
P37: Ago/27 | Q37: =Simulacao!R249 -> 161721.87 | R37: =Simulacao!R7 -> 68979.843 | S37: =Simulacao!R250 -> 0 | T37: =Simulacao!R252 -> 92742.025 | U37: =U36+T37 -> 451654.05
P38: Set/27 | Q38: =Simulacao!S249 -> 43681.482 | R38: =Simulacao!S7 -> 64726.665 | S38: =Simulacao!S250 -> 0 | T38: =Simulacao!S252 -> -21045.183 | U38: =U37+T38 -> 430608.87
P39: Out/27 | Q39: =Simulacao!T249 -> 44436.59 | R39: =Simulacao!T7 -> 66518.636 | S39: =Simulacao!T250 -> 0 | T39: =Simulacao!T252 -> -22082.045 | U39: =U38+T39 -> 408526.82
P40: Nov/27 | Q40: =Simulacao!U249 -> 44290.502 | R40: =Simulacao!U7 -> 64317.198 | S40: =Simulacao!U250 -> 0 | T40: =Simulacao!U252 -> -20026.696 | U40: =U39+T40 -> 388500.13
P41: Dez/27 | Q41: =Simulacao!V249 -> 45775.2 | R41: =Simulacao!V7 -> 61072.279 | S41: =Simulacao!V250 -> 0 | T41: =Simulacao!V252 -> -15297.079 | U41: =U40+T41 -> 373203.05
P42: Jan/28 | Q42: =Simulacao!W249 -> 42484.598 | R42: =Simulacao!W7 -> 63022.753 | S42: =Simulacao!W250 -> 0 | T42: =Simulacao!W252 -> -20538.155 | U42: =U41+T42 -> 352664.89
P43: Fev/28 | Q43: =Simulacao!X249 -> 45032.044 | R43: =Simulacao!X7 -> 56158.671 | S43: =Simulacao!X250 -> 0 | T43: =Simulacao!X252 -> -11126.626 | U43: =U42+T43 -> 341538.27
P44: Mar/28 | Q44: =Simulacao!Y249 -> 212454.37 | R44: =Simulacao!Y7 -> 64414.061 | S44: =Simulacao!Y250 -> 0 | T44: =Simulacao!Y252 -> 148040.31 | U44: =U43+T44 -> 489578.58
...

Sheet Premissas
A1: ="PREMISSAS — "&Premissas!$B$13&" × Copasul | Energisa MS" -> PREMISSAS — Cassilândia 03 × Copasul | Energisa MS | M1: 🎯 OTIMIZAÇÃO RATEIO — SOLVER CONFIG
A2: Azul = inputs editáveis | Preto = fórmulas | Verde = links entre abas | M2: Siga o passo a passo abaixo para maximizar Economia Líquida via Excel Solver
A4: A. TARIFAS ENERGISA MS (com tributos ICMS 17% + PIS/COFINS) | M4: ① CÉLULA OBJETIVO (aponte o Solver aqui): | P4: ENDEREÇO | Q4: VALOR ATUAL | R4: OBJETIVO
A5: Tarifa Grupo A FP com tributos (R$/kWh) | B5: 0.52647111 | C5: ← T_AFP: edit here | M5: Economia Líquida Copasul 24m (R$) | P5: Premissas!K5 | Q5: =Simulacao!B252 -> 1930957.3 | R5: ↑ MAXIMIZAR
A6: Tarifa Grupo A Ponta com tributos (R$/kWh) | B6: 2.9723794 | C6: ← T_APT: edit here
A7: Tarifa Grupo B3 com tributos (R$/kWh) | B7: 1.1568636 | C7: ← T_B3: edit here | M7: ② ATIVAR SOLVER (se ainda não estiver ativo) | O7: Arquivo → Opções → Suplementos → Gerenciar: Suplementos do Excel → Ir... → ✓ Solver Add-in → OK
A8: FA = TE_FP / TE_Ponta | B8: 0.60426705 | C8: ← FA: edit here | M8: ③ ABRIR SOLVER | O8: Guia Dados → botão "Solver" (canto direito da faixa de opções)
A9: ICMS (%) | B9: 0.17 | C9: ← ICMS: edit here | M9: ④ CONFIGURAR OBJETIVO | O9: Definir Objetivo: selecione a célula Premissas!K5 → marque ● Máx
A10: PIS + COFINS (%) | B10: 0.0855 | C10: ← PIS_COFINS: edit here | M10: ⑤ DEFINIR CÉLULAS VARIÁVEIS | O10: Alterando Células de Variáveis: Premissas!$B$33:$K$50 (170 variáveis = 17 UCs × 10 períodos)
A11: ICMS isenção autoconsumo remoto ativa? (Art. 23-A RICMS/MS) → 'Sim' = isento | 'Não' = ICMS cobrado sobre kWh compensados pelo CS3 | B11: Sim | C11: =IF($B$11="Sim",0,$B$5*$B$9/(1+$B$9)) -> 0 | D11: =IF($B$11="Sim",0,$B$6*$B$9/(1+$B$9)) -> 0 | E11: =IF($B$11="Sim",0,$B$7*$B$9/(1+$B$9)) -> 0 | F11: ← B=toggle (Sim/Não) | C=ICMS A_FP D=ICMS A_Ponta E=ICMS Grupo B (R$/kWh) — tudo 0 se Sim
A12: B. CONDIÇÕES DO CONTRATO | M12: ⑥ ADICIONAR AS RESTRIÇÕES (Adicionar → preencher cada linha → OK)
A13: Usina | B13: Cassilândia 03 | M13: Célula / Intervalo | O13: Relação | P13: Valor / Restrição | R13: Descrição
A14: Distribuidora | B14: Energisa MS | M14: Premissas!$B$33:$K$50 | O14: >= | P14: 0 | R14: Todos os rateios ≥ 0% (sem valores negativos, P1–P10)
A15: Início do contrato | B15: Jun/2026 | M15: Premissas!$B$51 | O15: = | P15: 1 | R15: Soma P1 = 100% (Jun–Set/26)
A16: Prazo (meses) | B16: 60 | M16: Premissas!$C$51 | O16: = | P16: 1 | R16: Soma P2 = 100% (Out/26–Mar/27)
A17: PPA Helexia CS3 (R$/kWh) | B17: 0.4425 | M17: Premissas!$D$51 | O17: = | P17: 1 | R17: Soma P3 = 100% (Abr–Set/27)
A18: H. CENÁRIO CONCORRENTE — ENERGIA ASSINATURA GRUPO B (ex: Plin Energia) | M18: Premissas!$E$51 | O18: = | P18: 1 | R18: Soma P4 = 100% (Out/27–Mai/28)
A19: Grupo B tem contrato Assinatura GD concorrente? | B19: Sim | C19: Desconto (%): | D19: 0.2 | E19: Tarifa B3 SEM efetiva: | F19: =IF(B19="Sim",B7*(1-D19),B7) -> 0.92549092 | M19: Premissas!$F$51 | O19: = | P19: 1 | R19: Soma P5 = 100% (Jun–Nov/28)
A20: C. PREMISSAS DE CRESCIMENTO E DEGRADAÇÃO | M20: Premissas!$G$51 | O20: = | P20: 1 | R20: Soma P6 = 100% (Dez/28–Mai/29)
A21: Crescimento consumo Y2 vs Y1 (%) | B21: 0.025 | C21: ← 2.5% editável | aplica a TODOS os UCs | M21: Premissas!$H$51 | O21: = | P21: 1 | R21: Soma P7 = 100% (Jun–Nov/29)
A22: Crescimento consumo Y3 parcial (Dez/27-Mai/28) (%) | B22: =B21 -> 0.025 | C22: ← mesmo % que Y2 por padrão | M22: Premissas!$I$51 | O22: = | P22: 1 | R22: Soma P8 = 100% (Dez/29–Mai/30)
A23: Degradação geração Y2 (%) | B23: 0.005 | C23: ← 0.5%/ano editável | M23: Premissas!$J$51 | O23: = | P23: 1 | R23: Soma P9 = 100% (Jun–Nov/30)
A24: Usar proxy Batayporã p/ Amandina gen? | B24: Sim | M24: Premissas!$K$51 | O24: = | P24: 1 | R24: Soma P10 = 100% (Dez/30–Mai/31)
A25: D. BANCOS DE CRÉDITOS — SALDO INICIAL (Mai/2026, FPt GD I) | M25: Premissas!$B$34:$K$34 | O25: = | P25: 0 | R25: BAT (linha 34) = 0% em todos os períodos (P1–P10)
A26: NHS — Silos Novo Horizonte do Sul (kWh) | B26: 148516 | M26: Premissas!$B$33:$E$50 | O26: <= | P26: 1 | R26: Todos os rateios ≤ 100% (limite superior)
A27: BAT — Silos Batayporã (kWh) [stranded — não transferível CS3] | B27: 906739
A28: AMD — Silos Amandina (kWh) | B28: 991029
A29: TOTAL NHS+AMD (kWh) | B29: =B26+B28 -> 1139545 | C29: ← BAT stranded bank não incluído no total | M29: ⑦ MÉTODO DE RESOLUÇÃO E OPÇÕES
M30: Método de Resolução: | O30: GRG Não-Linear | P30: O modelo tem funções IF (não-lineares). GRG é o método correto.
A31: ="E. RATEIO FIXO "&INDEX(PVSYST_Helexia!$A$5:$A$7,MATCH(Premissas!$B$13,PVSYST_Helexia!$B$5:$B$7,0))&" — 4 PERÍODOS (edit percentuais — devem somar 100% por período)" -> E. RATEIO FIXO HCS03 — 4 PERÍODOS (edit percentuais — devem somar 100% por período) | F31: Anos 3–5 (estado estacionário) | M31: Opções → Precisão: | O31: 0,000001 | P31: Maior precisão = resultado mais fino.
A32: UC / Planta | B32: P1: Jun–Set/26 | C32: P2: Out/26–Mar/27 | D32: P3: Abr/27–Set/27 | E32: P4: Out/27–Mai/28 | F32: P5: Jun–Nov/28 | G32: P6: Dez/28–Mai/29 | H32: P7: Jun–Nov/29 | I32: P8: Dez/29–Mai/30 | J32: P9: Jun–Nov/30 | K32: P10: Dez/30–Mai/31 | M32: Opções → Iterações: | O32: 1000 | P32: Permite mais buscas antes de parar.
A33: NHS — Silos N. Horizonte (A4V) | B33: 0.738 | C33: 0.5178 | D33: 0.6714 | E33: 0.2592 | F33: 0.4741 | G33: 0.4673 | H33: 0.4724 | I33: 0.4656 | J33: 0.5826 | K33: 0.4621 | M33: Opções → Convergência: | O33: 0,0001 | P33: Critério de parada quando melhoria < este valor.
A34: BAT — Silos Batayporã (A4V) | B34: 0 | C34: 0 | D34: 0 | E34: 0 | F34: 0 | G34: 0 | H34: 0 | I34: 0 | J34: 0 | K34: 0 | M34: ⚠ Otimização local: | O34: Execute 2–3 vezes | P34: GRG pode parar em mínimo local. Rode com rateios iniciais diferentes e fique com o melhor resultado.
A35: AMD — Silos Amandina (A3A) | B35: 0 | C35: 0 | D35: 0.0041 | E35: 0.1561 | F35: 0.3735 | G35: 0.3698 | H35: 0.3726 | I35: 0.3688 | J35: 0.2324 | K35: 0.2925
A36: AREC (B3) | B36: 0.027 | C36: 0.0532 | D36: 0.0311 | E36: 0.0674 | F36: 0.0156 | G36: 0.0171 | H36: 0.016 | I36: 0.0174 | J36: 0.0304 | K36: 0.0322 | M36: ⑧ EXECUTAR → clicar "Resolver" → aceitar "Manter Solução do Solver"
A37: Banheiro Motoristas (B3) | B37: 0.0033 | C37: 0.005 | D37: 0.004 | E37: 0.0045 | F37: 0.0026 | G37: 0.0027 | H37: 0.0026 | I37: 0.0027 | J37: 0.0027 | K37: 0.0034 | M37: Economia Liquida ANTES da otimização (R$): | P37: 670877.66 | Q37: ← valor antes de rodar o Solver (referência)
A38: CTC Copasul (B3) | B38: 0.0031 | C38: 0.0077 | D38: 0.0039 | E38: 0.0072 | F38: 0.0032 | G38: 0.0034 | H38: 0.0032 | I38: 0.0034 | J38: 0.0037 | K38: 0.0043 | M38: Vsalor Banco Residual ANTES da otimização (R$): | P38: =Resumo!H5 -> 396994.51 | Q38: ← valor antes de rodar o Solver (referência)
A39: Depósito Irrigação (B3) | B39: 0.0064 | C39: 0.0114 | D39: 0.0081 | E39: 0.0095 | F39: 0.007 | G39: 0.0075 | H39: 0.0071 | I39: 0.0076 | J39: 0.0098 | K39: 0.0044 | M39: Economia APÓS otimização (R$) — resultado: | P39: =Simulacao!B252 -> 1930957.3 | Q39: ← atualiza automaticamente após o Solver alterar B33:E50
A40: Entreposto (B3) | B40: 0.059 | C40: 0.1067 | D40: 0.0727 | E40: 0.2104 | F40: 0.006 | G40: 0.0064 | H40: 0.0061 | I40: 0.0065 | J40: 0.0075 | K40: 0.0313
A41: Esc. Deodápolis (B3) | B41: 0.0213 | C41: 0.0358 | D41: 0.026 | E41: 0.0439 | F41: 0.0111 | G41: 0.0121 | H41: 0.0113 | I41: 0.0123 | J41: 0.0181 | K41: 0.0212
...

Sheet Simulacao
A1: SIMULAÇÃO RATEIO FIXO — Cassilândia 03 × COPASUL | 18 UCs | Jun/2026–Mai/2031
A2: Energisa MS · Todas as células são fórmulas · Azul=input Premissas · Verde=link entre abas
A4: INDICADOR / UC | B4: TOTAL 60m ou SALDO FINAL | C4: MÉD/mês ou unidade | D4: Jun/26 | E4: Jul/26 | F4: Ago/26 | G4: Set/26 | H4: Out/26 | I4: Nov/26 | J4: Dez/26 | K4: Jan/27 | L4: Fev/27 | M4: Mar/27 | N4: Abr/27 | O4: Mai/27 | P4: Jun/27 | Q4: Jul/27 | R4: Ago/27 | S4: Set/27 | T4: Out/27 | U4: Nov/27 | V4: Dez/27 | W4: Jan/28 | X4: Fev/28 | Y4: Mar/28 | Z4: Abr/28 | AA4: Mai/28 | AB4: Jun/28 | AC4: Jul/28 | AD4: Ago/28 | AE4: Set/28 | AF4: Out/28 | AG4: Nov/28 | AH4: Dez/28 | AI4: Jan/29 | AJ4: Fev/29 | AK4: Mar/29 | AL4: Abr/29 | AM4: Mai/29 | AN4: Jun/29 | AO4: Jul/29 | AP4: Ago/29 | AQ4: Set/29 | AR4: Out/29 | AS4: Nov/29 | AT4: Dez/29 | AU4: Jan/30 | AV4: Fev/30 | AW4: Mar/30 | AX4: Abr/30 | AY4: Mai/30 | AZ4: Jun/30 | BA4: Jul/30 | BB4: Ago/30 | BC4: Set/30 | BD4: Out/30 | BE4: Nov/30 | BF4: Dez/30 | BG4: Jan/31 | BH4: Fev/31 | BI4: Mar/31 | BJ4: Abr/31 | BK4: Mai/31
A5: 0. Cassilândia 03 — GERAÇÃO E CUSTO PPA
A6: HCS03 Geração P50 (kWh) | B6: 8380442.4 | C6: 139674.04 | D6: 123990 | E6: 130510 | F6: 156670 | G6: 147010 | H6: 151080 | I6: 146080 | J6: 138710 | K6: 142424.3 | L6: 126912.25 | M6: 145568.5 | N6: 145250.1 | O6: 135936.9 | P6: 123370.05 | Q6: 129857.45 | R6: 155886.65 | S6: 146274.95 | T6: 150324.6 | U6: 145349.6 | V6: 138016.45 | W6: 142424.3 | X6: 126912.25 | Y6: 145568.5 | Z6: 145250.1 | AA6: 135936.9 | AB6: 122753.2 | AC6: 129208.16 | AD6: 155107.22 | AE6: 145543.58 | AF6: 149572.98 | AG6: 144622.85 | AH6: 137326.37 | AI6: 141712.18 | AJ6: 126277.69 | AK6: 144840.66 | AL6: 144523.85 | AM6: 135257.22 | AN6: 122139.43 | AO6: 128562.12 | AP6: 154331.68 | AQ6: 144815.86 | AR6: 148825.11 | AS6: 143899.74 | AT6: 136639.74 | AU6: 141003.62 | AV6: 125646.3 | AW6: 144116.45 | AX6: 143801.23 | AY6: 134580.93 | AZ6: 121528.74 | BA6: 127919.31 | BB6: 153560.02 | BC6: 144091.78 | BD6: 148080.99 | BE6: 143180.24 | BF6: 135956.54 | BG6: 140298.6 | BH6: 125018.07 | BI6: 143395.87 | BJ6: 143082.22 | BK6: 133908.02
A7: PPA Helexia — custo total (R$) | B7: 3708345.8 | C7: 61805.763 | D7: 54865.575 | E7: 57750.675 | F7: 69326.475 | G7: 65051.925 | H7: 66852.9 | I7: 64640.4 | J7: 61379.175 | K7: 63022.753 | L7: 56158.671 | M7: 64414.061 | N7: 64273.169 | O7: 60152.078 | P7: 54591.247 | Q7: 57461.922 | R7: 68979.843 | S7: 64726.665 | T7: 66518.636 | U7: 64317.198 | V7: 61072.279 | W7: 63022.753 | X7: 56158.671 | Y7: 64414.061 | Z7: 64273.169 | AA7: 60152.078 | AB7: 54318.291 | AC7: 57174.612 | AD7: 68634.943 | AE7: 64403.032 | AF7: 66186.042 | AG7: 63995.612 | AH7: 60766.918 | AI7: 62707.639 | AJ7: 55877.877 | AK7: 64091.991 | AL7: 63951.803 | AM7: 59851.318 | AN7: 54046.699 | AO7: 56888.739 | AP7: 68291.769 | AQ7: 64081.017 | AR7: 65855.112 | AS7: 63675.634 | AT7: 60463.083 | AU7: 62394.101 | AV7: 55598.488 | AW7: 63771.531 | AX7: 63632.044 | AY7: 59552.061 | AZ7: 53776.466 | BA7: 56604.295 | BB7: 67950.31 | BC7: 63760.612 | BD7: 65525.837 | BE7: 63357.256 | BF7: 60160.768 | BG7: 62082.13 | BH7: 55320.495 | BI7: 63452.673 | BJ7: 63313.884 | BK7: 59254.301
A8: 1. BAT — BATAYPORÃ — GERAÇÃO, CONSUMO E SURPLUS
A9: BAT Geração própria (kWh) | B9: 5593986.3 | C9: 93233.104 | D9: 72286.9 | E9: 88336.8 | F9: 93082.7 | G9: 94433.4 | H9: 95906.8 | I9: 107980.6 | J9: 106603.9 | K9: 113687.7 | L9: 90676.241 | M9: 102546.59 | N9: 73341.151 | O9: 91158.517 | P9: 71925.465 | Q9: 87895.116 | R9: 92617.287 | S9: 93961.233 | T9: 95427.266 | U9: 107440.7 | V9: 106070.88 | W9: 113119.27 | X9: 90222.859 | Y9: 102033.86 | Z9: 72974.446 | AA9: 90702.724 | AB9: 71565.838 | AC9: 87455.64 | AD9: 92154.2 | AE9: 93491.427 | AF9: 94950.13 | AG9: 106903.49 | AH9: 105540.53 | AI9: 112553.67 | AJ9: 89771.745 | AK9: 101523.69 | AL9: 72609.574 | AM9: 90249.211 | AN9: 71208.009 | AO9: 87018.362 | AP9: 91693.429 | AQ9: 93023.97 | AR9: 94475.379 | AS9: 106368.98 | AT9: 105012.82 | AU9: 111990.9 | AV9: 89322.886 | AW9: 101016.07 | AX9: 72246.526 | AY9: 89797.965 | AZ9: 70851.969 | BA9: 86583.27 | BB9: 91234.962 | BC9: 92558.85 | BD9: 94003.002 | BE9: 105837.13 | BF9: 104487.76 | BG9: 111430.95 | BH9: 88876.272 | BI9: 100510.99 | BJ9: 71885.293 | BK9: 89348.975
A10: BAT Consumo FP (kWh) | B10: 3509998.1 | C10: 58499.968 | D10: 78336 | E10: 115718.4 | F10: 23364 | G10: 10800 | H10: 10800 | I10: 10800 | J10: 3402 | K10: 116816.17 | L10: 129020.85 | M10: 58936.68 | N10: 36531 | O10: 81593.28 | P10: 80294.4 | Q10: 118611.36 | R10: 23948.1 | S10: 11070 | T10: 11070 | U10: 11070 | V10: 3487.05 | W10: 116816.17 | X10: 129020.85 | Y10: 58936.68 | Z10: 36531 | AA10: 81593.28 | AB10: 82301.76 | AC10: 121576.64 | AD10: 24546.802 | AE10: 11346.75 | AF10: 11346.75 | AG10: 11346.75 | AH10: 3574.2262 | AI10: 119736.58 | AJ10: 132246.37 | AK10: 60410.097 | AL10: 37444.275 | AM10: 83633.112 | AN10: 84359.304 | AO10: 124616.06 | AP10: 25160.473 | AQ10: 11630.419 | AR10: 11630.419 | AS10: 11630.419 | AT10: 3663.5819 | AU10: 122729.99 | AV10: 135552.53 | AW10: 61920.349 | AX10: 38380.382 | AY10: 85723.94 | AZ10: 86468.287 | BA10: 127731.46 | BB10: 25789.484 | BC10: 11921.179 | BD10: 11921.179 | BE10: 11921.179 | BF10: 3755.1715 | BG10: 125798.24 | BH10: 138941.34 | BI10: 63468.358 | BJ10: 39339.891 | BK10: 87867.038
A11: BAT Consumo Ponta (kWh) | B11: 389999.79 | C11: 6499.9965 | D11: 8704 | E11: 12857.6 | F11: 2596 | G11: 1200 | H11: 1200 | I11: 1200 | J11: 378 | K11: 12979.575 | L11: 14335.65 | M11: 6548.52 | N11: 4059 | O11: 9065.92 | P11: 8921.6 | Q11: 13179.04 | R11: 2660.9 | S11: 1230 | T11: 1230 | U11: 1230 | V11: 387.45 | W11: 12979.575 | X11: 14335.65 | Y11: 6548.52 | Z11: 4059 | AA11: 9065.92 | AB11: 9144.64 | AC11: 13508.516 | AD11: 2727.4225 | AE11: 1260.75 | AF11: 1260.75 | AG11: 1260.75 | AH11: 397.13625 | AI11: 13304.064 | AJ11: 14694.041 | AK11: 6712.233 | AL11: 4160.475 | AM11: 9292.568 | AN11: 9373.256 | AO11: 13846.229 | AP11: 2795.6081 | AQ11: 1292.2687 | AR11: 1292.2687 | AS11: 1292.2687 | AT11: 407.06466 | AU11: 13636.666 | AV11: 15061.392 | AW11: 6880.0388 | AX11: 4264.4869 | AY11: 9524.8822 | AZ11: 9607.5874 | BA11: 14192.385 | BB11: 2865.4983 | BC11: 1324.5755 | BD11: 1324.5755 | BE11: 1324.5755 | BF11: 417.24127 | BG11: 13977.583 | BH11: 15437.927 | BI11: 7052.0398 | BJ11: 4371.099 | BK11: 9763.0043
A12: BAT auto-comp. FP (kWh) | B12: 3030085.2 | C12: 50501.419 | D12: 72286.9 | E12: 88336.8 | F12: 23364 | G12: 10800 | H12: 10800 | I12: 10800 | J12: 3402 | K12: 113687.7 | L12: 90676.241 | M12: 58936.68 | N12: 36531 | O12: 81593.28 | P12: 71925.465 | Q12: 87895.116 | R12: 23948.1 | S12: 11070 | T12: 11070 | U12: 11070 | V12: 3487.05 | W12: 113119.27 | X12: 90222.859 | Y12: 58936.68 | Z12: 36531 | AA12: 81593.28 | AB12: 71565.838 | AC12: 87455.64 | AD12: 24546.802 | AE12: 11346.75 | AF12: 11346.75 | AG12: 11346.75 | AH12: 3574.2262 | AI12: 112553.67 | AJ12: 89771.745 | AK12: 60410.097 | AL12: 37444.275 | AM12: 83633.112 | AN12: 71208.009 | AO12: 87018.362 | AP12: 25160.473 | AQ12: 11630.419 | AR12: 11630.419 | AS12: 11630.419 | AT12: 3663.5819 | AU12: 111990.9 | AV12: 89322.886 | AW12: 61920.349 | AX12: 38380.382 | AY12: 85723.94 | AZ12: 70851.969 | BA12: 86583.27 | BB12: 25789.484 | BC12: 11921.179 | BD12: 11921.179 | BE12: 11921.179 | BF12: 3755.1715 | BG12: 111430.95 | BH12: 88876.272 | BI12: 63468.358 | BJ12: 39339.891 | BK12: 87867.038
A13: BAT auto-comp. Ponta via FA (kWh) | B13: 107850.19 | C13: 1797.5031 | D13: 0 | E13: 0 | F13: 2596 | G13: 1200 | H13: 1200 | I13: 1200 | J13: 378 | K13: 0 | L13: 0 | M13: 6548.52 | N13: 4059 | O13: 5779.9575 | P13: 0 | Q13: 0 | R13: 2660.9 | S13: 1230 | T13: 1230 | U13: 1230 | V13: 387.45 | W13: 0 | X13: 0 | Y13: 6548.52 | Z13: 4059 | AA13: 5504.5371 | AB13: 0 | AC13: 0 | AD13: 2727.4225 | AE13: 1260.75 | AF13: 1260.75 | AG13: 1260.75 | AH13: 397.13625 | AI13: 0 | AJ13: 0 | AK13: 6712.233 | AL13: 4160.475 | AM13: 3997.8905 | AN13: 0 | AO13: 0 | AP13: 2795.6081 | AQ13: 1292.2687 | AR13: 1292.2687 | AS13: 1292.2687 | AT13: 407.06466 | AU13: 0 | AV13: 0 | AW13: 6880.0388 | AX13: 4264.4869 | AY13: 2461.799 | AZ13: 0 | BA13: 0 | BB13: 2865.4983 | BC13: 1324.5755 | BD13: 1324.5755 | BE13: 1324.5755 | BF13: 417.24127 | BG13: 0 | BH13: 0 | BI13: 7052.0398 | BJ13: 4371.099 | BK13: 895.48547
A14: ★ BAT surplus líquido → rateio (kWh) | B14: 2385420.1 | C14: 39757.002 | D14: 0 | E14: 0 | F14: 65422.586 | G14: 81647.523 | H14: 83120.923 | I14: 95194.723 | J14: 102576.35 | K14: 0 | L14: 0 | M14: 32772.781 | N14: 30092.923 | O14: 0 | P14: 0 | Q14: 0 | R14: 64265.67 | S14: 80855.709 | T14: 82321.742 | U14: 94335.173 | V14: 101942.64 | W14: 0 | X14: 0 | Y14: 32260.048 | Z14: 29726.217 | AA14: 0 | AB14: 0 | AC14: 0 | AD14: 63093.793 | AE14: 80058.265 | AF14: 81516.968 | AG14: 93470.332 | AH14: 101309.08 | AI14: 0 | AJ14: 0 | AK14: 30005.534 | AL14: 28280.139 | AM14: 0 | AN14: 0 | AO14: 0 | AP14: 61906.512 | AQ14: 79254.979 | AR14: 80706.388 | AS14: 92599.985 | AT14: 100675.59 | AU14: 0 | AV14: 0 | AW14: 27709.962 | AX14: 26808.855 | AY14: 0 | AZ14: 0 | BA14: 0 | BB14: 60703.372 | BC14: 78445.634 | BD14: 79889.786 | BE14: 91723.915 | BF14: 100042.1 | BG14: 0 | BH14: 0 | BI14: 25372.229 | BJ14: 25311.681 | BK14: 0
A15: BAT banco stranded — depleção por consumo próprio apenas
A16: BAT banco início mês (kWh) | B16: 582152.89 | C16: — | D16: 906739 | E16: 886285.67 | F16: 837626.06 | G16: 837626.06 | H16: 837626.06 | I16: 837626.06 | J16: 837626.06 | K16: 837626.06 | L16: 813017.73 | M16: 750949.09 | N16: 750949.09 | O16: 750949.09 | P16: 745511.16 | Q16: 722377.89 | R16: 669851.69 | S16: 669851.69 | T16: 669851.69 | U16: 669851.69 | V16: 669851.69 | W16: 669851.69 | X16: 644674.91 | Y16: 582152.89 | Z16: 582152.89 | AA16: 582152.89 | AB16: 576259.17 | AC16: 550389.8 | AD16: 493913.59 | AE16: 493913.59 | AF16: 493913.59 | AG16: 493913.59 | AH16: 493913.59 | AI16: 493913.59 | AJ16: 464713.82 | AK16: 397922.06 | AL16: 397922.06 | AM16: 397922.06 | AN16: 389159.91 | AO16: 360496.84 | AP16: 299985.05 | AQ16: 299985.05 | AR16: 299985.05 | AS16: 299985.05 | AT16: 299985.05 | AU16: 299985.05 | AV16: 266678.68 | AW16: 195523.97 | AX16: 195523.97 | AY16: 195523.97 | AZ16: 183835.3 | BA16: 152319.41 | BB16: 87684.274 | BC16: 87684.274 | BD16: 87684.274 | BE16: 87684.274 | BF16: 87684.274 | BG16: 87684.274 | BH16: 50185.511 | BI16: 0 | BJ16: 0 | BK16: 0
A17: BAT banco draw (kWh) | B17: 906739 | C17: 15112.317 | D17: 20453.327 | E17: 48659.609 | F17: 0 | G17: 0 | H17: 0 | I17: 0 | J17: 0 | K17: 24608.336 | L17: 62068.64 | M17: 0 | N17: 0 | O17: 5437.9309 | P17: 23133.268 | Q17: 52526.204 | R17: 0 | S17: 0 | T17: 0 | U17: 0 | V17: 0 | W17: 25176.774 | X17: 62522.021 | Y17: 0 | Z17: 0 | AA17: 5893.7235 | AB17: 25869.363 | AC17: 56476.212 | AD17: 0 | AE17: 0 | AF17: 0 | AG17: 0 | AH17: 0 | AI17: 29199.771 | AJ17: 66791.758 | AK17: 0 | AL17: 0 | AM17: 8762.1483 | AN17: 28663.072 | AO17: 60511.787 | AP17: 0 | AQ17: 0 | AR17: 0 | AS17: 0 | AT17: 0 | AU17: 33306.376 | AV17: 71154.704 | AW17: 0 | AX17: 0 | AY17: 11688.678 | AZ17: 31515.89 | BA17: 64635.132 | BB17: 0 | BC17: 0 | BD17: 0 | BE17: 0 | BF17: 0 | BG17: 37498.762 | BH17: 50185.511 | BI17: 0 | BJ17: 0 | BK17: 0
A18: BAT banco fim mês (kWh) | B18: 576259.17 | C18: — | D18: 886285.67 | E18: 837626.06 | F18: 837626.06 | G18: 837626.06 | H18: 837626.06 | I18: 837626.06 | J18: 837626.06 | K18: 813017.73 | L18: 750949.09 | M18: 750949.09 | N18: 750949.09 | O18: 745511.16 | P18: 722377.89 | Q18: 669851.69 | R18: 669851.69 | S18: 669851.69 | T18: 669851.69 | U18: 669851.69 | V18: 669851.69 | W18: 644674.91 | X18: 582152.89 | Y18: 582152.89 | Z18: 582152.89 | AA18: 576259.17 | AB18: 550389.8 | AC18: 493913.59 | AD18: 493913.59 | AE18: 493913.59 | AF18: 493913.59 | AG18: 493913.59 | AH18: 493913.59 | AI18: 464713.82 | AJ18: 397922.06 | AK18: 397922.06 | AL18: 397922.06 | AM18: 389159.91 | AN18: 360496.84 | AO18: 299985.05 | AP18: 299985.05 | AQ18: 299985.05 | AR18: 299985.05 | AS18: 299985.05 | AT18: 299985.05 | AU18: 266678.68 | AV18: 195523.97 | AW18: 195523.97 | AX18: 195523.97 | AY18: 183835.3 | AZ18: 152319.41 | BA18: 87684.274 | BB18: 87684.274 | BC18: 87684.274 | BD18: 87684.274 | BE18: 87684.274 | BF18: 87684.274 | BG18: 50185.511 | BH18: 0 | BI18: 0 | BJ18: 0 | BK18: 0
A19: BAT créditos → NHS (kWh, T+1) | B19: 1192710.1 | C19: 19878.501 | D19: 0 | E19: 0 | F19: 0 | G19: 32711.293 | H19: 40823.762 | I19: 41560.462 | J19: 47597.362 | K19: 51288.174 | L19: 0 | M19: 0 | N19: 16386.391 | O19: 15046.461 | P19: 0 | Q19: 0 | R19: 0 | S19: 32132.835 | T19: 40427.855 | U19: 41160.871 | V19: 47167.587 | W19: 50971.32 | X19: 0 | Y19: 0 | Z19: 16130.024 | AA19: 14863.108 | AB19: 0 | AC19: 0 | AD19: 0 | AE19: 31546.897 | AF19: 40029.132 | AG19: 40758.484 | AH19: 46735.166 | AI19: 50654.54 | AJ19: 0 | AK19: 0 | AL19: 15002.767 | AM19: 14140.07 | AN19: 0 | AO19: 0 | AP19: 0 | AQ19: 30953.256 | AR19: 39627.489 | AS19: 40353.194 | AT19: 46299.993 | AU19: 50337.796 | AV19: 0 | AW19: 0 | AX19: 13854.981 | AY19: 13404.428 | AZ19: 0 | BA19: 0 | BB19: 0 | BC19: 30351.686 | BD19: 39222.817 | BE19: 39944.893 | BF19: 45861.958 | BG19: 50021.048 | BH19: 0 | BI19: 0 | BJ19: 12686.114 | BK19: 12655.84
A20: BAT créditos → AMD (kWh, T+1) | B20: 1192710.1 | C20: 19878.501 | D20: 0 | E20: 0 | F20: 0 | G20: 32711.293 | H20: 40823.762 | I20: 41560.462 | J20: 47597.362 | K20: 51288.174 | L20: 0 | M20: 0 | N20: 16386.391 | O20: 15046.461 | P20: 0 | Q20: 0 | R20: 0 | S20: 32132.835 | T20: 40427.855 | U20: 41160.871 | V20: 47167.587 | W20: 50971.32 | X20: 0 | Y20: 0 | Z20: 16130.024 | AA20: 14863.108 | AB20: 0 | AC20: 0 | AD20: 0 | AE20: 31546.897 | AF20: 40029.132 | AG20: 40758.484 | AH20: 46735.166 | AI20: 50654.54 | AJ20: 0 | AK20: 0 | AL20: 15002.767 | AM20: 14140.07 | AN20: 0 | AO20: 0 | AP20: 0 | AQ20: 30953.256 | AR20: 39627.489 | AS20: 40353.194 | AT20: 46299.993 | AU20: 50337.796 | AV20: 0 | AW20: 0 | AX20: 13854.981 | AY20: 13404.428 | AZ20: 0 | BA20: 0 | BB20: 0 | BC20: 30351.686 | BD20: 39222.817 | BE20: 39944.893 | BF20: 45861.958 | BG20: 50021.048 | BH20: 0 | BI20: 0 | BJ20: 12686.114 | BK20: 12655.84
A21: NHS — N. Horizonte do Sul (A4V)
A22: Consumo FP (kWh) | B22: 8849247.7 | C22: 147487.46 | D22: 108694.9 | E22: 328938.1 | F22: 190977.6 | G22: 126478.8 | H22: 28215 | I22: 42209.6 | J22: 42209.6 | K22: 72539.147 | L22: 249812.69 | M22: 340170.95 | N22: 105347.76 | O22: 64384.555 | P22: 111412.27 | Q22: 337161.55 | R22: 195752.04 | S22: 129640.77 | T22: 28920.375 | U22: 43264.84 | V22: 43264.84 | W22: 72539.147 | X22: 249812.69 | Y22: 340170.95 | Z22: 105347.76 | AA22: 64384.555 | AB22: 114197.58 | AC22: 345590.59 | AD22: 200645.84 | AE22: 132881.79 | AF22: 29643.384 | AG22: 44346.461 | AH22: 44346.461 | AI22: 74352.626 | AJ22: 256058.01 | AK22: 348675.23 | AL22: 107981.45 | AM22: 65994.169 | AN22: 117052.52 | AO22: 354230.36 | AP22: 205661.99 | AQ22: 136203.83 | AR22: 30384.469 | AS22: 45455.123 | AT22: 45455.123 | AU22: 76211.442 | AV22: 262459.46 | AW22: 357392.11 | AX22: 110680.99 | AY22: 67644.023 | AZ22: 119978.83 | BA22: 363086.11 | BB22: 210803.54 | BC22: 139608.93 | BD22: 31144.081 | BE22: 46591.501 | BF22: 46591.501 | BG22: 78116.728 | BH22: 269020.95 | BI22: 366326.91 | BJ22: 113448.01 | BK22: 69335.124
A23: Consumo Ponta (kWh) [via FA] | B23: 983250.33 | C23: 16387.506 | D23: 12077.2 | E23: 36548.7 | F23: 21219.7 | G23: 14053.2 | H23: 3135 | I23: 4690 | J23: 4690 | K23: 8059.8825 | L23: 27757 | M23: 37796.772 | N23: 11705.295 | O23: 7153.885 | P23: 12379.13 | Q23: 37462.417 | R23: 21750.192 | S23: 14404.53 | T23: 3213.375 | U23: 4807.25 | V23: 4807.25 | W23: 8059.8825 | X23: 27757 | Y23: 37796.772 | Z23: 11705.295 | AA23: 7153.885 | AB23: 12688.608 | AC23: 38398.978 | AD23: 22293.947 | AE23: 14764.643 | AF23: 3293.7094 | AG23: 4927.4312 | AH23: 4927.4312 | AI23: 8261.3796 | AJ23: 28450.925 | AK23: 38741.692 | AL23: 11997.927 | AM23: 7332.7321 | AN23: 13005.823 | AO23: 39358.952 | AP23: 22851.296 | AQ23: 15133.759 | AR23: 3376.0521 | AS23: 5050.617 | AT23: 5050.617 | AU23: 8467.9141 | AV23: 29162.198 | AW23: 39710.234 | AX23: 12297.876 | AY23: 7516.0504 | AZ23: 13330.969 | BA23: 40342.926 | BB23: 23422.578 | BC23: 15512.103 | BD23: 3460.4534 | BE23: 5176.8825 | BF23: 5176.8825 | BG23: 8679.6119 | BH23: 29891.253 | BI23: 40702.99 | BJ23: 12605.322 | BK23: 7703.9517
A24: Geração própria (kWh) | B24: 4634513.1 | C24: 77241.885 | D24: 60380.6 | E24: 76551.2 | F24: 79815.6 | G24: 78203 | H24: 73160.1 | I24: 91030.5 | J24: 88631.7 | K24: 83044.59 | L24: 75743.778 | M24: 89408.909 | N24: 62411.773 | O24: 77836.363 | P24: 60078.697 | Q24: 76168.444 | R24: 79416.522 | S24: 77811.985 | T24: 72794.299 | U24: 90575.348 | V24: 88188.541 | W24: 82629.368 | X24: 75365.059 | Y24: 88961.864 | Z24: 62099.714 | AA24: 77447.181 | AB24: 59778.304 | AC24: 75787.602 | AD24: 79019.439 | AE24: 77422.925 | AF24: 72430.328 | AG24: 90122.471 | AH24: 87747.599 | AI24: 82216.221 | AJ24: 74988.234 | AK24: 88517.055 | AL24: 61789.216 | AM24: 77059.945 | AN24: 59479.412 | AO24: 75408.664 | AP24: 78624.342 | AQ24: 77035.81 | AR24: 72068.176 | AS24: 89671.858 | AT24: 87308.861 | AU24: 81805.14 | AV24: 74613.293 | AW24: 88074.47 | AX24: 61480.269 | AY24: 76674.645 | AZ24: 59182.015 | BA24: 75031.62 | BB24: 78231.22 | BC24: 76650.631 | BD24: 71707.835 | BE24: 89223.499 | BF24: 86872.316 | BG24: 81396.114 | BH24: 74240.226 | BI24: 87634.098 | BJ24: 61172.868 | BK24: 76291.272
A25: Auto-comp. FP (kWh) | B25: 3884122.7 | C25: 64735.379 | D25: 60380.6 | E25: 76551.2 | F25: 79815.6 | G25: 78203 | H25: 28215 | I25: 42209.6 | J25: 42209.6 | K25: 72539.147 | L25: 75743.778 | M25: 89408.909 | N25: 62411.773 | O25: 64384.555 | P25: 60078.697 | Q25: 76168.444 | R25: 79416.522 | S25: 77811.985 | T25: 28920.375 | U25: 43264.84 | V25: 43264.84 | W25: 72539.147 | X25: 75365.059 | Y25: 88961.864 | Z25: 62099.714 | AA25: 64384.555 | AB25: 59778.304 | AC25: 75787.602 | AD25: 79019.439 | AE25: 77422.925 | AF25: 29643.384 | AG25: 44346.461 | AH25: 44346.461 | AI25: 74352.626 | AJ25: 74988.234 | AK25: 88517.055 | AL25: 61789.216 | AM25: 65994.169 | AN25: 59479.412 | AO25: 75408.664 | AP25: 78624.342 | AQ25: 77035.81 | AR25: 30384.469 | AS25: 45455.123 | AT25: 45455.123 | AU25: 76211.442 | AV25: 74613.293 | AW25: 88074.47 | AX25: 61480.269 | AY25: 67644.023 | AZ25: 59182.015 | BA25: 75031.62 | BB25: 78231.22 | BC25: 76650.631 | BD25: 31144.081 | BE25: 46591.501 | BF25: 46591.501 | BG25: 78116.728 | BH25: 74240.226 | BI25: 87634.098 | BJ25: 61172.868 | BK25: 69335.124
A26: Auto-comp. Ponta via FA (kWh) | B26: 118996.39 | C26: 1983.2731 | D26: 0 | E26: 0 | F26: 0 | G26: 0 | H26: 3135 | I26: 4690 | J26: 4690 | K26: 6348.093 | L26: 0 | M26: 0 | N26: 0 | O26: 7153.885 | P26: 0 | Q26: 0 | R26: 0 | S26: 0 | T26: 3213.375 | U26: 4807.25 | V26: 4807.25 | W26: 6097.1875 | X26: 0 | Y26: 0 | Z26: 0 | AA26: 7153.885 | AB26: 0 | AC26: 0 | AD26: 0 | AE26: 0 | AF26: 3293.7094 | AG26: 4927.4312 | AH26: 4927.4312 | AI26: 4751.7111 | AJ26: 0 | AK26: 0 | AL26: 0 | AM26: 6686.6838 | AN26: 0 | AO26: 0 | AP26: 0 | AQ26: 0 | AR26: 3376.0521 | AS26: 5050.617 | AT26: 5050.617 | AU26: 3380.0872 | AV26: 0 | AW26: 0 | AX26: 0 | AY26: 5456.9073 | AZ26: 0 | BA26: 0 | BB26: 0 | BC26: 0 | BD26: 3460.4534 | BE26: 5176.8825 | BF26: 5176.8825 | BG26: 1981.6249 | BH26: 0 | BI26: 0 | BJ26: 0 | BK26: 4203.3711
A27: HCS03 créditos recebidos (kWh) | B27: 4146923.6 | C27: 69115.393 | D27: 91504.62 | E27: 96316.38 | F27: 115622.46 | G27: 108493.38 | H27: 78229.224 | I27: 75640.224 | J27: 71824.038 | K27: 73747.303 | L27: 65715.163 | M27: 75375.369 | N27: 97520.917 | O27: 91268.035 | P27: 82830.652 | Q27: 87186.292 | R27: 104662.3 | S27: 98209.001 | T27: 38964.136 | U27: 37674.616 | V27: 35773.864 | W27: 36916.379 | X27: 32895.655 | Y27: 37731.355 | Z27: 37648.826 | AA27: 35234.844 | AB27: 58197.292 | AC27: 61257.59 | AD27: 73536.331 | AE27: 69002.209 | AF27: 70912.548 | AG27: 68565.694 | AH27: 64172.612 | AI27: 66222.101 | AJ27: 59009.564 | AK27: 67684.039 | AL27: 67535.995 | AM27: 63205.697 | AN27: 57698.669 | AO27: 60732.746 | AP27: 72906.286 | AQ27: 68411.011 | AR27: 70304.983 | AS27: 67978.236 | AT27: 63619.461 | AU27: 65651.284 | AV27: 58500.917 | AW27: 67100.621 | AX27: 66953.853 | AY27: 62660.881 | AZ27: 70802.642 | BA27: 74525.791 | BB27: 89464.069 | BC27: 83947.87 | BD27: 86271.983 | BE27: 83416.807 | BF27: 62825.516 | BG27: 64831.983 | BH27: 57770.85 | BI27: 66263.232 | BJ27: 66118.296 | BK27: 61878.898
A28: BAT créditos → NHS (kWh) | B28: 1192710.1 | C28: 19878.501 | D28: 0 | E28: 0 | F28: 0 | G28: 32711.293 | H28: 40823.762 | I28: 41560.462 | J28: 47597.362 | K28: 51288.174 | L28: 0 | M28: 0 | N28: 16386.391 | O28: 15046.461 | P28: 0 | Q28: 0 | R28: 0 | S28: 32132.835 | T28: 40427.855 | U28: 41160.871 | V28: 47167.587 | W28: 50971.32 | X28: 0 | Y28: 0 | Z28: 16130.024 | AA28: 14863.108 | AB28: 0 | AC28: 0 | AD28: 0 | AE28: 31546.897 | AF28: 40029.132 | AG28: 40758.484 | AH28: 46735.166 | AI28: 50654.54 | AJ28: 0 | AK28: 0 | AL28: 15002.767 | AM28: 14140.07 | AN28: 0 | AO28: 0 | AP28: 0 | AQ28: 30953.256 | AR28: 39627.489 | AS28: 40353.194 | AT28: 46299.993 | AU28: 50337.796 | AV28: 0 | AW28: 0 | AX28: 13854.981 | AY28: 13404.428 | AZ28: 0 | BA28: 0 | BB28: 0 | BC28: 30351.686 | BD28: 39222.817 | BE28: 39944.893 | BF28: 45861.958 | BG28: 50021.048 | BH28: 0 | BI28: 0 | BJ28: 12686.114 | BK28: 12655.84
A29: Banco início mês COM Helexia (kWh) | B29: 262414.01 | C29: — | D29: 148516 | E29: 171719.79 | F29: 0 | G29: 4460.46 | H29: 92928.873 | I29: 256926.96 | J29: 422948.54 | K29: 588792.04 | L29: 721500.13 | M29: 567211.39 | N29: 329274.93 | O29: 380875.19 | P29: 500641.49 | Q29: 511652.38 | R29: 275849.1 | S29: 228181.55 | T29: 282856.58 | U29: 406122.49 | V29: 532268.49 | W29: 660133.64 | X29: 750898.78 | Y29: 563411.81 | Z29: 287384.29 | AA29: 262414.01 | AB29: 325574.59 | AC29: 308354.26 | AD29: 36262.494 | AE29: 0 | AF29: 45090.241 | AG29: 198818.87 | AH29: 353919.05 | AI29: 508227.97 | AJ29: 627160.06 | AK29: 458016.49 | AL29: 201428.83 | AM29: 217920.02 | AN29: 305262.41 | AO29: 283864.67 | AP29: 640.6952 | AQ29: 0 | AR29: 40196.243 | AS29: 191812.42 | AT29: 344360.59 | AU29: 496133.78 | AV29: 609296.73 | AW29: 431691.03 | AX29: 163757.65 | AY29: 175014.04 | AZ29: 256702.3 | BA29: 244646.74 | BB29: 0 | BC29: 0 | BD29: 51341.257 | BE29: 217399.81 | BF29: 383393.51 | BG29: 532361.8 | BH29: 639409.74 | BI29: 452932.91 | BJ29: 173144.05 | BK29: 178812.8
A30: Bank draw COM Helexia (kWh) | B30: 3785853.1 | C30: 63097.552 | D30: 19986.528 | E30: 171719.79 | F30: 0 | G30: 4460.46 | H30: 0 | I30: 0 | J30: 0 | K30: 2832.836 | L30: 154288.74 | M30: 237936.46 | N30: 19371.063 | O30: 0 | P30: 20486.191 | Q30: 235803.28 | R30: 47667.559 | S30: 23838.02 | T30: 0 | U30: 0 | V30: 0 | W30: 7212.7806 | X30: 187486.97 | Y30: 276027.52 | Z30: 41100.305 | AA30: 0 | AB30: 20998.345 | AC30: 272091.77 | AD30: 36262.494 | AE30: 0 | AF30: 0 | AG30: 0 | AH30: 0 | AI30: 5808.1415 | AJ30: 169143.58 | AK30: 256587.66 | AL30: 19855.339 | AM30: 1069.1438 | AN30: 21523.304 | AO30: 283223.98 | AP30: 640.6952 | AQ30: 0 | AR30: 0 | AS30: 0 | AT30: 0 | AU30: 8419.8316 | AV30: 177605.7 | AW30: 267933.38 | AX30: 20351.723 | AY30: 3407.6707 | AZ30: 22061.387 | BA30: 244646.74 | BB30: 0 | BC30: 0 | BD30: 0 | BE30: 0 | BF30: 0 | BG30: 11084.482 | BH30: 186476.83 | BI30: 279788.85 | BJ30: 20860.516 | BK30: 5793.1019
A31: ★ Banco fim mês COM Helexia (kWh) | B31: 325574.59 | C31: — | D31: 171719.79 | E31: 0 | F31: 4460.46 | G31: 92928.873 | H31: 256926.96 | I31: 422948.54 | J31: 588792.04 | K31: 721500.13 | L31: 567211.39 | M31: 329274.93 | N31: 380875.19 | O31: 500641.49 | P31: 511652.38 | Q31: 275849.1 | R31: 228181.55 | S31: 282856.58 | T31: 406122.49 | U31: 532268.49 | V31: 660133.64 | W31: 750898.78 | X31: 563411.81 | Y31: 287384.29 | Z31: 262414.01 | AA31: 325574.59 | AB31: 308354.26 | AC31: 36262.494 | AD31: 0 | AE31: 45090.241 | AF31: 198818.87 | AG31: 353919.05 | AH31: 508227.97 | AI31: 627160.06 | AJ31: 458016.49 | AK31: 201428.83 | AL31: 217920.02 | AM31: 305262.41 | AN31: 283864.67 | AO31: 640.6952 | AP31: 0 | AQ31: 40196.243 | AR31: 191812.42 | AS31: 344360.59 | AT31: 496133.78 | AU31: 609296.73 | AV31: 431691.03 | AW31: 163757.65 | AX31: 175014.04 | AY31: 256702.3 | AZ31: 244646.74 | BA31: 0 | BB31: 0 | BC31: 51341.257 | BD31: 217399.81 | BE31: 383393.51 | BF31: 532361.8 | BG31: 639409.74 | BH31: 452932.91 | BI31: 173144.05 | BJ31: 178812.8 | BK31: 254510.59
A32: Banco início mês SEM Helexia (kWh) | B32: 16130.024 | C32: — | D32: 148516 | E32: 80215.172 | F32: 0 | G32: 0 | H32: 32711.293 | I32: 118480.15 | J32: 208861.52 | K32: 302880.98 | L32: 364674.6 | M32: 144670.69 | N32: 0 | O32: 16386.391 | P32: 44884.66 | Q32: 0 | R32: 0 | S32: 0 | T32: 32132.835 | U32: 116434.61 | V32: 204905.99 | W32: 296997.28 | X32: 358058.82 | Y32: 137676.2 | Z32: 0 | AA32: 16130.024 | AB32: 44055.758 | AC32: 0 | AD32: 0 | AE32: 0 | AF32: 31546.897 | AG32: 114362.97 | AH32: 200897.47 | AI32: 291033.77 | AJ32: 349551.9 | AK32: 121398.77 | AL32: 0 | AM32: 15002.767 | AN32: 40208.612 | AO32: 0 | AP32: 0 | AQ32: 0 | AR32: 30953.256 | AS32: 112264.45 | AT32: 196834.38 | AU32: 284988.11 | AV32: 338093.47 | AW32: 101986.86 | AX32: 0 | AY32: 13854.981 | AZ32: 36290.03 | BA32: 0 | BB32: 0 | BC32: 0 | BD32: 30351.686 | BE32: 110138.26 | BF32: 192715.15 | BG32: 278857.92 | BH32: 324353.26 | BI32: 80105.583 | BJ32: 0 | BK32: 12686.114
A33: Bank draw SEM Helexia (kWh) — gen+BAT, no CS3 | B33: 2059318.3 | C33: 34321.972 | D33: 68300.828 | E33: 80215.172 | F33: 0 | G33: 0 | H33: 0 | I33: 0 | J33: 0 | K33: 0 | L33: 220003.9 | M33: 144670.69 | N33: 0 | O33: 0 | P33: 44884.66 | Q33: 0 | R33: 0 | S33: 0 | T33: 0 | U33: 0 | V33: 0 | W33: 0 | X33: 220382.62 | Y33: 137676.2 | Z33: 0 | AA33: 0 | AB33: 44055.758 | AC33: 0 | AD33: 0 | AE33: 0 | AF33: 0 | AG33: 0 | AH33: 0 | AI33: 0 | AJ33: 228153.14 | AK33: 121398.77 | AL33: 0 | AM33: 0 | AN33: 40208.612 | AO33: 0 | AP33: 0 | AQ33: 0 | AR33: 0 | AS33: 0 | AT33: 0 | AU33: 2826.1339 | AV33: 236106.61 | AW33: 101986.86 | AX33: 0 | AY33: 0 | AZ33: 36290.03 | BA33: 0 | BB33: 0 | BC33: 0 | BD33: 0 | BE33: 0 | BF33: 0 | BG33: 7805.0956 | BH33: 244247.68 | BI33: 80105.583 | BJ33: 0 | BK33: 0
A34: Banco fim mês SEM Helexia (kWh) — gen+BAT, no CS3 | B34: 44055.758 | C34: — | D34: 80215.172 | E34: 0 | F34: 0 | G34: 32711.293 | H34: 118480.15 | I34: 208861.52 | J34: 302880.98 | K34: 364674.6 | L34: 144670.69 | M34: 0 | N34: 16386.391 | O34: 44884.66 | P34: 0 | Q34: 0 | R34: 0 | S34: 32132.835 | T34: 116434.61 | U34: 204905.99 | V34: 296997.28 | W34: 358058.82 | X34: 137676.2 | Y34: 0 | Z34: 16130.024 | AA34: 44055.758 | AB34: 0 | AC34: 0 | AD34: 0 | AE34: 31546.897 | AF34: 114362.97 | AG34: 200897.47 | AH34: 291033.77 | AI34: 349551.9 | AJ34: 121398.77 | AK34: 0 | AL34: 15002.767 | AM34: 40208.612 | AN34: 0 | AO34: 0 | AP34: 0 | AQ34: 30953.256 | AR34: 112264.45 | AS34: 196834.38 | AT34: 284988.11 | AU34: 338093.47 | AV34: 101986.86 | AW34: 0 | AX34: 13854.981 | AY34: 36290.03 | AZ34: 0 | BA34: 0 | BB34: 0 | BC34: 30351.686 | BD34: 110138.26 | BE34: 192715.15 | BF34: 278857.92 | BG34: 324353.26 | BH34: 80105.583 | BI34: 0 | BJ34: 12686.114 | BK34: 32298.103
A35: Custo SEM Helexia (R$) — só gen própria, sem HCS03/BAT/banco | B35: 3035458.3 | C35: 50590.972 | D35: 0 | E35: 199280.04 | F35: 121596.58 | G35: 0 | H35: 0 | I35: 0 | J35: 0 | K35: 0 | L35: 0 | M35: 168200.38 | N35: 0 | O35: 0 | P35: 40190.639 | Q35: 248757.85 | R35: 125897.11 | S35: 0 | T35: 0 | U35: 0 | V35: 0 | W35: 0 | X35: 0 | Y35: 172118.13 | Z35: 0 | AA35: 0 | AB35: 43171.45 | AC35: 256179.81 | AD35: 130298.86 | AE35: 0 | AF35: 0 | AG35: 0 | AH35: 0 | AI35: 0 | AJ35: 0 | AK35: 188207.83 | AL35: 0 | AM35: 0 | AN35: 47800.146 | AO35: 263781.31 | AP35: 134804.37 | AQ35: 0 | AR35: 0 | AS35: 0 | AT35: 0 | AU35: 0 | AV35: 0 | AW35: 206128.7 | AX35: 0 | AY35: 0 | AZ35: 52526.813 | BA35: 271566.85 | BB35: 139416.28 | BC35: 0 | BD35: 0 | BE35: 0 | BF35: 0 | BG35: 0 | BH35: 0 | BI35: 225535.17 | BJ35: 0 | BK35: 0
A36: Custo COM Helexia — rede remanescente (R$) | B36: 461336.25 | C36: 7688.9375 | D36: 0 | E36: 80528.774 | F36: 0 | G36: 0 | H36: 0 | I36: 0 | J36: 0 | K36: 0 | L36: 0 | M36: 0 | N36: 0 | O36: 0 | P36: 0 | Q36: 0 | R36: 0 | S36: 0 | T36: 0 | U36: 0 | V36: 0 | W36: 0 | X36: 0 | Y36: 0 | Z36: 0 | AA36: 0 | AB36: 0 | AC36: 0 | AD36: 72492.947 | AE36: 0 | AF36: 0 | AG36: 0 | AH36: 0 | AI36: 0 | AJ36: 0 | AK36: 0 | AL36: 0 | AM36: 0 | AN36: 0 | AO36: 0 | AP36: 96084.011 | AQ36: 0 | AR36: 0 | AS36: 0 | AT36: 0 | AU36: 0 | AV36: 0 | AW36: 0 | AX36: 0 | AY36: 0 | AZ36: 0 | BA36: 119914.48 | BB36: 92316.036 | BC36: 0 | BD36: 0 | BE36: 0 | BF36: 0 | BG36: 0 | BH36: 0 | BI36: 0 | BJ36: 0 | BK36: 0
A37: ★ Economia mensal (R$) | B37: 2574122.1 | C37: 42902.035 | D37: 0 | E37: 118751.27 | F37: 121596.58 | G37: 0 | H37: 0 | I37: 0 | J37: 0 | K37: 0 | L37: 0 | M37: 168200.38 | N37: 0 | O37: 0 | P37: 40190.639 | Q37: 248757.85 | R37: 125897.11 | S37: 0 | T37: 0 | U37: 0 | V37: 0 | W37: 0 | X37: 0 | Y37: 172118.13 | Z37: 0 | AA37: 0 | AB37: 43171.45 | AC37: 256179.81 | AD37: 57805.909 | AE37: 0 | AF37: 0 | AG37: 0 | AH37: 0 | AI37: 0 | AJ37: 0 | AK37: 188207.83 | AL37: 0 | AM37: 0 | AN37: 47800.146 | AO37: 263781.31 | AP37: 38720.361 | AQ37: 0 | AR37: 0 | AS37: 0 | AT37: 0 | AU37: 0 | AV37: 0 | AW37: 206128.7 | AX37: 0 | AY37: 0 | AZ37: 52526.813 | BA37: 151652.37 | BB37: 47100.248 | BC37: 0 | BD37: 0 | BE37: 0 | BF37: 0 | BG37: 0 | BH37: 0 | BI37: 225535.17 | BJ37: 0 | BK37: 0
A39: AMD — Amandina (A3A)
A40: Consumo FP (kWh) | B40: 6692611.4 | C40: 111543.52 | D40: 182444.7 | E40: 234799.2 | F40: 134799.3 | G40: 18637.2 | H40: 24382.8 | I40: 20225.7 | J40: 17142.3 | K40: 75822.735 | L40: 214709.01 | M40: 177591.7 | N40: 80409.61 | O40: 105195.24 | P40: 187005.82 | Q40: 240669.18 | R40: 138169.28 | S40: 19103.13 | T40: 24992.37 | U40: 20731.342 | V40: 17570.857 | W40: 75822.735 | X40: 214709.01 | Y40: 177591.7 | Z40: 80409.61 | AA40: 105195.24 | AB40: 191680.96 | AC40: 246685.91 | AD40: 141623.51 | AE40: 19580.708 | AF40: 25617.179 | AG40: 21249.626 | AH40: 18010.129 | AI40: 77718.303 | AJ40: 220076.73 | AK40: 182031.5 | AL40: 82419.85 | AM40: 107825.12 | AN40: 196472.99 | AO40: 252853.06 | AP40: 145164.1 | AQ40: 20070.226 | AR40: 26257.609 | AS40: 21780.867 | AT40: 18460.382 | AU40: 79661.261 | AV40: 225578.65 | AW40: 186582.29 | AX40: 84480.347 | AY40: 110520.75 | AZ40: 201384.81 | BA40: 259174.38 | BB40: 148793.2 | BC40: 20571.982 | BD40: 26914.049 | BE40: 22325.388 | BF40: 18921.892 | BG40: 81652.792 | BH40: 231218.11 | BI40: 191246.84 | BJ40: 86592.355 | BK40: 113283.77
A41: Consumo Ponta (kWh) [via FA] | B41: 743623.55 | C41: 12393.726 | D41: 20271.6 | E41: 26088.8 | F41: 14977.7 | G41: 2070.8 | H41: 2709.2 | I41: 2247.3 | J41: 1904.7 | K41: 8424.7825 | L41: 23856.567 | M41: 19732.377 | N41: 8934.4125 | O41: 11688.382 | P41: 20778.39 | Q41: 26741.02 | R41: 15352.142 | S41: 2122.57 | T41: 2776.93 | U41: 2303.4825 | V41: 1952.3175 | W41: 8424.7825 | X41: 23856.567 | Y41: 19732.377 | Z41: 8934.4125 | AA41: 11688.382 | AB41: 21297.85 | AC41: 27409.545 | AD41: 15735.946 | AE41: 2175.6343 | AF41: 2846.3532 | AG41: 2361.0696 | AH41: 2001.1254 | AI41: 8635.4021 | AJ41: 24452.982 | AK41: 20225.687 | AL41: 9157.7728 | AM41: 11980.592 | AN41: 21830.296 | AO41: 28094.784 | AP41: 16129.345 | AQ41: 2230.0251 | AR41: 2917.5121 | AS41: 2420.0963 | AT41: 2051.1536 | AU41: 8851.2871 | AV41: 25064.306 | AW41: 20731.329 | AX41: 9386.7171 | AY41: 12280.107 | AZ41: 22376.053 | BA41: 28797.154 | BB41: 16532.578 | BC41: 2285.7757 | BD41: 2990.4499 | BE41: 2480.5987 | BF41: 2102.4324 | BG41: 9072.5693 | BH41: 25690.914 | BI41: 21249.612 | BJ41: 9621.3851 | BK41: 12587.11
A42: Geração própria (kWh) | B42: 4482675.2 | C42: 74711.253 | D42: 57829.52 | E42: 70669.44 | F42: 74466.16 | G42: 75546.72 | H42: 76725.44 | I42: 86384.48 | J42: 85283.12 | K42: 90950.164 | L42: 72540.992 | M42: 82037.272 | N42: 58672.921 | O42: 72926.814 | P42: 57540.372 | Q42: 70316.093 | R42: 74093.829 | S42: 75168.986 | T42: 76341.813 | U42: 85952.558 | V42: 84856.704 | W42: 90950.164 | X42: 72540.992 | Y42: 82037.272 | Z42: 58672.921 | AA42: 72926.814 | AB42: 57252.671 | AC42: 69964.512 | AD42: 73723.36 | AE42: 74793.141 | AF42: 75960.104 | AG42: 85522.795 | AH42: 84432.421 | AI42: 90495.413 | AJ42: 72178.287 | AK42: 81627.086 | AL42: 58379.557 | AM42: 72562.18 | AN42: 56966.407 | AO42: 69614.69 | AP42: 73354.743 | AQ42: 74419.176 | AR42: 75580.303 | AS42: 85095.181 | AT42: 84010.259 | AU42: 90042.936 | AV42: 71817.396 | AW42: 81218.951 | AX42: 58087.659 | AY42: 72199.369 | AZ42: 56681.575 | BA42: 69266.616 | BB42: 72987.97 | BC42: 74047.08 | BD42: 75202.402 | BE42: 84669.705 | BF42: 83590.207 | BG42: 89592.721 | BH42: 71458.309 | BI42: 80812.856 | BJ42: 57797.221 | BK42: 71838.372
...

Sheet Input_Consumo_GrupoA
A1: INPUT — CONSUMO ORÇADO GRUPO A | Fonte: Consumo_Orçado_2026_GD
A2: Azul = valores editáveis (fonte: arquivo fornecido) | Preto = fórmulas de projeção Y2/Y3
A3: Mês | B3: NHS FP (kWh) | C3: NHS Ponta (kWh) | D3: BAT FP (kWh) | E3: BAT Ponta (kWh) | F3: AMD FP (kWh) | G3: AMD Ponta (kWh)
A4: Jan | B4: 70769.9 | C4: 7863.3 | D4: 113967 | E4: 12663 | F4: 73973.4 | G4: 8219.3
A5: Fev | B5: 243719.7 | C5: 27080 | D5: 125874 | E5: 13986 | F5: 209472.2 | G5: 23274.7
A6: Mar | B6: 331874.1 | C6: 36874.9 | D6: 57499.2 | E6: 6388.8 | F6: 173260.2 | G6: 19251.1
A7: Abr | B7: 102778.3 | C7: 11419.8 | D7: 35640 | E7: 3960 | F7: 78448.4 | G7: 8716.5
A8: Mai | B8: 62814.2 | C8: 6979.4 | D8: 79603.2 | E8: 8844.8 | F8: 102629.5 | G8: 11403.3
A9: Jun | B9: 108694.9 | C9: 12077.2 | D9: 78336 | E9: 8704 | F9: 182444.7 | G9: 20271.6
A10: Jul | B10: 328938.1 | C10: 36548.7 | D10: 115718.4 | E10: 12857.6 | F10: 234799.2 | G10: 26088.8
A11: Ago | B11: 190977.6 | C11: 21219.7 | D11: 23364 | E11: 2596 | F11: 134799.3 | G11: 14977.7
A12: Set | B12: 126478.8 | C12: 14053.2 | D12: 10800 | E12: 1200 | F12: 18637.2 | G12: 2070.8
A13: Out | B13: 28215 | C13: 3135 | D13: 10800 | E13: 1200 | F13: 24382.8 | G13: 2709.2
A14: Nov | B14: 42209.6 | C14: 4690 | D14: 10800 | E14: 1200 | F14: 20225.7 | G14: 2247.3
A15: Dez | B15: 42209.6 | C15: 4690 | D15: 3402 | E15: 378 | F15: 17142.3 | G15: 1904.7
A17: Crescimento Y2 aplicado automaticamente via Premissas!$B$21 (atualmente 2,5%). Altere lá para que todos os 18 UCs sejam atualizados.

Sheet Dados_Produção_Copasul

Sheet Amandina
A1: Unidade | B1: Data | C1: Geração (kWh) | D1: Yf Diário (kWh/kWp)
A2: Amandina | B2: 45716 | C2: 190.1 | D2: =IFERROR(C2/VLOOKUP(A2,Usinas!$A:$B,2,FALSE()),"") -> 0.27274032 | F2: Geração Mensal | H2: Mês | I2: Kwh | J2: MWh | L2: Proxi Bataypora | P2: proxy Rate | Q2: 0.8
A3: Amandina | B3: 45717 | C3: 249.5 | D3: =IFERROR(C3/VLOOKUP(A3,Usinas!$A:$B,2,FALSE()),"") -> 0.3579627 | F3: 45658 | G3: =+F3+30 -> 45688 | H3: =+F3 -> 45658 | I3: 0 | J3: 0 | L3: =+Batayporã!J3*Amandina!$Q$2 -> 91.4072
A4: Amandina | B4: 45718 | C4: 295.9 | D4: =IFERROR(C4/VLOOKUP(A4,Usinas!$A:$B,2,FALSE()),"") -> 0.42453372 | F4: =+B2 -> 45716 | G4: =+F4 -> 45716 | H4: =+F4 -> 45716 | I4: =SUMIFS($C$1:$C$366, $B$1:$B$366, ">="&F4, $B$1:$B$366, "<="&G4) -> 190.1 | J4: =+I4/1000 -> 0.1901 | L4: =+Batayporã!J4*Amandina!$Q$2 -> 72.90552
A5: Amandina | B5: 45719 | C5: 250.2 | D5: =IFERROR(C5/VLOOKUP(A5,Usinas!$A:$B,2,FALSE()),"") -> 0.358967 | F5: =+G4+1 -> 45717 | G5: =+F5+30 -> 45747 | H5: =+F5 -> 45717 | I5: =SUMIFS($C$1:$C$366, $B$1:$B$366, ">="&F5, $B$1:$B$366, "<="&G5) -> 7913.8 | J5: =+I5/1000 -> 7.9138 | L5: =+Batayporã!J5*Amandina!$Q$2 -> 82.44952
A6: Amandina | B6: 45720 | C6: 256.6 | D6: =IFERROR(C6/VLOOKUP(A6,Usinas!$A:$B,2,FALSE()),"") -> 0.36814921 | F6: =+G5+1 -> 45748 | G6: =+F6+29 -> 45777 | H6: =+F6 -> 45748 | I6: =SUMIFS($C$1:$C$366, $B$1:$B$366, ">="&F6, $B$1:$B$366, "<="&G6) -> 23902.8 | J6: =+I6/1000 -> 23.9028 | L6: =+Batayporã!J6*Amandina!$Q$2 -> 58.96776
A7: Amandina | B7: 45721 | C7: 241 | D7: =IFERROR(C7/VLOOKUP(A7,Usinas!$A:$B,2,FALSE()),"") -> 0.34576758 | F7: =+G6+1 -> 45778 | G7: =+F7+30 -> 45808 | H7: =+F7 -> 45778 | I7: =SUMIFS($C$1:$C$366, $B$1:$B$366, ">="&F7, $B$1:$B$366, "<="&G7) -> 28781.7 | J7: =+I7/1000 -> 28.7817 | L7: =+Batayporã!J7*Amandina!$Q$2 -> 73.29328
A8: Amandina | B8: 45722 | C8: 194.3 | D8: =IFERROR(C8/VLOOKUP(A8,Usinas!$A:$B,2,FALSE()),"") -> 0.27876614 | F8: =+G7+1 -> 45809 | G8: =+F8+29 -> 45838 | H8: =+F8 -> 45809 | I8: =SUMIFS($C$1:$C$366, $B$1:$B$366, ">="&F8, $B$1:$B$366, "<="&G8) -> 20798.2 | J8: =+I8/1000 -> 20.7982 | L8: =+Batayporã!J8*Amandina!$Q$2 -> 57.82952
A9: Amandina | B9: 45723 | C9: 89.9 | D9: =IFERROR(C9/VLOOKUP(A9,Usinas!$A:$B,2,FALSE()),"") -> 0.12898135 | F9: =+G8+1 -> 45839 | G9: =+F9+30 -> 45869 | H9: =+F9 -> 45839 | I9: =SUMIFS($C$1:$C$366, $B$1:$B$366, ">="&F9, $B$1:$B$366, "<="&G9) -> 37317.8 | J9: =+I9/1000 -> 37.3178 | L9: =+Batayporã!J9*Amandina!$Q$2 -> 70.66944
A10: Amandina | B10: 45724 | C10: 357.6 | D10: =IFERROR(C10/VLOOKUP(A10,Usinas!$A:$B,2,FALSE()),"") -> 0.51305595 | F10: =+G9+1 -> 45870 | G10: =+F10+30 -> 45900 | H10: =+F10 -> 45870 | I10: =SUMIFS($C$1:$C$366, $B$1:$B$366, ">="&F10, $B$1:$B$366, "<="&G10) -> 16177.9 | J10: =+I10/1000 -> 16.1779 | L10: =+Batayporã!J10*Amandina!$Q$2 -> 74.46616
A11: Amandina | B11: 45725 | C11: 287 | D11: =IFERROR(C11/VLOOKUP(A11,Usinas!$A:$B,2,FALSE()),"") -> 0.41176471 | F11: =+G10+1 -> 45901 | G11: =+F11+29 -> 45930 | H11: =+F11 -> 45901 | I11: =SUMIFS($C$1:$C$366, $B$1:$B$366, ">="&F11, $B$1:$B$366, "<="&G11) -> 37738.8 | J11: =+I11/1000 -> 37.7388 | L11: =+Batayporã!J11*Amandina!$Q$2 -> 75.54672
A12: Amandina | B12: 45726 | C12: 248.1 | D12: =IFERROR(C12/VLOOKUP(A12,Usinas!$A:$B,2,FALSE()),"") -> 0.35595409 | F12: =+G11+1 -> 45931 | G12: =+F12+30 -> 45961 | H12: =+F12 -> 45931 | I12: =SUMIFS($C$1:$C$366, $B$1:$B$366, ">="&F12, $B$1:$B$366, "<="&G12) -> 40322 | J12: =+I12/1000 -> 40.322 | L12: =+Batayporã!J12*Amandina!$Q$2 -> 76.72544
A13: Amandina | B13: 45727 | C13: 142.1 | D13: =IFERROR(C13/VLOOKUP(A13,Usinas!$A:$B,2,FALSE()),"") -> 0.20387374 | F13: =+G12+1 -> 45962 | G13: =+F13+29 -> 45991 | H13: =+F13 -> 45962 | I13: =SUMIFS($C$1:$C$366, $B$1:$B$366, ">="&F13, $B$1:$B$366, "<="&G13) -> 36462.9 | J13: =+I13/1000 -> 36.4629 | L13: =+Batayporã!J13*Amandina!$Q$2 -> 86.38448
A14: Amandina | B14: 45728 | C14: 224.8 | D14: =IFERROR(C14/VLOOKUP(A14,Usinas!$A:$B,2,FALSE()),"") -> 0.32252511 | F14: =+G13+1 -> 45992 | G14: =+F14+30 -> 46022 | H14: =+F14 -> 45992 | I14: =SUMIFS($C$1:$C$366, $B$1:$B$366, ">="&F14, $B$1:$B$366, "<="&G14) -> 19968.1 | J14: =+I14/1000 -> 19.9681 | L14: =+Batayporã!J14*Amandina!$Q$2 -> 85.28312
A15: Amandina | B15: 45729 | C15: 242.3 | D15: =IFERROR(C15/VLOOKUP(A15,Usinas!$A:$B,2,FALSE()),"") -> 0.34763271
A16: Amandina | B16: 45730 | C16: 288.4 | D16: =IFERROR(C16/VLOOKUP(A16,Usinas!$A:$B,2,FALSE()),"") -> 0.41377331
A17: Amandina | B17: 45731 | C17: 347.5 | D17: =IFERROR(C17/VLOOKUP(A17,Usinas!$A:$B,2,FALSE()),"") -> 0.49856528 | L17: =+SUM(L2:L14) -> 905.92816
A18: Amandina | B18: 45732 | C18: 310.4 | D18: =IFERROR(C18/VLOOKUP(A18,Usinas!$A:$B,2,FALSE()),"") -> 0.44533716
A19: Amandina | B19: 45733 | C19: 278 | D19: =IFERROR(C19/VLOOKUP(A19,Usinas!$A:$B,2,FALSE()),"") -> 0.39885222
A20: Amandina | B20: 45734 | C20: 222.1 | D20: =IFERROR(C20/VLOOKUP(A20,Usinas!$A:$B,2,FALSE()),"") -> 0.31865136
A21: Amandina | B21: 45735 | C21: 332.3 | D21: =IFERROR(C21/VLOOKUP(A21,Usinas!$A:$B,2,FALSE()),"") -> 0.47675753
A22: Amandina | B22: 45736 | C22: 318.3 | D22: =IFERROR(C22/VLOOKUP(A22,Usinas!$A:$B,2,FALSE()),"") -> 0.45667145
A23: Amandina | B23: 45737 | C23: 321.4 | D23: =IFERROR(C23/VLOOKUP(A23,Usinas!$A:$B,2,FALSE()),"") -> 0.46111908
A24: Amandina | B24: 45738 | C24: 272.8 | D24: =IFERROR(C24/VLOOKUP(A24,Usinas!$A:$B,2,FALSE()),"") -> 0.39139168
A25: Amandina | B25: 45739 | C25: 250.5 | D25: =IFERROR(C25/VLOOKUP(A25,Usinas!$A:$B,2,FALSE()),"") -> 0.35939742
A26: Amandina | B26: 45740 | C26: 281.2 | D26: =IFERROR(C26/VLOOKUP(A26,Usinas!$A:$B,2,FALSE()),"") -> 0.40344333
A27: Amandina | B27: 45741 | C27: 264.2 | D27: =IFERROR(C27/VLOOKUP(A27,Usinas!$A:$B,2,FALSE()),"") -> 0.37905308
A28: Amandina | B28: 45742 | C28: 275 | D28: =IFERROR(C28/VLOOKUP(A28,Usinas!$A:$B,2,FALSE()),"") -> 0.39454806
A29: Amandina | B29: 45743 | C29: 297 | D29: =IFERROR(C29/VLOOKUP(A29,Usinas!$A:$B,2,FALSE()),"") -> 0.42611191
... A356: Amandina | B356: 46022 | C356: 990.9 | D356: =IFERROR(C356/VLOOKUP(A356,Usinas!$A:$B,2,FALSE()),"") -> 1.4216643

Sheet Batayporã
A1: Unidade | B1: Data | C1: Geração (kWh) | D1: Yf Diário (kWh/kWp)
A2: Batayporã | B2: 45658 | C2: 3715.4 | D2: =IFERROR(C2/VLOOKUP(A2,Usinas!$A:$B,2,FALSE()),"") -> 5.2925926 | F2: Geração Mensal | H2: Mês | I2: Kwh | J2: MWh
A3: Batayporã | B3: 45659 | C3: 2498.6 | D3: =IFERROR(C3/VLOOKUP(A3,Usinas!$A:$B,2,FALSE()),"") -> 3.5592593 | F3: =+B2 -> 45658 | G3: =+B32 -> 45688 | H3: =+F3 -> 45658 | I3: =SUMIFS($C$1:$C$366, $B$1:$B$366, ">="&F3, $B$1:$B$366, "<="&G3) -> 114259 | J3: =+I3/1000 -> 114.259
A4: Batayporã | B4: 45660 | C4: 4061.9 | D4: =IFERROR(C4/VLOOKUP(A4,Usinas!$A:$B,2,FALSE()),"") -> 5.7861823 | F4: =+B33 -> 45689 | G4: =+F4+27 -> 45716 | H4: =+F4 -> 45689 | I4: =SUMIFS($C$1:$C$366, $B$1:$B$366, ">="&F4, $B$1:$B$366, "<="&G4) -> 91131.9 | J4: =+I4/1000 -> 91.1319
A5: Batayporã | B5: 45661 | C5: 3262.5 | D5: =IFERROR(C5/VLOOKUP(A5,Usinas!$A:$B,2,FALSE()),"") -> 4.6474359 | F5: =+G4+1 -> 45717 | G5: =+F5+30 -> 45747 | H5: =+F5 -> 45717 | I5: =SUMIFS($C$1:$C$366, $B$1:$B$366, ">="&F5, $B$1:$B$366, "<="&G5) -> 103061.9 | J5: =+I5/1000 -> 103.0619
A6: Batayporã | B6: 45662 | C6: 4061 | D6: =IFERROR(C6/VLOOKUP(A6,Usinas!$A:$B,2,FALSE()),"") -> 5.7849003 | F6: =+G5+1 -> 45748 | G6: =+F6+29 -> 45777 | H6: =+F6 -> 45748 | I6: =SUMIFS($C$1:$C$366, $B$1:$B$366, ">="&F6, $B$1:$B$366, "<="&G6) -> 73709.7 | J6: =+I6/1000 -> 73.7097
A7: Batayporã | B7: 45663 | C7: 4431.9 | D7: =IFERROR(C7/VLOOKUP(A7,Usinas!$A:$B,2,FALSE()),"") -> 6.3132479 | F7: =+G6+1 -> 45778 | G7: =+F7+30 -> 45808 | H7: =+F7 -> 45778 | I7: =SUMIFS($C$1:$C$366, $B$1:$B$366, ">="&F7, $B$1:$B$366, "<="&G7) -> 91616.6 | J7: =+I7/1000 -> 91.6166
A8: Batayporã | B8: 45664 | C8: 4460 | D8: =IFERROR(C8/VLOOKUP(A8,Usinas!$A:$B,2,FALSE()),"") -> 6.3532764 | F8: =+G7+1 -> 45809 | G8: =+F8+29 -> 45838 | H8: =+F8 -> 45809 | I8: =SUMIFS($C$1:$C$366, $B$1:$B$366, ">="&F8, $B$1:$B$366, "<="&G8) -> 72286.9 | J8: =+I8/1000 -> 72.2869
A9: Batayporã | B9: 45665 | C9: 3524.3 | D9: =IFERROR(C9/VLOOKUP(A9,Usinas!$A:$B,2,FALSE()),"") -> 5.0203704 | F9: =+G8+1 -> 45839 | G9: =+F9+30 -> 45869 | H9: =+F9 -> 45839 | I9: =SUMIFS($C$1:$C$366, $B$1:$B$366, ">="&F9, $B$1:$B$366, "<="&G9) -> 88336.8 | J9: =+I9/1000 -> 88.3368
A10: Batayporã | B10: 45666 | C10: 4744.5 | D10: =IFERROR(C10/VLOOKUP(A10,Usinas!$A:$B,2,FALSE()),"") -> 6.758547 | F10: =+G9+1 -> 45870 | G10: =+F10+30 -> 45900 | H10: =+F10 -> 45870 | I10: =SUMIFS($C$1:$C$366, $B$1:$B$366, ">="&F10, $B$1:$B$366, "<="&G10) -> 93082.7 | J10: =+I10/1000 -> 93.0827
A11: Batayporã | B11: 45667 | C11: 3305 | D11: =IFERROR(C11/VLOOKUP(A11,Usinas!$A:$B,2,FALSE()),"") -> 4.7079772 | F11: =+G10+1 -> 45901 | G11: =+F11+29 -> 45930 | H11: =+F11 -> 45901 | I11: =SUMIFS($C$1:$C$366, $B$1:$B$366, ">="&F11, $B$1:$B$366, "<="&G11) -> 94433.4 | J11: =+I11/1000 -> 94.4334
A12: Batayporã | B12: 45668 | C12: 4671.1 | D12: =IFERROR(C12/VLOOKUP(A12,Usinas!$A:$B,2,FALSE()),"") -> 6.6539886 | F12: =+G11+1 -> 45931 | G12: =+F12+30 -> 45961 | H12: =+F12 -> 45931 | I12: =SUMIFS($C$1:$C$366, $B$1:$B$366, ">="&F12, $B$1:$B$366, "<="&G12) -> 95906.8 | J12: =+I12/1000 -> 95.9068
A13: Batayporã | B13: 45669 | C13: 4211.9 | D13: =IFERROR(C13/VLOOKUP(A13,Usinas!$A:$B,2,FALSE()),"") -> 5.9998575 | F13: =+G12+1 -> 45962 | G13: =+F13+29 -> 45991 | H13: =+F13 -> 45962 | I13: =SUMIFS($C$1:$C$366, $B$1:$B$366, ">="&F13, $B$1:$B$366, "<="&G13) -> 107980.6 | J13: =+I13/1000 -> 107.9806
A14: Batayporã | B14: 45670 | C14: 4327.1 | D14: =IFERROR(C14/VLOOKUP(A14,Usinas!$A:$B,2,FALSE()),"") -> 6.1639601 | F14: =+G13+1 -> 45992 | G14: =+F14+30 -> 46022 | H14: =+F14 -> 45992 | I14: =SUMIFS($C$1:$C$366, $B$1:$B$366, ">="&F14, $B$1:$B$366, "<="&G14) -> 106603.9 | J14: =+I14/1000 -> 106.6039
A15: Batayporã | B15: 45671 | C15: 4370 | D15: =IFERROR(C15/VLOOKUP(A15,Usinas!$A:$B,2,FALSE()),"") -> 6.2250712
A16: Batayporã | B16: 45672 | C16: 4324 | D16: =IFERROR(C16/VLOOKUP(A16,Usinas!$A:$B,2,FALSE()),"") -> 6.1595442
A17: Batayporã | B17: 45673 | C17: 4173.6 | D17: =IFERROR(C17/VLOOKUP(A17,Usinas!$A:$B,2,FALSE()),"") -> 5.9452991
A18: Batayporã | B18: 45674 | C18: 2490.4 | D18: =IFERROR(C18/VLOOKUP(A18,Usinas!$A:$B,2,FALSE()),"") -> 3.5475783
A19: Batayporã | B19: 45675 | C19: 2419.1 | D19: =IFERROR(C19/VLOOKUP(A19,Usinas!$A:$B,2,FALSE()),"") -> 3.4460114
A20: Batayporã | B20: 45676 | C20: 3206.2 | D20: =IFERROR(C20/VLOOKUP(A20,Usinas!$A:$B,2,FALSE()),"") -> 4.5672365
A21: Batayporã | B21: 45677 | C21: 2768 | D21: =IFERROR(C21/VLOOKUP(A21,Usinas!$A:$B,2,FALSE()),"") -> 3.9430199
A22: Batayporã | B22: 45678 | C22: 3998.4 | D22: =IFERROR(C22/VLOOKUP(A22,Usinas!$A:$B,2,FALSE()),"") -> 5.6957265
A23: Batayporã | B23: 45679 | C23: 2927.9 | D23: =IFERROR(C23/VLOOKUP(A23,Usinas!$A:$B,2,FALSE()),"") -> 4.1707977
A24: Batayporã | B24: 45680 | C24: 3035.9 | D24: =IFERROR(C24/VLOOKUP(A24,Usinas!$A:$B,2,FALSE()),"") -> 4.3246439
A25: Batayporã | B25: 45681 | C25: 4013.7 | D25: =IFERROR(C25/VLOOKUP(A25,Usinas!$A:$B,2,FALSE()),"") -> 5.7175214
A26: Batayporã | B26: 45682 | C26: 3852.9 | D26: =IFERROR(C26/VLOOKUP(A26,Usinas!$A:$B,2,FALSE()),"") -> 5.4884615
