Workbook

Sheet Resumo
B1: ="SIMULAÇÃO RATEIO FIXO — "&Premissas!$B$13&" × COPASUL | Resumo Executivo" -> SIMULAÇÃO RATEIO FIXO — Cassilândia 03 × COPASUL | Resumo Executivo
B2: ="18 Unidades Consumidoras · Jun/2026–Mai/2031 · Energisa MS · Usina: "&Premissas!$B$13 -> 18 Unidades Consumidoras · Jun/2026–Mai/2031 · Energisa MS · Usina: Cassilândia 03
B4: ⚡ GERAÇÃO INJETADA | D4: 📄 PPA PAGO À HELEXIA | F4: ✅ ECONOMIA LÍQUIDA | H4: 🏦 BANCO RESIDUAL | J4: 🌟 VALOR TOTAL
B5: =Simulacao!B6/1000000 -> 8.3804424 | D5: =Simulacao!B7 -> 4542510.4 | F5: =Simulacao!B252 -> 2673060.5 | H5: =Simulacao!B273*Premissas!$B$17 -> 460824.2 | J5: =Simulacao!B278 -> 3247039.2
B6: 3,375 MWh injetados em 60 meses | D6: Custo total do contrato PPA | F6: Rede evitada menos PPA pago | H6: Banco total Copasul @ PPA | J6: Economia + banco ATRIBUÍVEL a Helexia
B8: A. CUSTO COPASUL — ANÁLISE 24 MESES | I8: B. INDICADORES-CHAVE
B9: COMPONENTE | E9: R$ | F9: % | G9: R$/mês | I9: Usina contratada | K9: =Premissas!$B$13 -> Cassilândia 03
B10: Custo SEM Helexia — baseline 60m | E10: =Simulacao!B249 -> 8246596.4 | F10: =Simulacao!B249/Simulacao!B249 -> 1 | G10: =(Simulacao!B249)/60 -> 137443.27 | I10: Período do contrato | K10: Jun/2026 – Mai/2031 (60 meses)
B11: Custo rede remanescente (COM Helexia) | E11: =Simulacao!B250 -> 1031025.5 | F11: =Simulacao!B250/Simulacao!B249 -> 0.12502437 | G11: =(Simulacao!B250)/60 -> 17183.758 | I11: Potência contratada | K11: =VLOOKUP(Premissas!$B$13,PVSYST_Helexia!$B$5:$F$7,5,0)&" kWac" -> 625 kWac
B12: PPA pago à Helexia | E12: =Simulacao!B7 -> 4542510.4 | F12: =Simulacao!B7/Simulacao!B249 -> 0.55083457 | G12: =(Simulacao!B7)/60 -> 75708.506 | I12: Geração P50 total | K12: =Simulacao!B6/1000 -> 8380.4424
B13: Custo total COM Helexia (rede + PPA) | E13: =Simulacao!B251 -> 5573535.9 | F13: =Simulacao!B251/Simulacao!B249 -> 0.67585894 | G13: =(Simulacao!B251)/60 -> 92892.264 | I13: PPA (R$/kWh) | K13: =Premissas!$B$17 -> 0.4425
B14: ★ ECONOMIA LÍQUIDA (rede − PPA) | E14: =Simulacao!B252 -> 2673060.5 | F14: =Simulacao!B252/Simulacao!B249 -> 0.32414106 | G14: =(Simulacao!B252)/60 -> 44551.009 | I14: Tarifa Grupo A FP | K14: =Premissas!$B$5 -> 0.52647111
B15: + Banco atribuível Helexia @ PPA (net NHS/AMD + Grupo B) | E15: =Simulacao!B285 -> 573978.69 | F15: =IFERROR(Simulacao!B285/Simulacao!B249,0) -> 0.069601889 | G15: =Simulacao!B285/60 -> 9566.3115 | I15: Tarifa Grupo B3 | K15: =Premissas!$B$7 -> 1.1568636
B16: ★ VALOR TOTAL HELEXIA (economia + banco atribuível) | E16: =Simulacao!B278 -> 3247039.2 | F16: =Simulacao!B278/Simulacao!B249 -> 0.39374295 | G16: =(Simulacao!B278)/60 -> 54117.32 | I16: Economia média/mês | K16: =Simulacao!B252/60 -> 44551.009
I17: % redução custo Copasul | K17: =IFERROR(Simulacao!B252/Simulacao!B249,0) -> 0.32414106
I18: Banco residual (kWh) | K18: =Simulacao!B273 -> 1041410.6
B20: C. ANÁLISE VISUAL — ECONOMIA E BANCO DE CRÉDITOS
P22: Mês | Q22: SEM Helexia | R22: PPA | S22: Rede COM | T22: Eco mensal | U22: Eco acumulada
P23: Jun/26 | Q23: =Simulacao!D249 -> 174954.21 | R23: =Simulacao!D7 -> 61449.444 | S23: =Simulacao!D250 -> 144748.07 | T23: =Simulacao!D252 -> -31243.305 | U23: =T23 -> -31243.305
P24: Jul/26 | Q24: =Simulacao!E249 -> 220226.76 | R24: =Simulacao!E7 -> 64680.756 | S24: =Simulacao!E250 -> 186553.14 | T24: =Simulacao!E252 -> -31007.137 | U24: =U23+T24 -> -62250.442
P25: Ago/26 | Q25: =Simulacao!F249 -> 124872.64 | R25: =Simulacao!F7 -> 77645.652 | S25: =Simulacao!F250 -> 86971.897 | T25: =Simulacao!F252 -> -39744.909 | U25: =U24+T25 -> -101995.35
P26: Set/26 | Q26: =Simulacao!G249 -> 47721.487 | R26: =Simulacao!G7 -> 72858.156 | S26: =Simulacao!G250 -> 3013.3082 | T26: =Simulacao!G252 -> -28149.977 | U26: =U25+T26 -> -130145.33
P27: Out/26 | Q27: =Simulacao!H249 -> 48546.433 | R27: =Simulacao!H7 -> 74875.248 | S27: =Simulacao!H250 -> 0 | T27: =Simulacao!H252 -> -26328.815 | U27: =U26+T27 -> -156474.14
P28: Nov/26 | Q28: =Simulacao!I249 -> 48386.833 | R28: =Simulacao!I7 -> 72397.248 | S28: =Simulacao!I250 -> 0 | T28: =Simulacao!I252 -> -24010.415 | U28: =U27+T28 -> -180484.56
P29: Dez/26 | Q29: =Simulacao!J249 -> 50008.847 | R29: =Simulacao!J7 -> 68744.676 | S29: =Simulacao!J250 -> 0 | T29: =Simulacao!J252 -> -18735.829 | U29: =U28+T29 -> -199220.39
P30: Jan/27 | Q30: =Simulacao!K249 -> 47574.253 | R30: =Simulacao!K7 -> 70585.483 | S30: =Simulacao!K250 -> 0 | T30: =Simulacao!K252 -> -23011.23 | U30: =U29+T30 -> -222231.62
P31: Fev/27 | Q31: =Simulacao!L249 -> 50426.883 | R31: =Simulacao!L7 -> 62897.711 | S31: =Simulacao!L250 -> 0 | T31: =Simulacao!L252 -> -12470.828 | U31: =U30+T31 -> -234702.45
P32: Mar/27 | Q32: =Simulacao!M249 -> 45168.521 | R32: =Simulacao!M7 -> 72143.749 | S32: =Simulacao!M250 -> 0 | T32: =Simulacao!M252 -> -26975.227 | U32: =U31+T32 -> -261677.67
P33: Abr/27 | Q33: =Simulacao!N249 -> 39380.616 | R33: =Simulacao!N7 -> 71985.95 | S33: =Simulacao!N250 -> 0 | T33: =Simulacao!N252 -> -32605.333 | U33: =U32+T33 -> -294283.01
P34: Mai/27 | Q34: =Simulacao!O249 -> 36641.224 | R34: =Simulacao!O7 -> 67370.328 | S34: =Simulacao!O250 -> 0 | T34: =Simulacao!O252 -> -30729.103 | U34: =U33+T34 -> -325012.11
P35: Jun/27 | Q35: =Simulacao!P249 -> 136929.15 | R35: =Simulacao!P7 -> 63893.596 | S35: =Simulacao!P250 -> 129586.67 | T35: =Simulacao!P252 -> -56551.124 | U35: =U34+T35 -> -381563.23
P36: Jul/27 | Q36: =Simulacao!Q249 -> 536959.78 | R36: =Simulacao!Q7 -> 67253.433 | S36: =Simulacao!Q250 -> 201204.56 | T36: =Simulacao!Q252 -> 268501.79 | U36: =U35+T36 -> -113061.45
P37: Ago/27 | Q37: =Simulacao!R249 -> 287060.8 | R37: =Simulacao!R7 -> 80734.008 | S37: =Simulacao!R250 -> 94150.865 | T37: =Simulacao!R252 -> 112175.92 | U37: =U36+T37 -> -885.52191
P38: Set/27 | Q38: =Simulacao!S249 -> 51849.395 | R38: =Simulacao!S7 -> 75756.089 | S38: =Simulacao!S250 -> 0 | T38: =Simulacao!S252 -> -23906.694 | U38: =U37+T38 -> -24792.216
P39: Out/27 | Q39: =Simulacao!T249 -> 52745.7 | R39: =Simulacao!T7 -> 77853.411 | S39: =Simulacao!T250 -> 0 | T39: =Simulacao!T252 -> -25107.711 | U39: =U38+T39 -> -49899.927
P40: Nov/27 | Q40: =Simulacao!U249 -> 52572.294 | R40: =Simulacao!U7 -> 75276.849 | S40: =Simulacao!U250 -> 0 | T40: =Simulacao!U252 -> -22704.555 | U40: =U39+T40 -> -72604.482
P41: Dez/27 | Q41: =Simulacao!V249 -> 54334.613 | R41: =Simulacao!V7 -> 71478.995 | S41: =Simulacao!V250 -> 0 | T41: =Simulacao!V252 -> -17144.383 | U41: =U40+T41 -> -89748.864
P42: Jan/28 | Q42: =Simulacao!W249 -> 50428.708 | R42: =Simulacao!W7 -> 73761.83 | S42: =Simulacao!W250 -> 0 | T42: =Simulacao!W252 -> -23333.122 | U42: =U41+T42 -> -113081.99
P43: Fev/28 | Q43: =Simulacao!X249 -> 53452.496 | R43: =Simulacao!X7 -> 65728.108 | S43: =Simulacao!X250 -> 0 | T43: =Simulacao!X252 -> -12275.612 | U43: =U42+T43 -> -125357.6
P44: Mar/28 | Q44: =Simulacao!Y249 -> 252928.82 | R44: =Simulacao!Y7 -> 75390.217 | S44: =Simulacao!Y250 -> 0 | T44: =Simulacao!Y252 -> 177538.6 | U44: =U43+T44 -> 52181.003
...

Sheet Premissas
A1: ="PREMISSAS — "&Premissas!$B$13&" × Copasul | Energisa MS" -> PREMISSAS — Cassilândia 03 × Copasul | Energisa MS | M1: 🎯 OTIMIZAÇÃO RATEIO — SOLVER CONFIG
A2: Azul = inputs editáveis | Preto = fórmulas | Verde = links entre abas | M2: Siga o passo a passo abaixo para maximizar Economia Líquida via Excel Solver
A4: A. TARIFAS ENERGISA MS (com tributos ICMS 17% + PIS/COFINS) | M4: ① CÉLULA OBJETIVO (aponte o Solver aqui): | P4: ENDEREÇO | Q4: VALOR ATUAL | R4: OBJETIVO
A5: Tarifa Grupo A FP com tributos (R$/kWh) | B5: 0.52647111 | C5: ← T_AFP: edit here | M5: Economia Líquida Copasul 24m (R$) | P5: Premissas!K5 | Q5: =Simulacao!B252 -> 2673060.5 | R5: ↑ MAXIMIZAR
A6: Tarifa Grupo A Ponta com tributos (R$/kWh) | B6: 2.9723794 | C6: ← T_APT: edit here
A7: Tarifa Grupo B3 com tributos (R$/kWh) | B7: 1.1568636 | C7: ← T_B3: edit here | M7: ② ATIVAR SOLVER (se ainda não estiver ativo) | O7: Arquivo → Opções → Suplementos → Gerenciar: Suplementos do Excel → Ir... → ✓ Solver Add-in → OK
A8: FA = TE_FP / TE_Ponta | B8: 0.60426705 | C8: ← FA: edit here | M8: ③ ABRIR SOLVER | O8: Guia Dados → botão "Solver" (canto direito da faixa de opções)
A9: ICMS (%) | B9: 0.17 | C9: ← ICMS: edit here | M9: ④ CONFIGURAR OBJETIVO | O9: Definir Objetivo: selecione a célula Premissas!K5 → marque ● Máx
A10: PIS + COFINS (%) | B10: 0.0855 | C10: ← PIS_COFINS: edit here | M10: ⑤ DEFINIR CÉLULAS VARIÁVEIS | O10: Alterando Células de Variáveis: Premissas!$B$33:$K$50 (170 variáveis = 17 UCs × 10 períodos)
A11: ICMS isenção autoconsumo remoto ativa? (Art. 23-A RICMS/MS) → 'Sim' = isento | 'Não' = ICMS cobrado sobre kWh compensados pelo CS3 | B11: Sim | C11: =IF($B$11="Sim",0,$B$5*$B$9/(1+$B$9)) -> 0 | D11: =IF($B$11="Sim",0,$B$6*$B$9/(1+$B$9)) -> 0 | E11: =IF($B$11="Sim",0,$B$7*$B$9/(1+$B$9)) -> 0 | F11: ← B=toggle (Sim/Não) | C=ICMS A_FP D=ICMS A_Ponta E=ICMS Grupo B (R$/kWh) — tudo 0 se Sim
A12: B. CONDIÇÕES DO CONTRATO | M12: ⑥ ADICIONAR AS RESTRIÇÕES (Adicionar → preencher cada linha → OK)
A13: Usina | B13: Cassilândia 03 | M13: Célula / Intervalo | O13: Relação | P13: Valor / Restrição | R13: Descrição
A14: Distribuidora | B14: Energisa MS | M14: Premissas!$B$33:$K$50 | O14: >= | P14: 0 | R14: Todos os rateios ≥ 0% (sem valores negativos, P1–P10)
A15: Início do contrato | B15: Jun/2026 | M15: Premissas!$B$51 | O15: = | P15: 1 | R15: Soma P1 = 100% (Jun–Set/26)
A16: Prazo (meses) | B16: 60 | M16: Premissas!$C$51 | O16: = | P16: 1 | R16: Soma P2 = 100% (Out/26–Mar/27)
A17: PPA Helexia CS3 (R$/kWh) | B17: 0.4425 | D17: → PPA Ajustado Y1 (R$/kWh): | E17: =B17*(1+B128) -> 0.4956 | M17: Premissas!$D$51 | O17: = | P17: 1 | R17: Soma P3 = 100% (Abr–Set/27)
A18: H. CENÁRIO CONCORRENTE — ENERGIA ASSINATURA GRUPO B (ex: Plin Energia) | M18: Premissas!$E$51 | O18: = | P18: 1 | R18: Soma P4 = 100% (Out/27–Mai/28)
A19: Grupo B tem contrato Assinatura GD concorrente? | B19: Sim | C19: Desconto (%): | D19: 0.2 | E19: Tarifa B3 SEM efetiva: | F19: =IF(B19="Sim",B7*(1-D19),B7) -> 0.92549092 | M19: Premissas!$F$51 | O19: = | P19: 1 | R19: Soma P5 = 100% (Jun–Nov/28)
A20: C. PREMISSAS DE CRESCIMENTO E DEGRADAÇÃO | M20: Premissas!$G$51 | O20: = | P20: 1 | R20: Soma P6 = 100% (Dez/28–Mai/29)
A21: Crescimento consumo Y2 vs Y1 (%) | B21: 0.025 | C21: ← 2.5% editável | aplica a TODOS os UCs | M21: Premissas!$H$51 | O21: = | P21: 1 | R21: Soma P7 = 100% (Jun–Nov/29)
A22: Crescimento consumo Y3 parcial (Dez/27-Mai/28) (%) | B22: =B21 -> 0.025 | C22: ← mesmo % que Y2 por padrão | M22: Premissas!$I$51 | O22: = | P22: 1 | R22: Soma P8 = 100% (Dez/29–Mai/30)
A23: Degradação geração Y2 (%) | B23: 0.005 | C23: ← 0.5%/ano editável | M23: Premissas!$J$51 | O23: = | P23: 1 | R23: Soma P9 = 100% (Jun–Nov/30)
A24: Usar proxy Batayporã p/ Amandina gen? | B24: Sim | M24: Premissas!$K$51 | O24: = | P24: 1 | R24: Soma P10 = 100% (Dez/30–Mai/31)
A25: D. BANCOS DE CRÉDITOS — SALDO INICIAL (NHS/AMD: demonstrativo Abr/2026 | BAT: demonstrativo Mar/2026 | Conservador: sem projeção Mai-Jun/2026) | M25: Premissas!$B$34:$K$34 | O25: = | P25: 0 | R25: BAT (linha 34) = 0% em todos os períodos (P1–P10)
A26: NHS — Silos Novo Horizonte do Sul (kWh) | B26: 786669 | M26: Premissas!$B$33:$E$50 | O26: <= | P26: 1 | R26: Todos os rateios ≤ 100% (limite superior)
A27: BAT — Silos Batayporã (kWh) [stranded — não transferível CS3] | B27: 791092
A28: AMD — Silos Amandina (kWh) | B28: 0
A29: TOTAL NHS+AMD (kWh) | B29: =B26+B28 -> 786669 | C29: ← BAT stranded bank não incluído no total | M29: ⑦ MÉTODO DE RESOLUÇÃO E OPÇÕES
M30: Método de Resolução: | O30: GRG Não-Linear | P30: O modelo tem funções IF (não-lineares). GRG é o método correto.
A31: ="E. RATEIO FIXO "&INDEX(PVSYST_Helexia!$A$5:$A$7,MATCH(Premissas!$B$13,PVSYST_Helexia!$B$5:$B$7,0))&" — 4 PERÍODOS (edit percentuais — devem somar 100% por período)" -> E. RATEIO FIXO HCS03 — 4 PERÍODOS (edit percentuais — devem somar 100% por período) | F31: Anos 3–5 (estado estacionário) | M31: Opções → Precisão: | O31: 0,000001 | P31: Maior precisão = resultado mais fino.
A32: UC / Planta | B32: P1: Jun–Set/26 | C32: P2: Out/26–Mar/27 | D32: P3: Abr/27–Set/27 | E32: P4: Out/27–Mai/28 | F32: P5: Jun–Nov/28 | G32: P6: Dez/28–Mai/29 | H32: P7: Jun–Nov/29 | I32: P8: Dez/29–Mai/30 | J32: P9: Jun–Nov/30 | K32: P10: Dez/30–Mai/31 | M32: Opções → Iterações: | O32: 1000 | P32: Permite mais buscas antes de parar.
A33: NHS — Silos N. Horizonte (A4V) | B33: 0.738 | C33: 0.5178 | D33: 0.6714 | E33: 0.2592 | F33: 0.4741 | G33: 0.4673 | H33: 0.4724 | I33: 0.4656 | J33: 0.5826 | K33: 0.4621 | M33: Opções → Convergência: | O33: 0,0001 | P33: Critério de parada quando melhoria < este valor.
A34: BAT — Silos Batayporã (A4V) | B34: 0 | C34: 0 | D34: 0 | E34: 0 | F34: 0 | G34: 0 | H34: 0 | I34: 0 | J34: 0 | K34: 0 | M34: ⚠ Otimização local: | O34: Execute 2–3 vezes | P34: GRG pode parar em mínimo local. Rode com rateios iniciais diferentes e fique com o melhor resultado.
A35: AMD — Silos Amandina (A3A) | B35: 0 | C35: 0 | D35: 0.0041 | E35: 0.1561 | F35: 0.3735 | G35: 0.3698 | H35: 0.3726 | I35: 0.3688 | J35: 0.2324 | K35: 0.2925
A36: AREC (B3) | B36: 0.027 | C36: 0.0532 | D36: 0.0311 | E36: 0.0674 | F36: 0.0156 | G36: 0.0171 | H36: 0.016 | I36: 0.0174 | J36: 0.0304 | K36: 0.0322 | M36: ⑧ EXECUTAR → clicar "Resolver" → aceitar "Manter Solução do Solver"
A37: Banheiro Motoristas (B3) | B37: 0.0033 | C37: 0.005 | D37: 0.004 | E37: 0.0045 | F37: 0.0026 | G37: 0.0027 | H37: 0.0026 | I37: 0.0027 | J37: 0.0027 | K37: 0.0034 | M37: Economia Liquida ANTES da otimização (R$): | P37: 670877.66 | Q37: ← valor antes de rodar o Solver (referência)
A38: CTC Copasul (B3) | B38: 0.0031 | C38: 0.0077 | D38: 0.0039 | E38: 0.0072 | F38: 0.0032 | G38: 0.0034 | H38: 0.0032 | I38: 0.0034 | J38: 0.0037 | K38: 0.0043 | M38: Vsalor Banco Residual ANTES da otimização (R$): | P38: =Resumo!H5 -> 460824.2 | Q38: ← valor antes de rodar o Solver (referência)
A39: Depósito Irrigação (B3) | B39: 0.0064 | C39: 0.0114 | D39: 0.0081 | E39: 0.0095 | F39: 0.007 | G39: 0.0075 | H39: 0.0071 | I39: 0.0076 | J39: 0.0098 | K39: 0.0044 | M39: Economia APÓS otimização (R$) — resultado: | P39: =Simulacao!B252 -> 2673060.5 | Q39: ← atualiza automaticamente após o Solver alterar B33:E50
A40: Entreposto (B3) | B40: 0.059 | C40: 0.1067 | D40: 0.0727 | E40: 0.2104 | F40: 0.006 | G40: 0.0064 | H40: 0.0061 | I40: 0.0065 | J40: 0.0075 | K40: 0.0313
A41: Esc. Deodápolis (B3) | B41: 0.0213 | C41: 0.0358 | D41: 0.026 | E41: 0.0439 | F41: 0.0111 | G41: 0.0121 | H41: 0.0113 | I41: 0.0123 | J41: 0.0181 | K41: 0.0212
...

Sheet Input_Consumo_GrupoA
A1: INPUT — CONSUMO ORÇADO GRUPO A | Fonte: Consumo_Orçado_2026_GD
A2: Azul = valores editáveis (fonte: arquivo fornecido) | Preto = fórmulas de projeção Y2/Y3
A3: Mês | B3: NHS FP (kWh) | C3: NHS Ponta (kWh) | D3: BAT FP (kWh) | E3: BAT Ponta (kWh) | F3: AMD FP (kWh) | G3: AMD Ponta (kWh)
A4: Jan | B4: 70769.9 | C4: 7863.3 | D4: 113967 | E4: 12663 | F4: 73973.4 | G4: 8219.3
A5: Fev | B5: 243719.7 | C5: 27080 | D5: 125874 | E5: 13986 | F5: 209472.2 | G5: 23274.7
A6: Mar | B6: 331874.1 | C6: 36874.9 | D6: 57499.2 | E6: 6388.8 | F6: 173260.2 | G6: 19251.1
A7: Abr | B7: 102778.3 | C7: 11419.8 | D7: 35640 | E7: 3960 | F7: 78448.4 | G7: 8716.5
A8: Mai | B8: 62814.2 | C8: 6979.4 | D8: 79603.2 | E8: 8844.8 | F8: 102629.5 | G8: 11403.3
A9: Jun | B9: 108694.9 | C9: 12077.2 | D9: 78336 | E9: 8704 | F9: 182444.7 | G9: 20271.6
A10: Jul | B10: 328938.1 | C10: 36548.7 | D10: 115718.4 | E10: 12857.6 | F10: 234799.2 | G10: 26088.8
A11: Ago | B11: 190977.6 | C11: 21219.7 | D11: 23364 | E11: 2596 | F11: 134799.3 | G11: 14977.7
A12: Set | B12: 126478.8 | C12: 14053.2 | D12: 10800 | E12: 1200 | F12: 18637.2 | G12: 2070.8
A13: Out | B13: 28215 | C13: 3135 | D13: 10800 | E13: 1200 | F13: 24382.8 | G13: 2709.2
A14: Nov | B14: 42209.6 | C14: 4690 | D14: 10800 | E14: 1200 | F14: 20225.7 | G14: 2247.3
A15: Dez | B15: 42209.6 | C15: 4690 | D15: 3402 | E15: 378 | F15: 17142.3 | G15: 1904.7
A17: Crescimento Y2 aplicado automaticamente via Premissas!$B$21 (atualmente 2,5%). Altere lá para que todos os 18 UCs sejam atualizados.

Sheet Simulacao
A1: ="SIMULAÇÃO RATEIO FIXO — "&Premissas!$B$13&" × COPASUL | 18 UCs | Jun/2026–Mai/2031" -> SIMULAÇÃO RATEIO FIXO — Cassilândia 03 × COPASUL | 18 UCs | Jun/2026–Mai/2031
A2: Energisa MS · Todas as células são fórmulas · Azul=input Premissas · Verde=link entre abas
A4: INDICADOR / UC | B4: TOTAL 60m ou SALDO FINAL | C4: MÉD/mês ou unidade | D4: Jun/26 | E4: Jul/26 | F4: Ago/26 | G4: Set/26 | H4: Out/26 | I4: Nov/26 | J4: Dez/26 | K4: Jan/27 | L4: Fev/27 | M4: Mar/27 | N4: Abr/27 | O4: Mai/27 | P4: Jun/27 | Q4: Jul/27 | R4: Ago/27 | S4: Set/27 | T4: Out/27 | U4: Nov/27 | V4: Dez/27 | W4: Jan/28 | X4: Fev/28 | Y4: Mar/28 | Z4: Abr/28 | AA4: Mai/28 | AB4: Jun/28 | AC4: Jul/28 | AD4: Ago/28 | AE4: Set/28 | AF4: Out/28 | AG4: Nov/28 | AH4: Dez/28 | AI4: Jan/29 | AJ4: Fev/29 | AK4: Mar/29 | AL4: Abr/29 | AM4: Mai/29 | AN4: Jun/29 | AO4: Jul/29 | AP4: Ago/29 | AQ4: Set/29 | AR4: Out/29 | AS4: Nov/29 | AT4: Dez/29 | AU4: Jan/30 | AV4: Fev/30 | AW4: Mar/30 | AX4: Abr/30 | AY4: Mai/30 | AZ4: Jun/30 | BA4: Jul/30 | BB4: Ago/30 | BC4: Set/30 | BD4: Out/30 | BE4: Nov/30 | BF4: Dez/30 | BG4: Jan/31 | BH4: Fev/31 | BI4: Mar/31 | BJ4: Abr/31 | BK4: Mai/31
A5: ="0. "&Premissas!B13&" — GERAÇÃO E CUSTO PPA" -> 0. Cassilândia 03 — GERAÇÃO E CUSTO PPA
A6: =INDEX(PVSYST_Helexia!$A$5:$A$7,MATCH(Premissas!$B$13,PVSYST_Helexia!$B$5:$B$7,0))&" Geração P50 (kWh)" -> HCS03 Geração P50 (kWh) | B6: =SUM(D6:BQ6) -> 8380442.4 | C6: =B6/60 -> 139674.04 | D6: =Premissas!$B$61 -> 123990 | E6: =Premissas!$B$62 -> 130510 | F6: =Premissas!$B$63 -> 156670 | G6: =Premissas!$B$64 -> 147010 | H6: =Premissas!$B$65 -> 151080 | I6: =Premissas!$B$66 -> 146080 | J6: =Premissas!$B$67 -> 138710 | K6: =Premissas!$B$68 -> 142424.3 | L6: =Premissas!$B$69 -> 126912.25 | M6: =Premissas!$B$70 -> 145568.5 | N6: =Premissas!$B$71 -> 145250.1 | O6: =Premissas!$B$72 -> 135936.9 | P6: =Premissas!$B$73 -> 123370.05 | Q6: =Premissas!$B$74 -> 129857.45 | R6: =Premissas!$B$75 -> 155886.65 | S6: =Premissas!$B$76 -> 146274.95 | T6: =Premissas!$B$77 -> 150324.6 | U6: =Premissas!$B$78 -> 145349.6 | V6: =Premissas!$B$79 -> 138016.45 | W6: =Premissas!$B$80 -> 142424.3 | X6: =Premissas!$B$81 -> 126912.25 | Y6: =Premissas!$B$82 -> 145568.5 | Z6: =Premissas!$B$83 -> 145250.1 | AA6: =Premissas!$B$84 -> 135936.9 | AB6: =Premissas!$B$85 -> 122753.2 | AC6: =Premissas!$B$86 -> 129208.16 | AD6: =Premissas!$B$87 -> 155107.22 | AE6: =Premissas!$B$88 -> 145543.58 | AF6: =Premissas!$B$89 -> 149572.98 | AG6: =Premissas!$B$90 -> 144622.85 | AH6: =Premissas!$B$91 -> 137326.37 | AI6: =Premissas!$B$92 -> 141712.18 | AJ6: =Premissas!$B$93 -> 126277.69 | AK6: =Premissas!$B$94 -> 144840.66 | AL6: =Premissas!$B$95 -> 144523.85 | AM6: =Premissas!$B$96 -> 135257.22 | AN6: =Premissas!$B$97 -> 122139.43 | AO6: =Premissas!$B$98 -> 128562.12 | AP6: =Premissas!$B$99 -> 154331.68 | AQ6: =Premissas!$B$100 -> 144815.86 | AR6: =Premissas!$B$101 -> 148825.11 | AS6: =Premissas!$B$102 -> 143899.74 | AT6: =Premissas!$B$103 -> 136639.74 | AU6: =Premissas!$B$104 -> 141003.62 | AV6: =Premissas!$B$105 -> 125646.3 | AW6: =Premissas!$B$106 -> 144116.45 | AX6: =Premissas!$B$107 -> 143801.23 | AY6: =Premissas!$B$108 -> 134580.93 | AZ6: =Premissas!$B$109 -> 121528.74 | BA6: =Premissas!$B$110 -> 127919.31 | BB6: =Premissas!$B$111 -> 153560.02 | BC6: =Premissas!$B$112 -> 144091.78 | BD6: =Premissas!$B$113 -> 148080.99 | BE6: =Premissas!$B$114 -> 143180.24 | BF6: =Premissas!$B$115 -> 135956.54 | BG6: =Premissas!$B$116 -> 140298.6 | BH6: =Premissas!$B$117 -> 125018.07 | BI6: =Premissas!$B$118 -> 143395.87 | BJ6: =Premissas!$B$119 -> 143082.22 | BK6: =Premissas!$B$120 -> 133908.02
A7: PPA Helexia — custo total (R$) | B7: =SUM(D7:BQ7) -> 4542510.4 | C7: =B7/60 -> 75708.506 | D7: =D6*Premissas!$B$17*(1+Premissas!$B$128)*(1+Premissas!$B$123)^0 -> 61449.444 | E7: =E6*Premissas!$B$17*(1+Premissas!$B$128)*(1+Premissas!$B$123)^0 -> 64680.756 | F7: =F6*Premissas!$B$17*(1+Premissas!$B$128)*(1+Premissas!$B$123)^0 -> 77645.652 | G7: =G6*Premissas!$B$17*(1+Premissas!$B$128)*(1+Premissas!$B$123)^0 -> 72858.156 | H7: =H6*Premissas!$B$17*(1+Premissas!$B$128)*(1+Premissas!$B$123)^0 -> 74875.248 | I7: =I6*Premissas!$B$17*(1+Premissas!$B$128)*(1+Premissas!$B$123)^0 -> 72397.248 | J7: =J6*Premissas!$B$17*(1+Premissas!$B$128)*(1+Premissas!$B$123)^0 -> 68744.676 | K7: =K6*Premissas!$B$17*(1+Premissas!$B$128)*(1+Premissas!$B$123)^0 -> 70585.483 | ... O7: =O6*Premissas!$B$17*(1+Premissas!$B$128)*(1+Premissas!$B$123)^0 -> 67370.328 | P7: =P6*Premissas!$B$17*(1+Premissas!$B$128)*(1+Premissas!$B$123)^1 -> 63893.596 | Q7: =Q6*Premissas!$B$17*(1+Premissas!$B$128)*(1+Premissas!$B$123)^1 -> 67253.433 | R7: =R6*Premissas!$B$17*(1+Premissas!$B$128)*(1+Premissas!$B$123)^1 -> 80734.008 | S7: =S6*Premissas!$B$17*(1+Premissas!$B$128)*(1+Premissas!$B$123)^1 -> 75756.089 | T7: =T6*Premissas!$B$17*(1+Premissas!$B$128)*(1+Premissas!$B$123)^1 -> 77853.411 | U7: =U6*Premissas!$B$17*(1+Premissas!$B$128)*(1+Premissas!$B$123)^1 -> 75276.849 | V7: =V6*Premissas!$B$17*(1+Premissas!$B$128)*(1+Premissas!$B$123)^1 -> 71478.995 | W7: =W6*Premissas!$B$17*(1+Premissas!$B$128)*(1+Premissas!$B$123)^1 -> 73761.83 | ... AA7: =AA6*Premissas!$B$17*(1+Premissas!$B$128)*(1+Premissas!$B$123)^1 -> 70401.992 | AB7: =AB6*Premissas!$B$17*(1+Premissas!$B$128)*(1+Premissas!$B$123)^2 -> 66434.963 | AC7: =AC6*Premissas!$B$17*(1+Premissas!$B$128)*(1+Premissas!$B$123)^2 -> 69928.438 | AD7: =AD6*Premissas!$B$17*(1+Premissas!$B$128)*(1+Premissas!$B$123)^2 -> 83945.203 | AE7: =AE6*Premissas!$B$17*(1+Premissas!$B$128)*(1+Premissas!$B$123)^2 -> 78769.288 | AF7: =AF6*Premissas!$B$17*(1+Premissas!$B$128)*(1+Premissas!$B$123)^2 -> 80950.03 | AG7: =AG6*Premissas!$B$17*(1+Premissas!$B$128)*(1+Premissas!$B$123)^2 -> 78270.985 | AH7: =AH6*Premissas!$B$17*(1+Premissas!$B$128)*(1+Premissas!$B$123)^2 -> 74322.073 | AI7: =AI6*Premissas!$B$17*(1+Premissas!$B$128)*(1+Premissas!$B$123)^2 -> 76695.707 | ... AM7: =AM6*Premissas!$B$17*(1+Premissas!$B$128)*(1+Premissas!$B$123)^2 -> 73202.232 | AN7: =AN6*Premissas!$B$17*(1+Premissas!$B$128)*(1+Premissas!$B$123)^3 -> 69077.414 | AO7: =AO6*Premissas!$B$17*(1+Premissas!$B$128)*(1+Premissas!$B$123)^3 -> 72709.842 | AP7: =AP6*Premissas!$B$17*(1+Premissas!$B$128)*(1+Premissas!$B$123)^3 -> 87284.123 | AQ7: =AQ6*Premissas!$B$17*(1+Premissas!$B$128)*(1+Premissas!$B$123)^3 -> 81902.336 | AR7: =AR6*Premissas!$B$17*(1+Premissas!$B$128)*(1+Premissas!$B$123)^3 -> 84169.818 | AS7: =AS6*Premissas!$B$17*(1+Premissas!$B$128)*(1+Premissas!$B$123)^3 -> 81384.214 | AT7: =AT6*Premissas!$B$17*(1+Premissas!$B$128)*(1+Premissas!$B$123)^3 -> 77278.233 | AU7: =AU6*Premissas!$B$17*(1+Premissas!$B$128)*(1+Premissas!$B$123)^3 -> 79746.278 | ... AY7: =AY6*Premissas!$B$17*(1+Premissas!$B$128)*(1+Premissas!$B$123)^3 -> 76113.85 | AZ7: =AZ6*Premissas!$B$17*(1+Premissas!$B$128)*(1+Premissas!$B$123)^4 -> 71824.968 | BA7: =BA6*Premissas!$B$17*(1+Premissas!$B$128)*(1+Premissas!$B$123)^4 -> 75601.876 | BB7: =BB6*Premissas!$B$17*(1+Premissas!$B$128)*(1+Premissas!$B$123)^4 -> 90755.849 | BC7: =BC6*Premissas!$B$17*(1+Premissas!$B$128)*(1+Premissas!$B$123)^4 -> 85160.001 | BD7: =BD6*Premissas!$B$17*(1+Premissas!$B$128)*(1+Premissas!$B$123)^4 -> 87517.672 | BE7: =BE6*Premissas!$B$17*(1+Premissas!$B$128)*(1+Premissas!$B$123)^4 -> 84621.271 | BF7: =BF6*Premissas!$B$17*(1+Premissas!$B$128)*(1+Premissas!$B$123)^4 -> 80351.975 | BG7: =BG6*Premissas!$B$17*(1+Premissas!$B$128)*(1+Premissas!$B$123)^4 -> 82918.187 | ... BK7: =BK6*Premissas!$B$17*(1+Premissas!$B$128)*(1+Premissas!$B$123)^4 -> 79141.279
A8: 1. BAT — BATAYPORÃ — GERAÇÃO, CONSUMO E SURPLUS
A9: BAT Geração própria (kWh) | B9: =SUM(D9:BQ9) -> 5593986.3 | C9: =B9/60 -> 93233.104 | D9: =+Batayporã!I8 -> 72286.9 | E9: =+Batayporã!I9 -> 88336.8 | F9: =+Batayporã!I10 -> 93082.7 | G9: =+Batayporã!I11 -> 94433.4 | H9: =+Batayporã!I12 -> 95906.8 | I9: =+Batayporã!I13 -> 107980.6 | J9: =+Batayporã!I14 -> 106603.9 | K9: =+Batayporã!I3*(1-Premissas!$B$23) -> 113687.7 | L9: =+Batayporã!I4*(1-Premissas!$B$23) -> 90676.241 | M9: =+Batayporã!I5*(1-Premissas!$B$23) -> 102546.59 | N9: =+Batayporã!I6*(1-Premissas!$B$23) -> 73341.151 | O9: =+Batayporã!I7*(1-Premissas!$B$23) -> 91158.517 | P9: =D9*(1-Premissas!$B$23) -> 71925.465 | Q9: =E9*(1-Premissas!$B$23) -> 87895.116 | R9: =F9*(1-Premissas!$B$23) -> 92617.287 | S9: =G9*(1-Premissas!$B$23) -> 93961.233 | T9: =H9*(1-Premissas!$B$23) -> 95427.266 | U9: =I9*(1-Premissas!$B$23) -> 107440.7 | V9: =J9*(1-Premissas!$B$23) -> 106070.88 | W9: =K9*(1-Premissas!$B$23) -> 113119.27 | ... BK9: =AY9*(1-Premissas!$B$23) -> 89348.975
A10: BAT Consumo FP (kWh) | B10: =SUM(D10:BQ10) -> 3509998.1 | C10: =B10/60 -> 58499.968 | D10: =Input_Consumo_GrupoA!$D$9 -> 78336 | E10: =Input_Consumo_GrupoA!$D$10 -> 115718.4 | F10: =Input_Consumo_GrupoA!$D$11 -> 23364 | G10: =Input_Consumo_GrupoA!$D$12 -> 10800 | H10: =Input_Consumo_GrupoA!$D$13 -> 10800 | I10: =Input_Consumo_GrupoA!$D$14 -> 10800 | J10: =Input_Consumo_GrupoA!$D$15 -> 3402 | K10: =Input_Consumo_GrupoA!$D$4*(1+Premissas!$B$21) -> 116816.17 | L10: =Input_Consumo_GrupoA!$D$5*(1+Premissas!$B$21) -> 129020.85 | M10: =Input_Consumo_GrupoA!$D$6*(1+Premissas!$B$21) -> 58936.68 | N10: =Input_Consumo_GrupoA!$D$7*(1+Premissas!$B$21) -> 36531 | O10: =Input_Consumo_GrupoA!$D$8*(1+Premissas!$B$21) -> 81593.28 | P10: =Input_Consumo_GrupoA!$D$9*(1+Premissas!$B$21) -> 80294.4 | Q10: =Input_Consumo_GrupoA!$D$10*(1+Premissas!$B$21) -> 118611.36 | R10: =Input_Consumo_GrupoA!$D$11*(1+Premissas!$B$21) -> 23948.1 | S10: =Input_Consumo_GrupoA!$D$12*(1+Premissas!$B$21) -> 11070 | T10: =Input_Consumo_GrupoA!$D$13*(1+Premissas!$B$21) -> 11070 | U10: =Input_Consumo_GrupoA!$D$14*(1+Premissas!$B$21) -> 11070 | V10: =Input_Consumo_GrupoA!$D$15*(1+Premissas!$B$21) -> 3487.05 | W10: =Input_Consumo_GrupoA!$D$4*(1+Premissas!$B$21) -> 116816.17 | X10: =Input_Consumo_GrupoA!$D$5*(1+Premissas!$B$21) -> 129020.85 | Y10: =Input_Consumo_GrupoA!$D$6*(1+Premissas!$B$21) -> 58936.68 | Z10: =Input_Consumo_GrupoA!$D$7*(1+Premissas!$B$21) -> 36531 | AA10: =Input_Consumo_GrupoA!$D$8*(1+Premissas!$B$21) -> 81593.28 | AB10: =Input_Consumo_GrupoA!$D$9*(1+Premissas!$B$21)^2 -> 82301.76 | AC10: =Input_Consumo_GrupoA!$D$10*(1+Premissas!$B$21)^2 -> 121576.64 | AD10: =Input_Consumo_GrupoA!$D$11*(1+Premissas!$B$21)^2 -> 24546.802 | AE10: =Input_Consumo_GrupoA!$D$12*(1+Premissas!$B$21)^2 -> 11346.75 | AF10: =Input_Consumo_GrupoA!$D$13*(1+Premissas!$B$21)^2 -> 11346.75 | AG10: =Input_Consumo_GrupoA!$D$14*(1+Premissas!$B$21)^2 -> 11346.75 | AH10: =Input_Consumo_GrupoA!$D$15*(1+Premissas!$B$21)^2 -> 3574.2262 | AI10: =Input_Consumo_GrupoA!$D$4*(1+Premissas!$B$21)^2 -> 119736.58 | AJ10: =Input_Consumo_GrupoA!$D$5*(1+Premissas!$B$21)^2 -> 132246.37 | AK10: =Input_Consumo_GrupoA!$D$6*(1+Premissas!$B$21)^2 -> 60410.097 | AL10: =Input_Consumo_GrupoA!$D$7*(1+Premissas!$B$21)^2 -> 37444.275 | AM10: =Input_Consumo_GrupoA!$D$8*(1+Premissas!$B$21)^2 -> 83633.112 | AN10: =Input_Consumo_GrupoA!$D$9*(1+Premissas!$B$21)^3 -> 84359.304 | AO10: =Input_Consumo_GrupoA!$D$10*(1+Premissas!$B$21)^3 -> 124616.06 | AP10: =Input_Consumo_GrupoA!$D$11*(1+Premissas!$B$21)^3 -> 25160.473 | AQ10: =Input_Consumo_GrupoA!$D$12*(1+Premissas!$B$21)^3 -> 11630.419 | AR10: =Input_Consumo_GrupoA!$D$13*(1+Premissas!$B$21)^3 -> 11630.419 | AS10: =Input_Consumo_GrupoA!$D$14*(1+Premissas!$B$21)^3 -> 11630.419 | AT10: =Input_Consumo_GrupoA!$D$15*(1+Premissas!$B$21)^3 -> 3663.5819 | AU10: =Input_Consumo_GrupoA!$D$4*(1+Premissas!$B$21)^3 -> 122729.99 | AV10: =Input_Consumo_GrupoA!$D$5*(1+Premissas!$B$21)^3 -> 135552.53 | AW10: =Input_Consumo_GrupoA!$D$6*(1+Premissas!$B$21)^3 -> 61920.349 | AX10: =Input_Consumo_GrupoA!$D$7*(1+Premissas!$B$21)^3 -> 38380.382 | AY10: =Input_Consumo_GrupoA!$D$8*(1+Premissas!$B$21)^3 -> 85723.94 | AZ10: =Input_Consumo_GrupoA!$D$9*(1+Premissas!$B$21)^4 -> 86468.287 | BA10: =Input_Consumo_GrupoA!$D$10*(1+Premissas!$B$21)^4 -> 127731.46 | BB10: =Input_Consumo_GrupoA!$D$11*(1+Premissas!$B$21)^4 -> 25789.484 | BC10: =Input_Consumo_GrupoA!$D$12*(1+Premissas!$B$21)^4 -> 11921.179 | BD10: =Input_Consumo_GrupoA!$D$13*(1+Premissas!$B$21)^4 -> 11921.179 | BE10: =Input_Consumo_GrupoA!$D$14*(1+Premissas!$B$21)^4 -> 11921.179 | BF10: =Input_Consumo_GrupoA!$D$15*(1+Premissas!$B$21)^4 -> 3755.1715 | BG10: =Input_Consumo_GrupoA!$D$4*(1+Premissas!$B$21)^4 -> 125798.24 | BH10: =Input_Consumo_GrupoA!$D$5*(1+Premissas!$B$21)^4 -> 138941.34 | BI10: =Input_Consumo_GrupoA!$D$6*(1+Premissas!$B$21)^4 -> 63468.358 | BJ10: =Input_Consumo_GrupoA!$D$7*(1+Premissas!$B$21)^4 -> 39339.891 | BK10: =Input_Consumo_GrupoA!$D$8*(1+Premissas!$B$21)^4 -> 87867.038
A11: BAT Consumo Ponta (kWh) | B11: =SUM(D11:BQ11) -> 389999.79 | C11: =B11/60 -> 6499.9965 | D11: =Input_Consumo_GrupoA!$E$9 -> 8704 | E11: =Input_Consumo_GrupoA!$E$10 -> 12857.6 | F11: =Input_Consumo_GrupoA!$E$11 -> 2596 | G11: =Input_Consumo_GrupoA!$E$12 -> 1200 | H11: =Input_Consumo_GrupoA!$E$13 -> 1200 | I11: =Input_Consumo_GrupoA!$E$14 -> 1200 | J11: =Input_Consumo_GrupoA!$E$15 -> 378 | K11: =Input_Consumo_GrupoA!$E$4*(1+Premissas!$B$21) -> 12979.575 | L11: =Input_Consumo_GrupoA!$E$5*(1+Premissas!$B$21) -> 14335.65 | M11: =Input_Consumo_GrupoA!$E$6*(1+Premissas!$B$21) -> 6548.52 | N11: =Input_Consumo_GrupoA!$E$7*(1+Premissas!$B$21) -> 4059 | O11: =Input_Consumo_GrupoA!$E$8*(1+Premissas!$B$21) -> 9065.92 | P11: =Input_Consumo_GrupoA!$E$9*(1+Premissas!$B$21) -> 8921.6 | Q11: =Input_Consumo_GrupoA!$E$10*(1+Premissas!$B$21) -> 13179.04 | R11: =Input_Consumo_GrupoA!$E$11*(1+Premissas!$B$21) -> 2660.9 | S11: =Input_Consumo_GrupoA!$E$12*(1+Premissas!$B$21) -> 1230 | T11: =Input_Consumo_GrupoA!$E$13*(1+Premissas!$B$21) -> 1230 | U11: =Input_Consumo_GrupoA!$E$14*(1+Premissas!$B$21) -> 1230 | V11: =Input_Consumo_GrupoA!$E$15*(1+Premissas!$B$21) -> 387.45 | W11: =Input_Consumo_GrupoA!$E$4*(1+Premissas!$B$21) -> 12979.575 | X11: =Input_Consumo_GrupoA!$E$5*(1+Premissas!$B$21) -> 14335.65 | Y11: =Input_Consumo_GrupoA!$E$6*(1+Premissas!$B$21) -> 6548.52 | Z11: =Input_Consumo_GrupoA!$E$7*(1+Premissas!$B$21) -> 4059 | AA11: =Input_Consumo_GrupoA!$E$8*(1+Premissas!$B$21) -> 9065.92 | AB11: =Input_Consumo_GrupoA!$E$9*(1+Premissas!$B$21)^2 -> 9144.64 | AC11: =Input_Consumo_GrupoA!$E$10*(1+Premissas!$B$21)^2 -> 13508.516 | AD11: =Input_Consumo_GrupoA!$E$11*(1+Premissas!$B$21)^2 -> 2727.4225 | AE11: =Input_Consumo_GrupoA!$E$12*(1+Premissas!$B$21)^2 -> 1260.75 | AF11: =Input_Consumo_GrupoA!$E$13*(1+Premissas!$B$21)^2 -> 1260.75 | AG11: =Input_Consumo_GrupoA!$E$14*(1+Premissas!$B$21)^2 -> 1260.75 | AH11: =Input_Consumo_GrupoA!$E$15*(1+Premissas!$B$21)^2 -> 397.13625 | AI11: =Input_Consumo_GrupoA!$E$4*(1+Premissas!$B$21)^2 -> 13304.064 | AJ11: =Input_Consumo_GrupoA!$E$5*(1+Premissas!$B$21)^2 -> 14694.041 | AK11: =Input_Consumo_GrupoA!$E$6*(1+Premissas!$B$21)^2 -> 6712.233 | AL11: =Input_Consumo_GrupoA!$E$7*(1+Premissas!$B$21)^2 -> 4160.475 | AM11: =Input_Consumo_GrupoA!$E$8*(1+Premissas!$B$21)^2 -> 9292.568 | AN11: =Input_Consumo_GrupoA!$E$9*(1+Premissas!$B$21)^3 -> 9373.256 | AO11: =Input_Consumo_GrupoA!$E$10*(1+Premissas!$B$21)^3 -> 13846.229 | AP11: =Input_Consumo_GrupoA!$E$11*(1+Premissas!$B$21)^3 -> 2795.6081 | AQ11: =Input_Consumo_GrupoA!$E$12*(1+Premissas!$B$21)^3 -> 1292.2687 | AR11: =Input_Consumo_GrupoA!$E$13*(1+Premissas!$B$21)^3 -> 1292.2687 | AS11: =Input_Consumo_GrupoA!$E$14*(1+Premissas!$B$21)^3 -> 1292.2687 | AT11: =Input_Consumo_GrupoA!$E$15*(1+Premissas!$B$21)^3 -> 407.06466 | AU11: =Input_Consumo_GrupoA!$E$4*(1+Premissas!$B$21)^3 -> 13636.666 | AV11: =Input_Consumo_GrupoA!$E$5*(1+Premissas!$B$21)^3 -> 15061.392 | AW11: =Input_Consumo_GrupoA!$E$6*(1+Premissas!$B$21)^3 -> 6880.0388 | AX11: =Input_Consumo_GrupoA!$E$7*(1+Premissas!$B$21)^3 -> 4264.4869 | AY11: =Input_Consumo_GrupoA!$E$8*(1+Premissas!$B$21)^3 -> 9524.8822 | AZ11: =Input_Consumo_GrupoA!$E$9*(1+Premissas!$B$21)^4 -> 9607.5874 | BA11: =Input_Consumo_GrupoA!$E$10*(1+Premissas!$B$21)^4 -> 14192.385 | BB11: =Input_Consumo_GrupoA!$E$11*(1+Premissas!$B$21)^4 -> 2865.4983 | BC11: =Input_Consumo_GrupoA!$E$12*(1+Premissas!$B$21)^4 -> 1324.5755 | BD11: =Input_Consumo_GrupoA!$E$13*(1+Premissas!$B$21)^4 -> 1324.5755 | BE11: =Input_Consumo_GrupoA!$E$14*(1+Premissas!$B$21)^4 -> 1324.5755 | BF11: =Input_Consumo_GrupoA!$E$15*(1+Premissas!$B$21)^4 -> 417.24127 | BG11: =Input_Consumo_GrupoA!$E$4*(1+Premissas!$B$21)^4 -> 13977.583 | BH11: =Input_Consumo_GrupoA!$E$5*(1+Premissas!$B$21)^4 -> 15437.927 | BI11: =Input_Consumo_GrupoA!$E$6*(1+Premissas!$B$21)^4 -> 7052.0398 | BJ11: =Input_Consumo_GrupoA!$E$7*(1+Premissas!$B$21)^4 -> 4371.099 | BK11: =Input_Consumo_GrupoA!$E$8*(1+Premissas!$B$21)^4 -> 9763.0043
A12: BAT auto-comp. FP (kWh) | B12: =SUM(D12:BQ12) -> 3030085.2 | C12: =B12/60 -> 50501.419 | D12: =MIN(D9,D10) -> 72286.9 | E12: =MIN(E9,E10) -> 88336.8 | F12: =MIN(F9,F10) -> 23364 | G12: =MIN(G9,G10) -> 10800 | H12: =MIN(H9,H10) -> 10800 | I12: =MIN(I9,I10) -> 10800 | J12: =MIN(J9,J10) -> 3402 | K12: =MIN(K9,K10) -> 113687.7 | ... BK12: =MIN(BK9,BK10) -> 87867.038
A13: BAT auto-comp. Ponta via FA (kWh) | B13: =SUM(D13:BQ13) -> 107850.19 | C13: =B13/60 -> 1797.5031 | D13: =MIN((D9-D12)*Premissas!$B$8,D11) -> 0 | E13: =MIN((E9-E12)*Premissas!$B$8,E11) -> 0 | F13: =MIN((F9-F12)*Premissas!$B$8,F11) -> 2596 | G13: =MIN((G9-G12)*Premissas!$B$8,G11) -> 1200 | H13: =MIN((H9-H12)*Premissas!$B$8,H11) -> 1200 | I13: =MIN((I9-I12)*Premissas!$B$8,I11) -> 1200 | J13: =MIN((J9-J12)*Premissas!$B$8,J11) -> 378 | K13: =MIN((K9-K12)*Premissas!$B$8,K11) -> 0 | ... BK13: =MIN((BK9-BK12)*Premissas!$B$8,BK11) -> 895.48547
A14: ★ BAT surplus líquido → rateio (kWh) | B14: =SUM(D14:BQ14) -> 2385420.1 | C14: =B14/60 -> 39757.002 | D14: =MAX(D9-D12-D11/Premissas!$B$8,0) -> 0 | E14: =MAX(E9-E12-E11/Premissas!$B$8,0) -> 0 | F14: =MAX(F9-F12-F11/Premissas!$B$8,0) -> 65422.586 | G14: =MAX(G9-G12-G11/Premissas!$B$8,0) -> 81647.523 | H14: =MAX(H9-H12-H11/Premissas!$B$8,0) -> 83120.923 | I14: =MAX(I9-I12-I11/Premissas!$B$8,0) -> 95194.723 | J14: =MAX(J9-J12-J11/Premissas!$B$8,0) -> 102576.35 | K14: =MAX(K9-K12-K11/Premissas!$B$8,0) -> 0 | ... BK14: =MAX(BK9-BK12-BK11/Premissas!$B$8,0) -> 0
A15: BAT banco stranded — depleção por consumo próprio apenas
A16: BAT banco início mês (kWh) | B16: =AA16 -> 466505.89 | C16: — | D16: =Premissas!$B$27 -> 791092 | E16: =D18 -> 770638.67 | F16: =E18 -> 721979.06 | G16: =F18 -> 721979.06 | H16: =G18 -> 721979.06 | I16: =H18 -> 721979.06 | J16: =I18 -> 721979.06 | K16: =J18 -> 721979.06 | L16: =K18 -> 697370.73 | ... BK16: =BJ18 -> 0
A17: BAT banco draw (kWh) | B17: =SUM(D17:BQ17) -> 791092 | C17: =B17/60 -> 13184.867 | D17: =MIN(D16,MAX(D10-D12,0)+IF(Premissas!$B$8=0,0,MAX(D11-D13,0)/Premissas!$B$8)) -> 20453.327 | E17: =MIN(E16,MAX(E10-E12,0)+IF(Premissas!$B$8=0,0,MAX(E11-E13,0)/Premissas!$B$8)) -> 48659.609 | F17: =MIN(F16,MAX(F10-F12,0)+IF(Premissas!$B$8=0,0,MAX(F11-F13,0)/Premissas!$B$8)) -> 0 | G17: =MIN(G16,MAX(G10-G12,0)+IF(Premissas!$B$8=0,0,MAX(G11-G13,0)/Premissas!$B$8)) -> 0 | H17: =MIN(H16,MAX(H10-H12,0)+IF(Premissas!$B$8=0,0,MAX(H11-H13,0)/Premissas!$B$8)) -> 0 | I17: =MIN(I16,MAX(I10-I12,0)+IF(Premissas!$B$8=0,0,MAX(I11-I13,0)/Premissas!$B$8)) -> 0 | J17: =MIN(J16,MAX(J10-J12,0)+IF(Premissas!$B$8=0,0,MAX(J11-J13,0)/Premissas!$B$8)) -> 0 | K17: =MIN(K16,MAX(K10-K12,0)+IF(Premissas!$B$8=0,0,MAX(K11-K13,0)/Premissas!$B$8)) -> 24608.336 | ... BK17: =MIN(BK16,MAX(BK10-BK12,0)+IF(Premissas!$B$8=0,0,MAX(BK11-BK13,0)/Premissas!$B$8)) -> 0
A18: BAT banco fim mês (kWh) | B18: =AA18 -> 460612.17 | C18: — | D18: =MAX(D16-D17,0) -> 770638.67 | E18: =MAX(E16-E17,0) -> 721979.06 | F18: =MAX(F16-F17,0) -> 721979.06 | G18: =MAX(G16-G17,0) -> 721979.06 | H18: =MAX(H16-H17,0) -> 721979.06 | I18: =MAX(I16-I17,0) -> 721979.06 | J18: =MAX(J16-J17,0) -> 721979.06 | K18: =MAX(K16-K17,0) -> 697370.73 | ... BK18: =MAX(BK16-BK17,0) -> 0
A19: BAT créditos → NHS (kWh, T+1) | B19: =SUM(D19:BQ19) -> 1192710.1 | C19: =B19/60 -> 19878.501 | D19: =0 -> 0 | E19: =D14*Premissas!$B$55 -> 0 | F19: =E14*Premissas!$B$55 -> 0 | G19: =F14*Premissas!$B$55 -> 32711.293 | H19: =G14*Premissas!$B$55 -> 40823.762 | I19: =H14*Premissas!$B$55 -> 41560.462 | J19: =I14*Premissas!$B$55 -> 47597.362 | K19: =J14*Premissas!$B$55 -> 51288.174 | L19: =K14*Premissas!$B$55 -> 0 | ... BK19: =BJ14*Premissas!$B$55 -> 12655.84
A20: BAT créditos → AMD (kWh, T+1) | B20: =SUM(D20:BQ20) -> 1192710.1 | C20: =B20/60 -> 19878.501 | D20: =0 -> 0 | E20: =D14*Premissas!$B$56 -> 0 | F20: =E14*Premissas!$B$56 -> 0 | G20: =F14*Premissas!$B$56 -> 32711.293 | H20: =G14*Premissas!$B$56 -> 40823.762 | I20: =H14*Premissas!$B$56 -> 41560.462 | J20: =I14*Premissas!$B$56 -> 47597.362 | K20: =J14*Premissas!$B$56 -> 51288.174 | L20: =K14*Premissas!$B$56 -> 0 | ... BK20: =BJ14*Premissas!$B$56 -> 12655.84
A21: NHS — N. Horizonte do Sul (A4V)
A22: Consumo FP (kWh) | B22: =SUM(D22:BQ22) -> 8849247.7 | C22: =B22/60 -> 147487.46 | D22: =Input_Consumo_GrupoA!$B$9 -> 108694.9 | E22: =Input_Consumo_GrupoA!$B$10 -> 328938.1 | F22: =Input_Consumo_GrupoA!$B$11 -> 190977.6 | G22: =Input_Consumo_GrupoA!$B$12 -> 126478.8 | H22: =Input_Consumo_GrupoA!$B$13 -> 28215 | I22: =Input_Consumo_GrupoA!$B$14 -> 42209.6 | J22: =Input_Consumo_GrupoA!$B$15 -> 42209.6 | K22: =Input_Consumo_GrupoA!$B$4*(1+Premissas!$B$21) -> 72539.147 | L22: =Input_Consumo_GrupoA!$B$5*(1+Premissas!$B$21) -> 249812.69 | M22: =Input_Consumo_GrupoA!$B$6*(1+Premissas!$B$21) -> 340170.95 | N22: =Input_Consumo_GrupoA!$B$7*(1+Premissas!$B$21) -> 105347.76 | O22: =Input_Consumo_GrupoA!$B$8*(1+Premissas!$B$21) -> 64384.555 | P22: =Input_Consumo_GrupoA!$B$9*(1+Premissas!$B$21) -> 111412.27 | Q22: =Input_Consumo_GrupoA!$B$10*(1+Premissas!$B$21) -> 337161.55 | R22: =Input_Consumo_GrupoA!$B$11*(1+Premissas!$B$21) -> 195752.04 | S22: =Input_Consumo_GrupoA!$B$12*(1+Premissas!$B$21) -> 129640.77 | T22: =Input_Consumo_GrupoA!$B$13*(1+Premissas!$B$21) -> 28920.375 | U22: =Input_Consumo_GrupoA!$B$14*(1+Premissas!$B$21) -> 43264.84 | V22: =Input_Consumo_GrupoA!$B$15*(1+Premissas!$B$21) -> 43264.84 | W22: =Input_Consumo_GrupoA!$B$4*(1+Premissas!$B$21) -> 72539.147 | X22: =Input_Consumo_GrupoA!$B$5*(1+Premissas!$B$21) -> 249812.69 | Y22: =Input_Consumo_GrupoA!$B$6*(1+Premissas!$B$21) -> 340170.95 | Z22: =Input_Consumo_GrupoA!$B$7*(1+Premissas!$B$21) -> 105347.76 | AA22: =Input_Consumo_GrupoA!$B$8*(1+Premissas!$B$21) -> 64384.555 | AB22: =Input_Consumo_GrupoA!$B$9*(1+Premissas!$B$21)^2 -> 114197.58 | AC22: =Input_Consumo_GrupoA!$B$10*(1+Premissas!$B$21)^2 -> 345590.59 | AD22: =Input_Consumo_GrupoA!$B$11*(1+Premissas!$B$21)^2 -> 200645.84 | AE22: =Input_Consumo_GrupoA!$B$12*(1+Premissas!$B$21)^2 -> 132881.79 | AF22: =Input_Consumo_GrupoA!$B$13*(1+Premissas!$B$21)^2 -> 29643.384 | AG22: =Input_Consumo_GrupoA!$B$14*(1+Premissas!$B$21)^2 -> 44346.461 | AH22: =Input_Consumo_GrupoA!$B$15*(1+Premissas!$B$21)^2 -> 44346.461 | AI22: =Input_Consumo_GrupoA!$B$4*(1+Premissas!$B$21)^2 -> 74352.626 | AJ22: =Input_Consumo_GrupoA!$B$5*(1+Premissas!$B$21)^2 -> 256058.01 | AK22: =Input_Consumo_GrupoA!$B$6*(1+Premissas!$B$21)^2 -> 348675.23 | AL22: =Input_Consumo_GrupoA!$B$7*(1+Premissas!$B$21)^2 -> 107981.45 | AM22: =Input_Consumo_GrupoA!$B$8*(1+Premissas!$B$21)^2 -> 65994.169 | AN22: =Input_Consumo_GrupoA!$B$9*(1+Premissas!$B$21)^3 -> 117052.52 | AO22: =Input_Consumo_GrupoA!$B$10*(1+Premissas!$B$21)^3 -> 354230.36 | AP22: =Input_Consumo_GrupoA!$B$11*(1+Premissas!$B$21)^3 -> 205661.99 | AQ22: =Input_Consumo_GrupoA!$B$12*(1+Premissas!$B$21)^3 -> 136203.83 | AR22: =Input_Consumo_GrupoA!$B$13*(1+Premissas!$B$21)^3 -> 30384.469 | AS22: =Input_Consumo_GrupoA!$B$14*(1+Premissas!$B$21)^3 -> 45455.123 | AT22: =Input_Consumo_GrupoA!$B$15*(1+Premissas!$B$21)^3 -> 45455.123 | AU22: =Input_Consumo_GrupoA!$B$4*(1+Premissas!$B$21)^3 -> 76211.442 | AV22: =Input_Consumo_GrupoA!$B$5*(1+Premissas!$B$21)^3 -> 262459.46 | AW22: =Input_Consumo_GrupoA!$B$6*(1+Premissas!$B$21)^3 -> 357392.11 | AX22: =Input_Consumo_GrupoA!$B$7*(1+Premissas!$B$21)^3 -> 110680.99 | AY22: =Input_Consumo_GrupoA!$B$8*(1+Premissas!$B$21)^3 -> 67644.023 | AZ22: =Input_Consumo_GrupoA!$B$9*(1+Premissas!$B$21)^4 -> 119978.83 | BA22: =Input_Consumo_GrupoA!$B$10*(1+Premissas!$B$21)^4 -> 363086.11 | BB22: =Input_Consumo_GrupoA!$B$11*(1+Premissas!$B$21)^4 -> 210803.54 | BC22: =Input_Consumo_GrupoA!$B$12*(1+Premissas!$B$21)^4 -> 139608.93 | BD22: =Input_Consumo_GrupoA!$B$13*(1+Premissas!$B$21)^4 -> 31144.081 | BE22: =Input_Consumo_GrupoA!$B$14*(1+Premissas!$B$21)^4 -> 46591.501 | BF22: =Input_Consumo_GrupoA!$B$15*(1+Premissas!$B$21)^4 -> 46591.501 | BG22: =Input_Consumo_GrupoA!$B$4*(1+Premissas!$B$21)^4 -> 78116.728 | BH22: =Input_Consumo_GrupoA!$B$5*(1+Premissas!$B$21)^4 -> 269020.95 | BI22: =Input_Consumo_GrupoA!$B$6*(1+Premissas!$B$21)^4 -> 366326.91 | BJ22: =Input_Consumo_GrupoA!$B$7*(1+Premissas!$B$21)^4 -> 113448.01 | BK22: =Input_Consumo_GrupoA!$B$8*(1+Premissas!$B$21)^4 -> 69335.124
A23: Consumo Ponta (kWh) [via FA] | B23: =SUM(D23:BQ23) -> 983250.33 | C23: =B23/60 -> 16387.506 | D23: =Input_Consumo_GrupoA!$C$9 -> 12077.2 | E23: =Input_Consumo_GrupoA!$C$10 -> 36548.7 | F23: =Input_Consumo_GrupoA!$C$11 -> 21219.7 | G23: =Input_Consumo_GrupoA!$C$12 -> 14053.2 | H23: =Input_Consumo_GrupoA!$C$13 -> 3135 | I23: =Input_Consumo_GrupoA!$C$14 -> 4690 | J23: =Input_Consumo_GrupoA!$C$15 -> 4690 | K23: =Input_Consumo_GrupoA!$C$4*(1+Premissas!$B$21) -> 8059.8825 | L23: =Input_Consumo_GrupoA!$C$5*(1+Premissas!$B$21) -> 27757 | M23: =Input_Consumo_GrupoA!$C$6*(1+Premissas!$B$21) -> 37796.772 | N23: =Input_Consumo_GrupoA!$C$7*(1+Premissas!$B$21) -> 11705.295 | O23: =Input_Consumo_GrupoA!$C$8*(1+Premissas!$B$21) -> 7153.885 | P23: =Input_Consumo_GrupoA!$C$9*(1+Premissas!$B$21) -> 12379.13 | Q23: =Input_Consumo_GrupoA!$C$10*(1+Premissas!$B$21) -> 37462.417 | R23: =Input_Consumo_GrupoA!$C$11*(1+Premissas!$B$21) -> 21750.192 | S23: =Input_Consumo_GrupoA!$C$12*(1+Premissas!$B$21) -> 14404.53 | T23: =Input_Consumo_GrupoA!$C$13*(1+Premissas!$B$21) -> 3213.375 | U23: =Input_Consumo_GrupoA!$C$14*(1+Premissas!$B$21) -> 4807.25 | V23: =Input_Consumo_GrupoA!$C$15*(1+Premissas!$B$21) -> 4807.25 | W23: =Input_Consumo_GrupoA!$C$4*(1+Premissas!$B$21) -> 8059.8825 | X23: =Input_Consumo_GrupoA!$C$5*(1+Premissas!$B$21) -> 27757 | Y23: =Input_Consumo_GrupoA!$C$6*(1+Premissas!$B$21) -> 37796.772 | Z23: =Input_Consumo_GrupoA!$C$7*(1+Premissas!$B$21) -> 11705.295 | AA23: =Input_Consumo_GrupoA!$C$8*(1+Premissas!$B$21) -> 7153.885 | AB23: =Input_Consumo_GrupoA!$C$9*(1+Premissas!$B$21)^2 -> 12688.608 | AC23: =Input_Consumo_GrupoA!$C$10*(1+Premissas!$B$21)^2 -> 38398.978 | AD23: =Input_Consumo_GrupoA!$C$11*(1+Premissas!$B$21)^2 -> 22293.947 | AE23: =Input_Consumo_GrupoA!$C$12*(1+Premissas!$B$21)^2 -> 14764.643 | AF23: =Input_Consumo_GrupoA!$C$13*(1+Premissas!$B$21)^2 -> 3293.7094 | AG23: =Input_Consumo_GrupoA!$C$14*(1+Premissas!$B$21)^2 -> 4927.4312 | AH23: =Input_Consumo_GrupoA!$C$15*(1+Premissas!$B$21)^2 -> 4927.4312 | AI23: =Input_Consumo_GrupoA!$C$4*(1+Premissas!$B$21)^2 -> 8261.3796 | AJ23: =Input_Consumo_GrupoA!$C$5*(1+Premissas!$B$21)^2 -> 28450.925 | AK23: =Input_Consumo_GrupoA!$C$6*(1+Premissas!$B$21)^2 -> 38741.692 | AL23: =Input_Consumo_GrupoA!$C$7*(1+Premissas!$B$21)^2 -> 11997.927 | AM23: =Input_Consumo_GrupoA!$C$8*(1+Premissas!$B$21)^2 -> 7332.7321 | AN23: =Input_Consumo_GrupoA!$C$9*(1+Premissas!$B$21)^3 -> 13005.823 | AO23: =Input_Consumo_GrupoA!$C$10*(1+Premissas!$B$21)^3 -> 39358.952 | AP23: =Input_Consumo_GrupoA!$C$11*(1+Premissas!$B$21)^3 -> 22851.296 | AQ23: =Input_Consumo_GrupoA!$C$12*(1+Premissas!$B$21)^3 -> 15133.759 | AR23: =Input_Consumo_GrupoA!$C$13*(1+Premissas!$B$21)^3 -> 3376.0521 | AS23: =Input_Consumo_GrupoA!$C$14*(1+Premissas!$B$21)^3 -> 5050.617 | AT23: =Input_Consumo_GrupoA!$C$15*(1+Premissas!$B$21)^3 -> 5050.617 | AU23: =Input_Consumo_GrupoA!$C$4*(1+Premissas!$B$21)^3 -> 8467.9141 | AV23: =Input_Consumo_GrupoA!$C$5*(1+Premissas!$B$21)^3 -> 29162.198 | AW23: =Input_Consumo_GrupoA!$C$6*(1+Premissas!$B$21)^3 -> 39710.234 | AX23: =Input_Consumo_GrupoA!$C$7*(1+Premissas!$B$21)^3 -> 12297.876 | AY23: =Input_Consumo_GrupoA!$C$8*(1+Premissas!$B$21)^3 -> 7516.0504 | AZ23: =Input_Consumo_GrupoA!$C$9*(1+Premissas!$B$21)^4 -> 13330.969 | BA23: =Input_Consumo_GrupoA!$C$10*(1+Premissas!$B$21)^4 -> 40342.926 | BB23: =Input_Consumo_GrupoA!$C$11*(1+Premissas!$B$21)^4 -> 23422.578 | BC23: =Input_Consumo_GrupoA!$C$12*(1+Premissas!$B$21)^4 -> 15512.103 | BD23: =Input_Consumo_GrupoA!$C$13*(1+Premissas!$B$21)^4 -> 3460.4534 | BE23: =Input_Consumo_GrupoA!$C$14*(1+Premissas!$B$21)^4 -> 5176.8825 | BF23: =Input_Consumo_GrupoA!$C$15*(1+Premissas!$B$21)^4 -> 5176.8825 | BG23: =Input_Consumo_GrupoA!$C$4*(1+Premissas!$B$21)^4 -> 8679.6119 | BH23: =Input_Consumo_GrupoA!$C$5*(1+Premissas!$B$21)^4 -> 29891.253 | BI23: =Input_Consumo_GrupoA!$C$6*(1+Premissas!$B$21)^4 -> 40702.99 | BJ23: =Input_Consumo_GrupoA!$C$7*(1+Premissas!$B$21)^4 -> 12605.322 | BK23: =Input_Consumo_GrupoA!$C$8*(1+Premissas!$B$21)^4 -> 7703.9517
A24: Geração própria (kWh) | B24: =SUM(D24:BQ24) -> 4634513.1 | C24: =B24/60 -> 77241.885 | D24: =+'Novo Horizonte do Sul'!I8 -> 60380.6 | E24: =+'Novo Horizonte do Sul'!I9 -> 76551.2 | F24: =+'Novo Horizonte do Sul'!I10 -> 79815.6 | G24: =+'Novo Horizonte do Sul'!I11 -> 78203 | H24: =+'Novo Horizonte do Sul'!I12 -> 73160.1 | I24: =+'Novo Horizonte do Sul'!I13 -> 91030.5 | J24: =+'Novo Horizonte do Sul'!I14 -> 88631.7 | K24: =+'Novo Horizonte do Sul'!I3*(1-Premissas!$B$23) -> 83044.59 | L24: =+'Novo Horizonte do Sul'!I4*(1-Premissas!$B$23) -> 75743.778 | M24: =+'Novo Horizonte do Sul'!I5*(1-Premissas!$B$23) -> 89408.909 | N24: =+'Novo Horizonte do Sul'!I6*(1-Premissas!$B$23) -> 62411.773 | O24: =+'Novo Horizonte do Sul'!I7*(1-Premissas!$B$23) -> 77836.363 | P24: =D24*(1-Premissas!$B$23) -> 60078.697 | Q24: =E24*(1-Premissas!$B$23) -> 76168.444 | R24: =F24*(1-Premissas!$B$23) -> 79416.522 | S24: =G24*(1-Premissas!$B$23) -> 77811.985 | T24: =H24*(1-Premissas!$B$23) -> 72794.299 | U24: =I24*(1-Premissas!$B$23) -> 90575.348 | V24: =J24*(1-Premissas!$B$23) -> 88188.541 | W24: =K24*(1-Premissas!$B$23) -> 82629.368 | ... BK24: =AY24*(1-Premissas!$B$23) -> 76291.272
A25: Auto-comp. FP (kWh) | B25: =SUM(D25:BQ25) -> 3884122.7 | C25: =B25/60 -> 64735.379 | D25: =MIN(D24,D22) -> 60380.6 | E25: =MIN(E24,E22) -> 76551.2 | F25: =MIN(F24,F22) -> 79815.6 | G25: =MIN(G24,G22) -> 78203 | H25: =MIN(H24,H22) -> 28215 | I25: =MIN(I24,I22) -> 42209.6 | J25: =MIN(J24,J22) -> 42209.6 | K25: =MIN(K24,K22) -> 72539.147 | ... BK25: =MIN(BK24,BK22) -> 69335.124
A26: Auto-comp. Ponta via FA (kWh) | B26: =SUM(D26:BQ26) -> 118996.39 | C26: =B26/60 -> 1983.2731 | D26: =MIN((D24-D25)*Premissas!$B$8,D23) -> 0 | E26: =MIN((E24-E25)*Premissas!$B$8,E23) -> 0 | F26: =MIN((F24-F25)*Premissas!$B$8,F23) -> 0 | G26: =MIN((G24-G25)*Premissas!$B$8,G23) -> 0 | H26: =MIN((H24-H25)*Premissas!$B$8,H23) -> 3135 | I26: =MIN((I24-I25)*Premissas!$B$8,I23) -> 4690 | J26: =MIN((J24-J25)*Premissas!$B$8,J23) -> 4690 | K26: =MIN((K24-K25)*Premissas!$B$8,K23) -> 6348.093 | ... BK26: =MIN((BK24-BK25)*Premissas!$B$8,BK23) -> 4203.3711
A27: =" "&INDEX(PVSYST_Helexia!$A$5:$A$7,MATCH(Premissas!$B$13,PVSYST_Helexia!$B$5:$B$7,0))&" créditos recebidos (kWh)" -> HCS03 créditos recebidos (kWh) | B27: =SUM(D27:BQ27) -> 4146923.6 | C27: =B27/60 -> 69115.393 | D27: =D6*Premissas!$B$33 -> 91504.62 | E27: =E6*Premissas!$B$33 -> 96316.38 | F27: =F6*Premissas!$B$33 -> 115622.46 | G27: =G6*Premissas!$B$33 -> 108493.38 | H27: =H6*Premissas!$C$33 -> 78229.224 | I27: =I6*Premissas!$C$33 -> 75640.224 | J27: =J6*Premissas!$C$33 -> 71824.038 | K27: =K6*Premissas!$C$33 -> 73747.303 | L27: =L6*Premissas!$C$33 -> 65715.163 | M27: =M6*Premissas!$C$33 -> 75375.369 | N27: =N6*Premissas!$D$33 -> 97520.917 | O27: =O6*Premissas!$D$33 -> 91268.035 | P27: =P6*Premissas!$D$33 -> 82830.652 | Q27: =Q6*Premissas!$D$33 -> 87186.292 | R27: =R6*Premissas!$D$33 -> 104662.3 | S27: =S6*Premissas!$D$33 -> 98209.001 | T27: =T6*Premissas!$E$33 -> 38964.136 | U27: =U6*Premissas!$E$33 -> 37674.616 | V27: =V6*Premissas!$E$33 -> 35773.864 | W27: =W6*Premissas!$E$33 -> 36916.379 | X27: =X6*Premissas!$E$33 -> 32895.655 | Y27: =Y6*Premissas!$E$33 -> 37731.355 | Z27: =Z6*Premissas!$E$33 -> 37648.826 | AA27: =AA6*Premissas!$E$33 -> 35234.844 | AB27: =AB6*Premissas!$F$33 -> 58197.292 | AC27: =AC6*Premissas!$F$33 -> 61257.59 | AD27: =AD6*Premissas!$F$33 -> 73536.331 | AE27: =AE6*Premissas!$F$33 -> 69002.209 | AF27: =AF6*Premissas!$F$33 -> 70912.548 | AG27: =AG6*Premissas!$F$33 -> 68565.694 | AH27: =AH6*Premissas!$G$33 -> 64172.612 | AI27: =AI6*Premissas!$G$33 -> 66222.101 | AJ27: =AJ6*Premissas!$G$33 -> 59009.564 | AK27: =AK6*Premissas!$G$33 -> 67684.039 | AL27: =AL6*Premissas!$G$33 -> 67535.995 | AM27: =AM6*Premissas!$G$33 -> 63205.697 | AN27: =AN6*Premissas!$H$33 -> 57698.669 | AO27: =AO6*Premissas!$H$33 -> 60732.746 | AP27: =AP6*Premissas!$H$33 -> 72906.286 | AQ27: =AQ6*Premissas!$H$33 -> 68411.011 | AR27: =AR6*Premissas!$H$33 -> 70304.983 | AS27: =AS6*Premissas!$H$33 -> 67978.236 | AT27: =AT6*Premissas!$I$33 -> 63619.461 | AU27: =AU6*Premissas!$I$33 -> 65651.284 | AV27: =AV6*Premissas!$I$33 -> 58500.917 | AW27: =AW6*Premissas!$I$33 -> 67100.621 | AX27: =AX6*Premissas!$I$33 -> 66953.853 | AY27: =AY6*Premissas!$I$33 -> 62660.881 | AZ27: =AZ6*Premissas!$J$33 -> 70802.642 | BA27: =BA6*Premissas!$J$33 -> 74525.791 | BB27: =BB6*Premissas!$J$33 -> 89464.069 | BC27: =BC6*Premissas!$J$33 -> 83947.87 | BD27: =BD6*Premissas!$J$33 -> 86271.983 | BE27: =BE6*Premissas!$J$33 -> 83416.807 | BF27: =BF6*Premissas!$K$33 -> 62825.516 | BG27: =BG6*Premissas!$K$33 -> 64831.983 | BH27: =BH6*Premissas!$K$33 -> 57770.85 | BI27: =BI6*Premissas!$K$33 -> 66263.232 | BJ27: =BJ6*Premissas!$K$33 -> 66118.296 | BK27: =BK6*Premissas!$K$33 -> 61878.898
A28: BAT créditos → NHS (kWh) | B28: =SUM(D28:BQ28) -> 1192710.1 | C28: =B28/60 -> 19878.501 | D28: =D19 -> 0 | E28: =E19 -> 0 | F28: =F19 -> 0 | G28: =G19 -> 32711.293 | H28: =H19 -> 40823.762 | I28: =I19 -> 41560.462 | J28: =J19 -> 47597.362 | K28: =K19 -> 51288.174 | ... BK28: =BK19 -> 12655.84
A29: Banco início mês COM Helexia (kWh) | B29: =AA29 -> 801819.36 | C29: — | D29: =Premissas!$B$26 -> 786669 | E29: =D31 -> 809872.79 | F29: =E31 -> 593317.92 | G29: =F31 -> 562661.95 | H29: =G31 -> 632334.22 | I29: =H31 -> 796332.31 | J29: =I31 -> 962353.89 | K29: =J31 -> 1128197.4 | L29: =K31 -> 1260905.5 | ... BK29: =BJ31 -> 336447.92
A30: Bank draw COM Helexia (kWh) | B30: =SUM(D30:BQ30) -> 4266371 | C30: =B30/60 -> 71106.184 | D30: =MIN(D29,MAX(D22-D24-D27+D28,0)+IF(Premissas!$B$8=0,0,MAX(D23-D26,0)/Premissas!$B$8)) -> 19986.528 | E30: =MIN(E29,MAX(E22-E24-E27+E28,0)+IF(Premissas!$B$8=0,0,MAX(E23-E26,0)/Premissas!$B$8)) -> 216554.87 | F30: =MIN(F29,MAX(F22-F24-F27+F28,0)+IF(Premissas!$B$8=0,0,MAX(F23-F26,0)/Premissas!$B$8)) -> 35116.427 | G30: =MIN(G29,MAX(G22-G24-G27+G28,0)+IF(Premissas!$B$8=0,0,MAX(G23-G26,0)/Premissas!$B$8)) -> 23256.605 | H30: =MIN(H29,MAX(H22-H24-H27+H28,0)+IF(Premissas!$B$8=0,0,MAX(H23-H26,0)/Premissas!$B$8)) -> 0 | I30: =MIN(I29,MAX(I22-I24-I27+I28,0)+IF(Premissas!$B$8=0,0,MAX(I23-I26,0)/Premissas!$B$8)) -> 0 | J30: =MIN(J29,MAX(J22-J24-J27+J28,0)+IF(Premissas!$B$8=0,0,MAX(J23-J26,0)/Premissas!$B$8)) -> 0 | K30: =MIN(K29,MAX(K22-K24-K27+K28,0)+IF(Premissas!$B$8=0,0,MAX(K23-K26,0)/Premissas!$B$8)) -> 2832.836 | ... BK30: =MIN(BK29,MAX(BK22-BK24-BK27+BK28,0)+IF(Premissas!$B$8=0,0,MAX(BK23-BK26,0)/Premissas!$B$8)) -> 5793.1019
A31: ★ Banco fim mês COM Helexia (kWh) | B31: =AA31 -> 864979.94 | C31: — | D31: =MAX(D29-D30,0)+D28+MAX(D27-MAX(D22-D24,0),0)+MAX(D24-D22,0) -> 809872.79 | E31: =MAX(E29-E30,0)+E28+MAX(E27-MAX(E22-E24,0),0)+MAX(E24-E22,0) -> 593317.92 | F31: =MAX(F29-F30,0)+F28+MAX(F27-MAX(F22-F24,0),0)+MAX(F24-F22,0) -> 562661.95 | G31: =MAX(G29-G30,0)+G28+MAX(G27-MAX(G22-G24,0),0)+MAX(G24-G22,0) -> 632334.22 | H31: =MAX(H29-H30,0)+H28+MAX(H27-MAX(H22-H24,0),0)+MAX(H24-H22,0) -> 796332.31 | I31: =MAX(I29-I30,0)+I28+MAX(I27-MAX(I22-I24,0),0)+MAX(I24-I22,0) -> 962353.89 | J31: =MAX(J29-J30,0)+J28+MAX(J27-MAX(J22-J24,0),0)+MAX(J24-J22,0) -> 1128197.4 | K31: =MAX(K29-K30,0)+K28+MAX(K27-MAX(K22-K24,0),0)+MAX(K24-K22,0) -> 1260905.5 | ... BK31: =MAX(BK29-BK30,0)+BK28+MAX(BK27-MAX(BK22-BK24,0),0)+MAX(BK24-BK22,0) -> 412145.7
A32: Banco início mês SEM Helexia (kWh) | B32: =AA32 -> 16130.024 | C32: — | D32: =Premissas!$B$26 -> 786669 | E32: =D34 -> 718368.17 | F32: =E34 -> 405496.92 | G32: =F34 -> 259218.49 | H32: =G34 -> 253108.68 | I32: =H34 -> 338877.54 | J32: =I34 -> 429258.9 | K32: =J34 -> 523278.36 | L32: =K34 -> 585071.98 | ... BK32: =BJ34 -> 12686.114
A33: Bank draw SEM Helexia (kWh) — gen+BAT, no CS3 | B33: =SUM(D33:BQ33) -> 2697471.3 | C33: =B33/60 -> 44957.856 | D33: =MIN(D32,MAX(D22-D24-D28,0)+IF(Premissas!$B$8=0,0,MAX(D23-D26-(IF(Premissas!$B$8>0,MAX(D24-D22,0)*Premissas!$B$8,0)),0)/Premissas!$B$8)) -> 68300.828 | E33: =MIN(E32,MAX(E22-E24-E28,0)+IF(Premissas!$B$8=0,0,MAX(E23-E26-(IF(Premissas!$B$8>0,MAX(E24-E22,0)*Premissas!$B$8,0)),0)/Premissas!$B$8)) -> 312871.25 | F33: =MIN(F32,MAX(F22-F24-F28,0)+IF(Premissas!$B$8=0,0,MAX(F23-F26-(IF(Premissas!$B$8>0,MAX(F24-F22,0)*Premissas!$B$8,0)),0)/Premissas!$B$8)) -> 146278.43 | G33: =MIN(G32,MAX(G22-G24-G28,0)+IF(Premissas!$B$8=0,0,MAX(G23-G26-(IF(Premissas!$B$8>0,MAX(G24-G22,0)*Premissas!$B$8,0)),0)/Premissas!$B$8)) -> 38821.112 | H33: =MIN(H32,MAX(H22-H24-H28,0)+IF(Premissas!$B$8=0,0,MAX(H23-H26-(IF(Premissas!$B$8>0,MAX(H24-H22,0)*Premissas!$B$8,0)),0)/Premissas!$B$8)) -> 0 | I33: =MIN(I32,MAX(I22-I24-I28,0)+IF(Premissas!$B$8=0,0,MAX(I23-I26-(IF(Premissas!$B$8>0,MAX(I24-I22,0)*Premissas!$B$8,0)),0)/Premissas!$B$8)) -> 0 | J33: =MIN(J32,MAX(J22-J24-J28,0)+IF(Premissas!$B$8=0,0,MAX(J23-J26-(IF(Premissas!$B$8>0,MAX(J24-J22,0)*Premissas!$B$8,0)),0)/Premissas!$B$8)) -> 0 | K33: =MIN(K32,MAX(K22-K24-K28,0)+IF(Premissas!$B$8=0,0,MAX(K23-K26-(IF(Premissas!$B$8>0,MAX(K24-K22,0)*Premissas!$B$8,0)),0)/Premissas!$B$8)) -> 0 | ... AA33: =MIN(AA32,MAX(AA22-AA24-AA28,0)+IF(Premissas!$B$8=0,0,MAX(AA23-AA26-(IF(Premissas!$B$8>0,MAX(AA24-AA22,0)*Premissas!$B$8,0)),0)/Premissas!$B$8)) -> 0 | AB33: =MIN(AB32,MAX(AB22-AB24-AB28,0)+IF(Premissas!$B$8=0,0,MAX(AB23-AB26-(IF(Premissas!$B$8>0,MAX(AB24-AB22,0),0))*Premissas!$B$8,0)/Premissas!$B$8)) -> 44055.758 | AC33: =MIN(AC32,MAX(AC22-AC24-AC28,0)+IF(Premissas!$B$8=0,0,MAX(AC23-AC26-(IF(Premissas!$B$8>0,MAX(AC24-AC22,0),0))*Premissas!$B$8,0)/Premissas!$B$8)) -> 0 | AD33: =MIN(AD32,MAX(AD22-AD24-AD28,0)+IF(Premissas!$B$8=0,0,MAX(AD23-AD26-(IF(Premissas!$B$8>0,MAX(AD24-AD22,0),0))*Premissas!$B$8,0)/Premissas!$B$8)) -> 0 | AE33: =MIN(AE32,MAX(AE22-AE24-AE28,0)+IF(Premissas!$B$8=0,0,MAX(AE23-AE26-(IF(Premissas!$B$8>0,MAX(AE24-AE22,0),0))*Premissas!$B$8,0)/Premissas!$B$8)) -> 0 | AF33: =MIN(AF32,MAX(AF22-AF24-AF28,0)+IF(Premissas!$B$8=0,0,MAX(AF23-AF26-(IF(Premissas!$B$8>0,MAX(AF24-AF22,0),0))*Premissas!$B$8,0)/Premissas!$B$8)) -> 0 | AG33: =MIN(AG32,MAX(AG22-AG24-AG28,0)+IF(Premissas!$B$8=0,0,MAX(AG23-AG26-(IF(Premissas!$B$8>0,MAX(AG24-AG22,0),0))*Premissas!$B$8,0)/Premissas!$B$8)) -> 0 | AH33: =MIN(AH32,MAX(AH22-AH24-AH28,0)+IF(Premissas!$B$8=0,0,MAX(AH23-AH26-(IF(Premissas!$B$8>0,MAX(AH24-AH22,0),0))*Premissas!$B$8,0)/Premissas!$B$8)) -> 0 | AI33: =MIN(AI32,MAX(AI22-AI24-AI28,0)+IF(Premissas!$B$8=0,0,MAX(AI23-AI26-(IF(Premissas!$B$8>0,MAX(AI24-AI22,0),0))*Premissas!$B$8,0)/Premissas!$B$8)) -> 0 | ... BK33: =MIN(BK32,MAX(BK22-BK24-BK28,0)+IF(Premissas!$B$8=0,0,MAX(BK23-BK26-(IF(Premissas!$B$8>0,MAX(BK24-BK22,0),0))*Premissas!$B$8,0)/Premissas!$B$8)) -> 0
A34: Banco fim mês SEM Helexia (kWh) — gen+BAT, no CS3 | B34: =AA34 -> 44055.758 | C34: — | D34: =MAX(D32-D33,0)+D28+MAX(D24-D22,0) -> 718368.17 | E34: =MAX(E32-E33,0)+E28+MAX(E24-E22,0) -> 405496.92 | F34: =MAX(F32-F33,0)+F28+MAX(F24-F22,0) -> 259218.49 | G34: =MAX(G32-G33,0)+G28+MAX(G24-G22,0) -> 253108.68 | H34: =MAX(H32-H33,0)+H28+MAX(H24-H22,0) -> 338877.54 | I34: =MAX(I32-I33,0)+I28+MAX(I24-I22,0) -> 429258.9 | J34: =MAX(J32-J33,0)+J28+MAX(J24-J22,0) -> 523278.36 | K34: =MAX(K32-K33,0)+K28+MAX(K24-K22,0) -> 585071.98 | ... BK34: =MAX(BK32-BK33,0)+BK28+MAX(BK24-BK22,0) -> 32298.103
