Workbook

Sheet Resumo
B1: ="SIMULAÇÃO RATEIO FIXO — "&Premissas!$B$13&" × COPASUL | Resumo Executivo" -> SIMULAÇÃO RATEIO FIXO — Cassilândia 03 × COPASUL | Resumo Executivo
B2: ="18 Unidades Consumidoras · Jun/2026–Mai/2028 · Energisa MS · Usina: "&Premissas!$B$13 -> 18 Unidades Consumidoras · Jun/2026–Mai/2028 · Energisa MS · Usina: Cassilândia 03
B4: ⚡ GERAÇÃO INJETADA | D4: 📄 PPA PAGO À HELEXIA | F4: ✅ ECONOMIA LÍQUIDA | H4: 🏦 BANCO RESIDUAL | J4: 🌟 VALOR TOTAL
B5: =Simulacao!B6/1000000 -> 3.3753139 | D5: =Simulacao!B7 -> 1493576.4 | F5: =Simulacao!B252 -> 435907.06 | H5: =Simulacao!B273*Premissas!$B$17 -> 510604.46 | J5: =Simulacao!B278 -> 776149.85
B6: 3,375 MWh injetados em 24 meses | D6: Custo total do contrato PPA | F6: Rede evitada menos PPA pago | H6: Banco total Copasul @ PPA | J6: Economia + banco ATRIBUÍVEL a Helexia
B8: A. CUSTO COPASUL — ANÁLISE 24 MESES | I8: B. INDICADORES-CHAVE
B9: COMPONENTE | E9: R$ | F9: % | G9: R$/mês | I9: Usina contratada | K9: =Premissas!$B$13 -> Cassilândia 03
B10: Custo SEM Helexia — baseline 24m | E10: =Simulacao!B249 -> 2015923 | F10: =Simulacao!B249/Simulacao!B249 -> 1 | G10: =(Simulacao!B249)/24 -> 83996.79 | I10: Período do contrato | K10: Jun/2026 – Mai/2028 (24 meses)
B11: Custo rede remanescente (COM Helexia) | E11: =Simulacao!B250 -> 86439.528 | F11: =Simulacao!B250/Simulacao!B249 -> 0.042878389 | G11: =(Simulacao!B250)/24 -> 3601.647 | I11: Potência contratada | K11: =VLOOKUP(Premissas!$B$13,PVSYST_Helexia!$B$5:$F$7,5,0)&" kWac" -> 625 kWac
B12: PPA pago à Helexia | E12: =Simulacao!B7 -> 1493576.4 | F12: =Simulacao!B7/Simulacao!B249 -> 0.74088961 | G12: =(Simulacao!B7)/24 -> 62232.349 | I12: Geração P50 total | K12: =Simulacao!B6/1000 -> 3375.3139
B13: Custo total COM Helexia (rede + PPA) | E13: =Simulacao!B251 -> 1580015.9 | F13: =Simulacao!B251/Simulacao!B249 -> 0.783768 | G13: =(Simulacao!B251)/24 -> 65833.996 | I13: PPA (R$/kWh) | K13: =Premissas!$B$17 -> 0.4425
B14: ★ ECONOMIA LÍQUIDA (rede − PPA) | E14: =Simulacao!B252 -> 435907.06 | F14: =Simulacao!B252/Simulacao!B249 -> 0.216232 | G14: =(Simulacao!B252)/24 -> 18162.794 | I14: Tarifa Grupo A FP | K14: =Premissas!$B$5 -> 0.52647111
B15: + Banco atribuível Helexia @ PPA (net NHS/AMD + Grupo B) | E15: =Simulacao!B285 -> 340242.8 | F15: =IFERROR(Simulacao!B285/Simulacao!B249,0) -> 0.16877768 | G15: =Simulacao!B285/24 -> 14176.783 | I15: Tarifa Grupo B3 | K15: =Premissas!$B$7 -> 1.1568636
B16: ★ VALOR TOTAL HELEXIA (economia + banco atribuível) | E16: =Simulacao!B278 -> 776149.85 | F16: =Simulacao!B278/Simulacao!B249 -> 0.38500968 | G16: =(Simulacao!B278)/24 -> 32339.577 | I16: Economia média/mês | K16: =Simulacao!B252/24 -> 18162.794
I17: % redução custo Copasul | K17: =IFERROR(Simulacao!B252/Simulacao!B249,0) -> 0.216232
I18: Banco residual (kWh) | K18: =Simulacao!B273 -> 1153908.4
B20: C. ANÁLISE VISUAL — ECONOMIA E BANCO DE CRÉDITOS
P22: Mês | Q22: SEM Helexia | R22: PPA | S22: Rede COM | T22: Eco mensal | U22: Eco acumulada
P23: Jun/26 | Q23: =Simulacao!D249 -> 29915.013 | R23: =Simulacao!D7 -> 54865.575 | S23: =Simulacao!D250 -> 2915.1861 | T23: =Simulacao!D252 -> -27865.748 | U23: =T23 -> -27865.748
P24: Jul/26 | Q24: =Simulacao!E249 -> 231390.51 | R24: =Simulacao!E7 -> 57750.675 | S24: =Simulacao!E250 -> 83523.678 | T24: =Simulacao!E252 -> 90116.154 | U24: =U23+T24 -> 62250.406
P25: Ago/26 | Q25: =Simulacao!F249 -> 156547.56 | R25: =Simulacao!F7 -> 69326.475 | S25: =Simulacao!F250 -> 0.54126728 | T25: =Simulacao!F252 -> 87220.544 | U25: =U24+T25 -> 149470.95
P26: Set/26 | Q26: =Simulacao!G249 -> 42616.08 | R26: =Simulacao!G7 -> 65051.925 | S26: =Simulacao!G250 -> 0.12303998 | T26: =Simulacao!G252 -> -22435.968 | U26: =U25+T26 -> 127034.98
P27: Out/26 | Q27: =Simulacao!H249 -> 43352.771 | R27: =Simulacao!H7 -> 66852.9 | S27: =Simulacao!H250 -> 0 | T27: =Simulacao!H252 -> -23500.129 | U27: =U26+T27 -> 103534.85
P28: Nov/26 | Q28: =Simulacao!I249 -> 43210.246 | R28: =Simulacao!I7 -> 64640.4 | S28: =Simulacao!I250 -> 0 | T28: =Simulacao!I252 -> -21430.154 | U28: =U27+T28 -> 82104.699
P29: Dez/26 | Q29: =Simulacao!J249 -> 44658.731 | R29: =Simulacao!J7 -> 61379.175 | S29: =Simulacao!J250 -> 0 | T29: =Simulacao!J252 -> -16720.444 | U29: =U28+T29 -> 65384.255
P30: Jan/27 | Q30: =Simulacao!K249 -> 42484.598 | R30: =Simulacao!K7 -> 63022.753 | S30: =Simulacao!K250 -> 0 | T30: =Simulacao!K252 -> -20538.155 | U30: =U29+T30 -> 44846.1
P31: Fev/27 | Q31: =Simulacao!L249 -> 45032.044 | R31: =Simulacao!L7 -> 56158.671 | S31: =Simulacao!L250 -> 0 | T31: =Simulacao!L252 -> -11126.626 | U31: =U30+T31 -> 33719.474
P32: Mar/27 | Q32: =Simulacao!M249 -> 208536.62 | R32: =Simulacao!M7 -> 64414.061 | S32: =Simulacao!M250 -> 0 | T32: =Simulacao!M252 -> 144122.56 | U32: =U31+T32 -> 177842.03
P33: Abr/27 | Q33: =Simulacao!N249 -> 35167.544 | R33: =Simulacao!N7 -> 64273.169 | S33: =Simulacao!N250 -> 0 | T33: =Simulacao!N252 -> -29105.625 | U33: =U32+T33 -> 148736.41
P34: Mai/27 | Q34: =Simulacao!O249 -> 32721.222 | R34: =Simulacao!O7 -> 60152.078 | S34: =Simulacao!O250 -> 0 | T34: =Simulacao!O252 -> -27430.856 | U34: =U33+T34 -> 121305.55
P35: Jun/27 | Q35: =Simulacao!P249 -> 70853.527 | R35: =Simulacao!P7 -> 54591.247 | S35: =Simulacao!P250 -> 0 | T35: =Simulacao!P252 -> 16262.28 | U35: =U34+T35 -> 137567.83
P36: Jul/27 | Q36: =Simulacao!Q249 -> 281671.07 | R36: =Simulacao!Q7 -> 57461.922 | S36: =Simulacao!Q250 -> 0 | T36: =Simulacao!Q252 -> 224209.15 | U36: =U35+T36 -> 361776.98
P37: Ago/27 | Q37: =Simulacao!R249 -> 161721.87 | R37: =Simulacao!R7 -> 68979.843 | S37: =Simulacao!R250 -> 0 | T37: =Simulacao!R252 -> 92742.025 | U37: =U36+T37 -> 454519.01
P38: Set/27 | Q38: =Simulacao!S249 -> 43681.482 | R38: =Simulacao!S7 -> 64726.665 | S38: =Simulacao!S250 -> 0 | T38: =Simulacao!S252 -> -21045.183 | U38: =U37+T38 -> 433473.83
P39: Out/27 | Q39: =Simulacao!T249 -> 44436.59 | R39: =Simulacao!T7 -> 66518.636 | S39: =Simulacao!T250 -> 0 | T39: =Simulacao!T252 -> -22082.045 | U39: =U38+T39 -> 411391.78
P40: Nov/27 | Q40: =Simulacao!U249 -> 44290.502 | R40: =Simulacao!U7 -> 64317.198 | S40: =Simulacao!U250 -> 0 | T40: =Simulacao!U252 -> -20026.696 | U40: =U39+T40 -> 391365.09
P41: Dez/27 | Q41: =Simulacao!V249 -> 45775.2 | R41: =Simulacao!V7 -> 61072.279 | S41: =Simulacao!V250 -> 0 | T41: =Simulacao!V252 -> -15297.079 | U41: =U40+T41 -> 376068.01
P42: Jan/28 | Q42: =Simulacao!W249 -> 42484.598 | R42: =Simulacao!W7 -> 63022.753 | S42: =Simulacao!W250 -> 0 | T42: =Simulacao!W252 -> -20538.155 | U42: =U41+T42 -> 355529.85
P43: Fev/28 | Q43: =Simulacao!X249 -> 45032.044 | R43: =Simulacao!X7 -> 56158.671 | S43: =Simulacao!X250 -> 0 | T43: =Simulacao!X252 -> -11126.626 | U43: =U42+T43 -> 344403.22
P44: Mar/28 | Q44: =Simulacao!Y249 -> 212454.37 | R44: =Simulacao!Y7 -> 64414.061 | S44: =Simulacao!Y250 -> 0 | T44: =Simulacao!Y252 -> 148040.31 | U44: =U43+T44 -> 492443.54
...

Sheet Premissas
A1: ="PREMISSAS — "&Premissas!$B$13&" × Copasul | Energisa MS" -> PREMISSAS — Cassilândia 03 × Copasul | Energisa MS | G1: 🎯 OTIMIZAÇÃO RATEIO — SOLVER CONFIG
A2: Azul = inputs editáveis | Preto = fórmulas | Verde = links entre abas | G2: Siga o passo a passo abaixo para maximizar Economia Líquida via Excel Solver
A4: A. TARIFAS ENERGISA MS (com tributos ICMS 17% + PIS/COFINS) | G4: ① CÉLULA OBJETIVO (aponte o Solver aqui): | J4: ENDEREÇO | K4: VALOR ATUAL | L4: OBJETIVO
A5: Tarifa Grupo A FP com tributos (R$/kWh) | B5: 0.52647111 | C5: ← T_AFP: edit here | G5: Economia Líquida Copasul 24m (R$) | J5: Premissas!K5 | K5: =Simulacao!B252 -> 435907.06 | L5: ↑ MAXIMIZAR
A6: Tarifa Grupo A Ponta com tributos (R$/kWh) | B6: 2.9723794 | C6: ← T_APT: edit here
A7: Tarifa Grupo B3 com tributos (R$/kWh) | B7: 1.1568636 | C7: ← T_B3: edit here | D7: =(592+286.02)/(1-B10)/(1-B9) -> 1156.7583 | G7: ② ATIVAR SOLVER (se ainda não estiver ativo) | I7: Arquivo → Opções → Suplementos → Gerenciar: Suplementos do Excel → Ir... → ✓ Solver Add-in → OK
A8: FA = TE_FP / TE_Ponta | B8: 0.60426705 | C8: ← FA: edit here | G8: ③ ABRIR SOLVER | I8: Guia Dados → botão "Solver" (canto direito da faixa de opções)
A9: ICMS (%) | B9: 0.17 | C9: ← ICMS: edit here | G9: ④ CONFIGURAR OBJETIVO | I9: Definir Objetivo: selecione a célula Premissas!K5 → marque ● Máx
A10: PIS + COFINS (%) | B10: 0.0855 | C10: ← PIS_COFINS: edit here | G10: ⑤ DEFINIR CÉLULAS VARIÁVEIS | I10: Alterando Células de Variáveis: Premissas!$B$33:$E$50 (68 variáveis = 17 UCs × 4 períodos)
A11: ICMS isenção autoconsumo remoto ativa? (Art. 23-A RICMS/MS) → 'Sim' = isento | 'Não' = ICMS cobrado sobre kWh compensados pelo CS3 | B11: Sim | C11: =IF($B$11="Sim",0,$B$5*$B$9/(1+$B$9)) -> 0 | D11: =IF($B$11="Sim",0,$B$6*$B$9/(1+$B$9)) -> 0 | E11: =IF($B$11="Sim",0,$B$7*$B$9/(1+$B$9)) -> 0 | F11: ← B=toggle (Sim/Não) | C=ICMS A_FP D=ICMS A_Ponta E=ICMS Grupo B (R$/kWh) — tudo 0 se Sim
A12: B. CONDIÇÕES DO CONTRATO | G12: ⑥ ADICIONAR AS RESTRIÇÕES (Adicionar → preencher cada linha → OK)
A13: Usina | B13: Cassilândia 03 | G13: Célula / Intervalo | I13: Relação | J13: Valor / Restrição | L13: Descrição
A14: Distribuidora | B14: Energisa MS | G14: Premissas!$B$33:$E$50 | I14: >= | J14: 0 | L14: Todos os rateios ≥ 0% (sem valores negativos)
A15: Início do contrato | B15: Jun/2026 | G15: Premissas!$B$51 | I15: = | J15: 1 | L15: Soma P1 = 100% (Jun–Set/26)
A16: Prazo (meses) | B16: 24 | G16: Premissas!$C$51 | I16: = | J16: 1 | L16: Soma P2 = 100% (Out/26–Mar/27)
A17: PPA Helexia CS3 (R$/kWh) | B17: 0.4425 | G17: Premissas!$D$51 | I17: = | J17: 1 | L17: Soma P3 = 100% (Abr–Set/27)
A18: H. CENÁRIO CONCORRENTE — ENERGIA ASSINATURA GRUPO B (ex: Plin Energia) | G18: Premissas!$E$51 | I18: = | J18: 1 | L18: Soma P4 = 100% (Out/27–Mai/28)
A19: Grupo B tem contrato Assinatura GD concorrente? | B19: Sim | C19: Desconto (%): | D19: 0.2 | E19: Tarifa B3 SEM efetiva: | F19: =IF(B19="Sim",B7*(1-D19),B7) -> 0.92549092 | G19: Premissas!$B$34:$E$34 | I19: = | J19: 0 | L19: BAT (linha 34) = 0% em todos os períodos
A20: C. PREMISSAS DE CRESCIMENTO E DEGRADAÇÃO | G20: Premissas!$B$33:$E$50 | I20: <= | J20: 1 | L20: Todos os rateios ≤ 100% (limite superior)
A21: Crescimento consumo Y2 vs Y1 (%) | B21: 0.025 | C21: ← 2.5% editável | aplica a TODOS os UCs
A22: Crescimento consumo Y3 parcial (Dez/27-Mai/28) (%) | B22: =B21 -> 0.025 | C22: ← mesmo % que Y2 por padrão | G22: ⑦ MÉTODO DE RESOLUÇÃO E OPÇÕES
A23: Degradação geração Y2 (%) | B23: 0.005 | C23: ← 0.5%/ano editável | G23: Método de Resolução: | I23: GRG Não-Linear | J23: O modelo tem funções IF (não-lineares). GRG é o método correto.
A24: Usar proxy Batayporã p/ Amandina gen? | B24: Sim | G24: Opções → Precisão: | I24: 0,000001 | J24: Maior precisão = resultado mais fino.
A25: D. BANCOS DE CRÉDITOS — SALDO INICIAL (Mai/2026, FPt GD I) | G25: Opções → Iterações: | I25: 1000 | J25: Permite mais buscas antes de parar.
A26: NHS — Silos Novo Horizonte do Sul (kWh) | B26: 148516 | G26: Opções → Convergência: | I26: 0,0001 | J26: Critério de parada quando melhoria < este valor.
A27: BAT — Silos Batayporã (kWh) [stranded — não transferível CS3] | B27: 906739 | G27: ⚠ Otimização local: | I27: Execute 2–3 vezes | J27: GRG pode parar em mínimo local. Rode com rateios iniciais diferentes e fique com o melhor resultado.
A28: AMD — Silos Amandina (kWh) | B28: 991029
A29: TOTAL NHS+AMD (kWh) | B29: =B26+B28 -> 1139545 | C29: ← BAT stranded bank não incluído no total | G29: ⑧ EXECUTAR → clicar "Resolver" → aceitar "Manter Solução do Solver"
G30: Economia Liquida ANTES da otimização (R$): | J30: 670877.66 | K30: ← valor antes de rodar o Solver (referência)
A31: ="E. RATEIO FIXO "&INDEX(PVSYST_Helexia!$A$5:$A$7,MATCH(Premissas!$B$13,PVSYST_Helexia!$B$5:$B$7,0))&" — 4 PERÍODOS (edit percentuais — devem somar 100% por período)" -> E. RATEIO FIXO HCS03 — 4 PERÍODOS (edit percentuais — devem somar 100% por período) | G31: Vsalor Banco Residual ANTES da otimização (R$): | J31: =Resumo!H5 -> 510604.46 | K31: ← valor antes de rodar o Solver (referência)
A32: UC / Planta | B32: P1: Jun–Set/26 | C32: P2: Out/26–Mar/27 | D32: P3: Abr/27–Set/27 | E32: P4: Out/27–Mai/28 | G32: Economia APÓS otimização (R$) — resultado: | J32: =Simulacao!B252 -> 435907.06 | K32: ← atualiza automaticamente após o Solver alterar B33:E50
A33: NHS — Silos N. Horizonte (A4V) | B33: 0.73507401 | C33: 0.52568024 | D33: 0.67565005 | E33: 0.2812
A34: BAT — Silos Batayporã (A4V) | B34: 0 | C34: 0 | D34: 0 | E34: 0
A35: AMD — Silos Amandina (A3A) | B35: 0 | C35: 0 | D35: 0.0040543277 | E35: 0.15613575
A36: AREC (B3) | B36: 0.02507178 | C36: 0.052438168 | D36: 0.030810666 | E36: 0.065745819
A37: Banheiro Motoristas (B3) | B37: 0.0029636272 | C37: 0.0050152416 | D37: 0.0040120941 | E37: 0.0045
A38: CTC Copasul (B3) | B38: 0.0030456113 | C38: 0.0077143316 | D38: 0.0039240548 | E38: 0.0072001249
A39: Depósito Irrigação (B3) | B39: 0.005207938 | C39: 0.011390137 | D39: 0.0081206428 | E39: 0.0095
A40: Entreposto (B3) | B40: 0.062427819 | C40: 0.10355391 | D40: 0.071218793 | E40: 0.19566197
A41: Esc. Deodápolis (B3) | B41: 0.020366818 | C41: 0.035456452 | D41: 0.025789767 | E41: 0.043215414
...

Sheet Input_Consumo_GrupoA
A1: INPUT — CONSUMO ORÇADO GRUPO A | Fonte: Consumo_Orçado_2026_GD
A2: Azul = valores editáveis (fonte: arquivo fornecido) | Preto = fórmulas de projeção Y2/Y3
A3: Mês | B3: NHS FP (kWh) | C3: NHS Ponta (kWh) | D3: BAT FP (kWh) | E3: BAT Ponta (kWh) | F3: AMD FP (kWh) | G3: AMD Ponta (kWh)
A4: Jan | B4: 70769.9 | C4: 7863.3 | D4: 113967 | E4: 12663 | F4: 73973.4 | G4: 8219.3
A5: Fev | B5: 243719.7 | C5: 27080 | D5: 125874 | E5: 13986 | F5: 209472.2 | G5: 23274.7
A6: Mar | B6: 331874.1 | C6: 36874.9 | D6: 57499.2 | E6: 6388.8 | F6: 173260.2 | G6: 19251.1
A7: Abr | B7: 102778.3 | C7: 11419.8 | D7: 35640 | E7: 3960 | F7: 78448.4 | G7: 8716.5
A8: Mai | B8: 62814.2 | C8: 6979.4 | D8: 79603.2 | E8: 8844.8 | F8: 102629.5 | G8: 11403.3
A9: Jun | B9: 108694.9 | C9: 12077.2 | D9: 78336 | E9: 8704 | F9: 182444.7 | G9: 20271.6
A10: Jul | B10: 328938.1 | C10: 36548.7 | D10: 115718.4 | E10: 12857.6 | F10: 234799.2 | G10: 26088.8
A11: Ago | B11: 190977.6 | C11: 21219.7 | D11: 23364 | E11: 2596 | F11: 134799.3 | G11: 14977.7
A12: Set | B12: 126478.8 | C12: 14053.2 | D12: 10800 | E12: 1200 | F12: 18637.2 | G12: 2070.8
A13: Out | B13: 28215 | C13: 3135 | D13: 10800 | E13: 1200 | F13: 24382.8 | G13: 2709.2
A14: Nov | B14: 42209.6 | C14: 4690 | D14: 10800 | E14: 1200 | F14: 20225.7 | G14: 2247.3
A15: Dez | B15: 42209.6 | C15: 4690 | D15: 3402 | E15: 378 | F15: 17142.3 | G15: 1904.7
A17: Crescimento Y2 aplicado automaticamente via Premissas!$B$21 (atualmente 2,5%). Altere lá para que todos os 18 UCs sejam atualizados.

Sheet Simulacao
A1: ="SIMULAÇÃO RATEIO FIXO — "&Premissas!$B$13&" × COPASUL | 18 UCs | Jun/2026–Mai/2028" -> SIMULAÇÃO RATEIO FIXO — Cassilândia 03 × COPASUL | 18 UCs | Jun/2026–Mai/2028
A2: Energisa MS · Todas as células são fórmulas · Azul=input Premissas · Verde=link entre abas
A4: INDICADOR / UC | B4: TOTAL 24m ou SALDO FINAL | C4: MÉD/mês ou unidade | D4: Jun/26 | E4: Jul/26 | F4: Ago/26 | G4: Set/26 | H4: Out/26 | I4: Nov/26 | J4: Dez/26 | K4: Jan/27 | L4: Fev/27 | M4: Mar/27 | N4: Abr/27 | O4: Mai/27 | P4: Jun/27 | Q4: Jul/27 | R4: Ago/27 | S4: Set/27 | T4: Out/27 | U4: Nov/27 | V4: Dez/27 | W4: Jan/28 | X4: Fev/28 | Y4: Mar/28 | Z4: Abr/28 | AA4: Mai/28
A5: ="0. "&Premissas!B13&" — GERAÇÃO E CUSTO PPA" -> 0. Cassilândia 03 — GERAÇÃO E CUSTO PPA
A6: =INDEX(PVSYST_Helexia!$A$5:$A$7,MATCH(Premissas!$B$13,PVSYST_Helexia!$B$5:$B$7,0))&" Geração P50 (kWh)" -> HCS03 Geração P50 (kWh) | B6: =SUM(D6:AA6) -> 3375313.9 | C6: =B6/24 -> 140638.08 | D6: =Premissas!$B$61 -> 123990 | E6: =Premissas!$B$62 -> 130510 | F6: =Premissas!$B$63 -> 156670 | G6: =Premissas!$B$64 -> 147010 | H6: =Premissas!$B$65 -> 151080 | I6: =Premissas!$B$66 -> 146080 | J6: =Premissas!$B$67 -> 138710 | K6: =Premissas!$B$68 -> 142424.3 | L6: =Premissas!$B$69 -> 126912.25 | M6: =Premissas!$B$70 -> 145568.5 | N6: =Premissas!$B$71 -> 145250.1 | O6: =Premissas!$B$72 -> 135936.9 | P6: =Premissas!$B$73 -> 123370.05 | Q6: =Premissas!$B$74 -> 129857.45 | R6: =Premissas!$B$75 -> 155886.65 | S6: =Premissas!$B$76 -> 146274.95 | T6: =Premissas!$B$77 -> 150324.6 | U6: =Premissas!$B$78 -> 145349.6 | V6: =Premissas!$B$79 -> 138016.45 | W6: =Premissas!$B$80 -> 142424.3 | X6: =Premissas!$B$81 -> 126912.25 | Y6: =Premissas!$B$82 -> 145568.5 | Z6: =Premissas!$B$83 -> 145250.1 | AA6: =Premissas!$B$84 -> 135936.9
A7: PPA Helexia — custo total (R$) | B7: =SUM(D7:AA7) -> 1493576.4 | C7: =B7/24 -> 62232.349 | D7: =D6*Premissas!$B$17 -> 54865.575 | E7: =E6*Premissas!$B$17 -> 57750.675 | F7: =F6*Premissas!$B$17 -> 69326.475 | G7: =G6*Premissas!$B$17 -> 65051.925 | H7: =H6*Premissas!$B$17 -> 66852.9 | I7: =I6*Premissas!$B$17 -> 64640.4 | J7: =J6*Premissas!$B$17 -> 61379.175 | K7: =K6*Premissas!$B$17 -> 63022.753 | ... AA7: =AA6*Premissas!$B$17 -> 60152.078
A8: 1. BAT — BATAYPORÃ — GERAÇÃO, CONSUMO E SURPLUS
A9: BAT Geração própria (kWh) | B9: =SUM(D9:AA9) -> 2254432.4 | C9: =B9/24 -> 93934.683 | D9: =+Batayporã!I8 -> 72286.9 | E9: =+Batayporã!I9 -> 88336.8 | F9: =+Batayporã!I10 -> 93082.7 | G9: =+Batayporã!I11 -> 94433.4 | H9: =+Batayporã!I12 -> 95906.8 | I9: =+Batayporã!I13 -> 107980.6 | J9: =+Batayporã!I14 -> 106603.9 | K9: =+Batayporã!I3*(1-Premissas!$B$23) -> 113687.7 | L9: =+Batayporã!I4*(1-Premissas!$B$23) -> 90676.241 | M9: =+Batayporã!I5*(1-Premissas!$B$23) -> 102546.59 | N9: =+Batayporã!I6*(1-Premissas!$B$23) -> 73341.151 | O9: =+Batayporã!I7*(1-Premissas!$B$23) -> 91158.517 | P9: =D9*(1-Premissas!$B$23) -> 71925.465 | Q9: =E9*(1-Premissas!$B$23) -> 87895.116 | R9: =F9*(1-Premissas!$B$23) -> 92617.287 | S9: =G9*(1-Premissas!$B$23) -> 93961.233 | T9: =H9*(1-Premissas!$B$23) -> 95427.266 | U9: =I9*(1-Premissas!$B$23) -> 107440.7 | V9: =J9*(1-Premissas!$B$23) -> 106070.88 | W9: =K9*(1-Premissas!$B$23) -> 113119.27 | ... AA9: =O9*(1-Premissas!$B$23) -> 90702.724
A10: BAT Consumo FP (kWh) | B10: =SUM(D10:AA10) -> 1358567.3 | C10: =B10/24 -> 56606.97 | D10: =Input_Consumo_GrupoA!$D$9 -> 78336 | E10: =Input_Consumo_GrupoA!$D$10 -> 115718.4 | F10: =Input_Consumo_GrupoA!$D$11 -> 23364 | G10: =Input_Consumo_GrupoA!$D$12 -> 10800 | H10: =Input_Consumo_GrupoA!$D$13 -> 10800 | I10: =Input_Consumo_GrupoA!$D$14 -> 10800 | J10: =Input_Consumo_GrupoA!$D$15 -> 3402 | K10: =Input_Consumo_GrupoA!$D$4*(1+Premissas!$B$21) -> 116816.17 | L10: =Input_Consumo_GrupoA!$D$5*(1+Premissas!$B$21) -> 129020.85 | M10: =Input_Consumo_GrupoA!$D$6*(1+Premissas!$B$21) -> 58936.68 | N10: =Input_Consumo_GrupoA!$D$7*(1+Premissas!$B$21) -> 36531 | O10: =Input_Consumo_GrupoA!$D$8*(1+Premissas!$B$21) -> 81593.28 | P10: =Input_Consumo_GrupoA!$D$9*(1+Premissas!$B$21) -> 80294.4 | Q10: =Input_Consumo_GrupoA!$D$10*(1+Premissas!$B$21) -> 118611.36 | R10: =Input_Consumo_GrupoA!$D$11*(1+Premissas!$B$21) -> 23948.1 | S10: =Input_Consumo_GrupoA!$D$12*(1+Premissas!$B$21) -> 11070 | T10: =Input_Consumo_GrupoA!$D$13*(1+Premissas!$B$21) -> 11070 | U10: =Input_Consumo_GrupoA!$D$14*(1+Premissas!$B$21) -> 11070 | V10: =Input_Consumo_GrupoA!$D$15*(1+Premissas!$B$21) -> 3487.05 | W10: =Input_Consumo_GrupoA!$D$4*(1+Premissas!$B$21) -> 116816.17 | X10: =Input_Consumo_GrupoA!$D$5*(1+Premissas!$B$21) -> 129020.85 | Y10: =Input_Consumo_GrupoA!$D$6*(1+Premissas!$B$21) -> 58936.68 | Z10: =Input_Consumo_GrupoA!$D$7*(1+Premissas!$B$21) -> 36531 | AA10: =Input_Consumo_GrupoA!$D$8*(1+Premissas!$B$21) -> 81593.28
A11: BAT Consumo Ponta (kWh) | B11: =SUM(D11:AA11) -> 150951.92 | C11: =B11/24 -> 6289.6633 | D11: =Input_Consumo_GrupoA!$E$9 -> 8704 | E11: =Input_Consumo_GrupoA!$E$10 -> 12857.6 | F11: =Input_Consumo_GrupoA!$E$11 -> 2596 | G11: =Input_Consumo_GrupoA!$E$12 -> 1200 | H11: =Input_Consumo_GrupoA!$E$13 -> 1200 | I11: =Input_Consumo_GrupoA!$E$14 -> 1200 | J11: =Input_Consumo_GrupoA!$E$15 -> 378 | K11: =Input_Consumo_GrupoA!$E$4*(1+Premissas!$B$21) -> 12979.575 | L11: =Input_Consumo_GrupoA!$E$5*(1+Premissas!$B$21) -> 14335.65 | M11: =Input_Consumo_GrupoA!$E$6*(1+Premissas!$B$21) -> 6548.52 | N11: =Input_Consumo_GrupoA!$E$7*(1+Premissas!$B$21) -> 4059 | O11: =Input_Consumo_GrupoA!$E$8*(1+Premissas!$B$21) -> 9065.92 | P11: =Input_Consumo_GrupoA!$E$9*(1+Premissas!$B$21) -> 8921.6 | Q11: =Input_Consumo_GrupoA!$E$10*(1+Premissas!$B$21) -> 13179.04 | R11: =Input_Consumo_GrupoA!$E$11*(1+Premissas!$B$21) -> 2660.9 | S11: =Input_Consumo_GrupoA!$E$12*(1+Premissas!$B$21) -> 1230 | T11: =Input_Consumo_GrupoA!$E$13*(1+Premissas!$B$21) -> 1230 | U11: =Input_Consumo_GrupoA!$E$14*(1+Premissas!$B$21) -> 1230 | V11: =Input_Consumo_GrupoA!$E$15*(1+Premissas!$B$21) -> 387.45 | W11: =Input_Consumo_GrupoA!$E$4*(1+Premissas!$B$21) -> 12979.575 | X11: =Input_Consumo_GrupoA!$E$5*(1+Premissas!$B$21) -> 14335.65 | Y11: =Input_Consumo_GrupoA!$E$6*(1+Premissas!$B$21) -> 6548.52 | Z11: =Input_Consumo_GrupoA!$E$7*(1+Premissas!$B$21) -> 4059 | AA11: =Input_Consumo_GrupoA!$E$8*(1+Premissas!$B$21) -> 9065.92
A12: BAT auto-comp. FP (kWh) | B12: =SUM(D12:AA12) -> 1202083.4 | C12: =B12/24 -> 50086.809 | D12: =MIN(D9,D10) -> 72286.9 | E12: =MIN(E9,E10) -> 88336.8 | F12: =MIN(F9,F10) -> 23364 | G12: =MIN(G9,G10) -> 10800 | H12: =MIN(H9,H10) -> 10800 | I12: =MIN(I9,I10) -> 10800 | J12: =MIN(J9,J10) -> 3402 | K12: =MIN(K9,K10) -> 113687.7 | ... AA12: =MIN(AA9,AA10) -> 81593.28
A13: BAT auto-comp. Ponta via FA (kWh) | B13: =SUM(D13:AA13) -> 45811.885 | C13: =B13/24 -> 1908.8285 | D13: =MIN((D9-D12)*Premissas!$B$8,D11) -> 0 | E13: =MIN((E9-E12)*Premissas!$B$8,E11) -> 0 | F13: =MIN((F9-F12)*Premissas!$B$8,F11) -> 2596 | G13: =MIN((G9-G12)*Premissas!$B$8,G11) -> 1200 | H13: =MIN((H9-H12)*Premissas!$B$8,H11) -> 1200 | I13: =MIN((I9-I12)*Premissas!$B$8,I11) -> 1200 | J13: =MIN((J9-J12)*Premissas!$B$8,J11) -> 378 | K13: =MIN((K9-K12)*Premissas!$B$8,K11) -> 0 | ... AA13: =MIN((AA9-AA12)*Premissas!$B$8,AA11) -> 5504.5371
A14: ★ BAT surplus líquido → rateio (kWh) | B14: =SUM(D14:AA14) -> 976535.01 | C14: =B14/24 -> 40688.959 | D14: =MAX(D9-D12-D11/Premissas!$B$8,0) -> 0 | E14: =MAX(E9-E12-E11/Premissas!$B$8,0) -> 0 | F14: =MAX(F9-F12-F11/Premissas!$B$8,0) -> 65422.586 | G14: =MAX(G9-G12-G11/Premissas!$B$8,0) -> 81647.523 | H14: =MAX(H9-H12-H11/Premissas!$B$8,0) -> 83120.923 | I14: =MAX(I9-I12-I11/Premissas!$B$8,0) -> 95194.723 | J14: =MAX(J9-J12-J11/Premissas!$B$8,0) -> 102576.35 | K14: =MAX(K9-K12-K11/Premissas!$B$8,0) -> 0 | ... AA14: =MAX(AA9-AA12-AA11/Premissas!$B$8,0) -> 0
A15: BAT banco stranded — depleção por consumo próprio apenas
A16: BAT banco início mês (kWh) | B16: =AA16 -> 582152.89 | C16: — | D16: =Premissas!$B$27 -> 906739 | E16: =D18 -> 886285.67 | F16: =E18 -> 837626.06 | G16: =F18 -> 837626.06 | H16: =G18 -> 837626.06 | I16: =H18 -> 837626.06 | J16: =I18 -> 837626.06 | K16: =J18 -> 837626.06 | L16: =K18 -> 813017.73 | ... AA16: =Z18 -> 582152.89
A17: BAT banco draw (kWh) | B17: =SUM(D17:AA17) -> 330479.83 | C17: =B17/24 -> 13769.993 | D17: =MIN(D16,MAX(D10-D12,0)+IF(Premissas!$B$8=0,0,MAX(D11-D13,0)/Premissas!$B$8)) -> 20453.327 | E17: =MIN(E16,MAX(E10-E12,0)+IF(Premissas!$B$8=0,0,MAX(E11-E13,0)/Premissas!$B$8)) -> 48659.609 | F17: =MIN(F16,MAX(F10-F12,0)+IF(Premissas!$B$8=0,0,MAX(F11-F13,0)/Premissas!$B$8)) -> 0 | G17: =MIN(G16,MAX(G10-G12,0)+IF(Premissas!$B$8=0,0,MAX(G11-G13,0)/Premissas!$B$8)) -> 0 | H17: =MIN(H16,MAX(H10-H12,0)+IF(Premissas!$B$8=0,0,MAX(H11-H13,0)/Premissas!$B$8)) -> 0 | I17: =MIN(I16,MAX(I10-I12,0)+IF(Premissas!$B$8=0,0,MAX(I11-I13,0)/Premissas!$B$8)) -> 0 | J17: =MIN(J16,MAX(J10-J12,0)+IF(Premissas!$B$8=0,0,MAX(J11-J13,0)/Premissas!$B$8)) -> 0 | K17: =MIN(K16,MAX(K10-K12,0)+IF(Premissas!$B$8=0,0,MAX(K11-K13,0)/Premissas!$B$8)) -> 24608.336 | ... AA17: =MIN(AA16,MAX(AA10-AA12,0)+IF(Premissas!$B$8=0,0,MAX(AA11-AA13,0)/Premissas!$B$8)) -> 5893.7235
A18: BAT banco fim mês (kWh) | B18: =AA18 -> 576259.17 | C18: — | D18: =MAX(D16-D17,0) -> 886285.67 | E18: =MAX(E16-E17,0) -> 837626.06 | F18: =MAX(F16-F17,0) -> 837626.06 | G18: =MAX(G16-G17,0) -> 837626.06 | H18: =MAX(H16-H17,0) -> 837626.06 | I18: =MAX(I16-I17,0) -> 837626.06 | J18: =MAX(J16-J17,0) -> 837626.06 | K18: =MAX(K16-K17,0) -> 813017.73 | ... AA18: =MAX(AA16-AA17,0) -> 576259.17
A19: BAT créditos → NHS (kWh, T+1) | B19: =SUM(D19:AA19) -> 488267.5 | C19: =B19/24 -> 20344.479 | D19: =0 -> 0 | E19: =D14*Premissas!$B$55 -> 0 | F19: =E14*Premissas!$B$55 -> 0 | G19: =F14*Premissas!$B$55 -> 32711.293 | H19: =G14*Premissas!$B$55 -> 40823.762 | I19: =H14*Premissas!$B$55 -> 41560.462 | J19: =I14*Premissas!$B$55 -> 47597.362 | K19: =J14*Premissas!$B$55 -> 51288.174 | L19: =K14*Premissas!$B$55 -> 0 | ... AA19: =Z14*Premissas!$B$55 -> 14863.108
A20: BAT créditos → AMD (kWh, T+1) | B20: =SUM(D20:AA20) -> 488267.5 | C20: =B20/24 -> 20344.479 | D20: =0 -> 0 | E20: =D14*Premissas!$B$56 -> 0 | F20: =E14*Premissas!$B$56 -> 0 | G20: =F14*Premissas!$B$56 -> 32711.293 | H20: =G14*Premissas!$B$56 -> 40823.762 | I20: =H14*Premissas!$B$56 -> 41560.462 | J20: =I14*Premissas!$B$56 -> 47597.362 | K20: =J14*Premissas!$B$56 -> 51288.174 | L20: =K14*Premissas!$B$56 -> 0 | ... AA20: =Z14*Premissas!$B$56 -> 14863.108
A21: NHS — N. Horizonte do Sul (A4V)
A22: Consumo FP (kWh) | B22: =SUM(D22:AA22) -> 3421650.5 | C22: =B22/24 -> 142568.77 | D22: =Input_Consumo_GrupoA!$B$9 -> 108694.9 | E22: =Input_Consumo_GrupoA!$B$10 -> 328938.1 | F22: =Input_Consumo_GrupoA!$B$11 -> 190977.6 | G22: =Input_Consumo_GrupoA!$B$12 -> 126478.8 | H22: =Input_Consumo_GrupoA!$B$13 -> 28215 | I22: =Input_Consumo_GrupoA!$B$14 -> 42209.6 | J22: =Input_Consumo_GrupoA!$B$15 -> 42209.6 | K22: =Input_Consumo_GrupoA!$B$4*(1+Premissas!$B$21) -> 72539.147 | L22: =Input_Consumo_GrupoA!$B$5*(1+Premissas!$B$21) -> 249812.69 | M22: =Input_Consumo_GrupoA!$B$6*(1+Premissas!$B$21) -> 340170.95 | N22: =Input_Consumo_GrupoA!$B$7*(1+Premissas!$B$21) -> 105347.76 | O22: =Input_Consumo_GrupoA!$B$8*(1+Premissas!$B$21) -> 64384.555 | P22: =Input_Consumo_GrupoA!$B$9*(1+Premissas!$B$21) -> 111412.27 | Q22: =Input_Consumo_GrupoA!$B$10*(1+Premissas!$B$21) -> 337161.55 | R22: =Input_Consumo_GrupoA!$B$11*(1+Premissas!$B$21) -> 195752.04 | S22: =Input_Consumo_GrupoA!$B$12*(1+Premissas!$B$21) -> 129640.77 | T22: =Input_Consumo_GrupoA!$B$13*(1+Premissas!$B$21) -> 28920.375 | U22: =Input_Consumo_GrupoA!$B$14*(1+Premissas!$B$21) -> 43264.84 | V22: =Input_Consumo_GrupoA!$B$15*(1+Premissas!$B$21) -> 43264.84 | W22: =Input_Consumo_GrupoA!$B$4*(1+Premissas!$B$21) -> 72539.147 | X22: =Input_Consumo_GrupoA!$B$5*(1+Premissas!$B$21) -> 249812.69 | Y22: =Input_Consumo_GrupoA!$B$6*(1+Premissas!$B$21) -> 340170.95 | Z22: =Input_Consumo_GrupoA!$B$7*(1+Premissas!$B$21) -> 105347.76 | AA22: =Input_Consumo_GrupoA!$B$8*(1+Premissas!$B$21) -> 64384.555
A23: Consumo Ponta (kWh) [via FA] | B23: =SUM(D23:AA23) -> 380183.62 | C23: =B23/24 -> 15840.984 | D23: =Input_Consumo_GrupoA!$C$9 -> 12077.2 | E23: =Input_Consumo_GrupoA!$C$10 -> 36548.7 | F23: =Input_Consumo_GrupoA!$C$11 -> 21219.7 | G23: =Input_Consumo_GrupoA!$C$12 -> 14053.2 | H23: =Input_Consumo_GrupoA!$C$13 -> 3135 | I23: =Input_Consumo_GrupoA!$C$14 -> 4690 | J23: =Input_Consumo_GrupoA!$C$15 -> 4690 | K23: =Input_Consumo_GrupoA!$C$4*(1+Premissas!$B$21) -> 8059.8825 | L23: =Input_Consumo_GrupoA!$C$5*(1+Premissas!$B$21) -> 27757 | M23: =Input_Consumo_GrupoA!$C$6*(1+Premissas!$B$21) -> 37796.772 | N23: =Input_Consumo_GrupoA!$C$7*(1+Premissas!$B$21) -> 11705.295 | O23: =Input_Consumo_GrupoA!$C$8*(1+Premissas!$B$21) -> 7153.885 | P23: =Input_Consumo_GrupoA!$C$9*(1+Premissas!$B$21) -> 12379.13 | Q23: =Input_Consumo_GrupoA!$C$10*(1+Premissas!$B$21) -> 37462.417 | R23: =Input_Consumo_GrupoA!$C$11*(1+Premissas!$B$21) -> 21750.192 | S23: =Input_Consumo_GrupoA!$C$12*(1+Premissas!$B$21) -> 14404.53 | T23: =Input_Consumo_GrupoA!$C$13*(1+Premissas!$B$21) -> 3213.375 | U23: =Input_Consumo_GrupoA!$C$14*(1+Premissas!$B$21) -> 4807.25 | V23: =Input_Consumo_GrupoA!$C$15*(1+Premissas!$B$21) -> 4807.25 | W23: =Input_Consumo_GrupoA!$C$4*(1+Premissas!$B$21) -> 8059.8825 | X23: =Input_Consumo_GrupoA!$C$5*(1+Premissas!$B$21) -> 27757 | Y23: =Input_Consumo_GrupoA!$C$6*(1+Premissas!$B$21) -> 37796.772 | Z23: =Input_Consumo_GrupoA!$C$7*(1+Premissas!$B$21) -> 11705.295 | AA23: =Input_Consumo_GrupoA!$C$8*(1+Premissas!$B$21) -> 7153.885
A24: Geração própria (kWh) | B24: =SUM(D24:AA24) -> 1867755.1 | C24: =B24/24 -> 77823.131 | D24: =+'Novo Horizonte do Sul'!I8 -> 60380.6 | E24: =+'Novo Horizonte do Sul'!I9 -> 76551.2 | F24: =+'Novo Horizonte do Sul'!I10 -> 79815.6 | G24: =+'Novo Horizonte do Sul'!I11 -> 78203 | H24: =+'Novo Horizonte do Sul'!I12 -> 73160.1 | I24: =+'Novo Horizonte do Sul'!I13 -> 91030.5 | J24: =+'Novo Horizonte do Sul'!I14 -> 88631.7 | K24: =+'Novo Horizonte do Sul'!I3*(1-Premissas!$B$23) -> 83044.59 | L24: =+'Novo Horizonte do Sul'!I4*(1-Premissas!$B$23) -> 75743.778 | M24: =+'Novo Horizonte do Sul'!I5*(1-Premissas!$B$23) -> 89408.909 | N24: =+'Novo Horizonte do Sul'!I6*(1-Premissas!$B$23) -> 62411.773 | O24: =+'Novo Horizonte do Sul'!I7*(1-Premissas!$B$23) -> 77836.363 | P24: =D24*(1-Premissas!$B$23) -> 60078.697 | Q24: =E24*(1-Premissas!$B$23) -> 76168.444 | R24: =F24*(1-Premissas!$B$23) -> 79416.522 | S24: =G24*(1-Premissas!$B$23) -> 77811.985 | T24: =H24*(1-Premissas!$B$23) -> 72794.299 | U24: =I24*(1-Premissas!$B$23) -> 90575.348 | V24: =J24*(1-Premissas!$B$23) -> 88188.541 | W24: =K24*(1-Premissas!$B$23) -> 82629.368 | ... AA24: =O24*(1-Premissas!$B$23) -> 77447.181
A25: Auto-comp. FP (kWh) | B25: =SUM(D25:AA25) -> 1544348.8 | C25: =B25/24 -> 64347.867 | D25: =MIN(D24,D22) -> 60380.6 | E25: =MIN(E24,E22) -> 76551.2 | F25: =MIN(F24,F22) -> 79815.6 | G25: =MIN(G24,G22) -> 78203 | H25: =MIN(H24,H22) -> 28215 | I25: =MIN(I24,I22) -> 42209.6 | J25: =MIN(J24,J22) -> 42209.6 | K25: =MIN(K24,K22) -> 72539.147 | ... AA25: =MIN(AA24,AA22) -> 64384.555
A26: Auto-comp. Ponta via FA (kWh) | B26: =SUM(D26:AA26) -> 52095.926 | C26: =B26/24 -> 2170.6636 | D26: =MIN((D24-D25)*Premissas!$B$8,D23) -> 0 | E26: =MIN((E24-E25)*Premissas!$B$8,E23) -> 0 | F26: =MIN((F24-F25)*Premissas!$B$8,F23) -> 0 | G26: =MIN((G24-G25)*Premissas!$B$8,G23) -> 0 | H26: =MIN((H24-H25)*Premissas!$B$8,H23) -> 3135 | I26: =MIN((I24-I25)*Premissas!$B$8,I23) -> 4690 | J26: =MIN((J24-J25)*Premissas!$B$8,J23) -> 4690 | K26: =MIN((K24-K25)*Premissas!$B$8,K23) -> 6348.093 | ... AA26: =MIN((AA24-AA25)*Premissas!$B$8,AA23) -> 7153.885
A27: =" "&INDEX(PVSYST_Helexia!$A$5:$A$7,MATCH(Premissas!$B$13,PVSYST_Helexia!$B$5:$B$7,0))&" créditos recebidos (kWh)" -> HCS03 créditos recebidos (kWh) | B27: =SUM(D27:AA27) -> 1740466.8 | C27: =B27/24 -> 72519.451 | D27: =D6*Premissas!$B$33 -> 91141.827 | E27: =E6*Premissas!$B$33 -> 95934.51 | F27: =F6*Premissas!$B$33 -> 115164.05 | G27: =G6*Premissas!$B$33 -> 108063.23 | H27: =H6*Premissas!$C$33 -> 79419.771 | I27: =I6*Premissas!$C$33 -> 76791.37 | J27: =J6*Premissas!$C$33 -> 72917.106 | K27: =K6*Premissas!$C$33 -> 74869.64 | L27: =L6*Premissas!$C$33 -> 66715.262 | M27: =M6*Premissas!$C$33 -> 76522.484 | N27: =N6*Premissas!$D$33 -> 98138.237 | O27: =O6*Premissas!$D$33 -> 91845.773 | P27: =P6*Premissas!$D$33 -> 83354.98 | Q27: =Q6*Premissas!$D$33 -> 87738.192 | R27: =R6*Premissas!$D$33 -> 105324.82 | S27: =S6*Premissas!$D$33 -> 98830.677 | T27: =T6*Premissas!$E$33 -> 42271.278 | U27: =U6*Premissas!$E$33 -> 40872.308 | V27: =V6*Premissas!$E$33 -> 38810.226 | W27: =W6*Premissas!$E$33 -> 40049.713 | X27: =X6*Premissas!$E$33 -> 35687.725 | Y27: =Y6*Premissas!$E$33 -> 40933.862 | Z27: =Z6*Premissas!$E$33 -> 40844.328 | AA27: =AA6*Premissas!$E$33 -> 38225.456
A28: BAT créditos → NHS (kWh) | B28: =SUM(D28:AA28) -> 488267.5 | C28: =B28/24 -> 20344.479 | D28: =D19 -> 0 | E28: =E19 -> 0 | F28: =F19 -> 0 | G28: =G19 -> 32711.293 | H28: =H19 -> 40823.762 | I28: =I19 -> 41560.462 | J28: =J19 -> 47597.362 | K28: =K19 -> 51288.174 | ... AA28: =AA19 -> 14863.108
A29: Banco início mês COM Helexia (kWh) | B29: =AA29 -> 297241.61 | C29: — | D29: =Premissas!$B$26 -> 148516 | E29: =D31 -> 171357 | F29: =E31 -> 0 | G29: =F31 -> 4002.0458 | H29: =G31 -> 92498.724 | I29: =H31 -> 257687.36 | J29: =I31 -> 424860.09 | K29: =J31 -> 591796.66 | L29: =K31 -> 725627.08 | ... AA29: =Z31 -> 297241.61
A30: Bank draw COM Helexia (kWh) | B30: =SUM(D30:AA30) -> 1433712.2 | C30: =B30/24 -> 59738.009 | D30: =MIN(D29,MAX(D22-D24-D27+D28,0)+IF(Premissas!$B$8=0,0,MAX(D23-D26,0)/Premissas!$B$8)) -> 19986.528 | E30: =MIN(E29,MAX(E22-E24-E27+E28,0)+IF(Premissas!$B$8=0,0,MAX(E23-E26,0)/Premissas!$B$8)) -> 171357 | F30: =MIN(F29,MAX(F22-F24-F27+F28,0)+IF(Premissas!$B$8=0,0,MAX(F23-F26,0)/Premissas!$B$8)) -> 0 | G30: =MIN(G29,MAX(G22-G24-G27+G28,0)+IF(Premissas!$B$8=0,0,MAX(G23-G26,0)/Premissas!$B$8)) -> 4002.0458 | H30: =MIN(H29,MAX(H22-H24-H27+H28,0)+IF(Premissas!$B$8=0,0,MAX(H23-H26,0)/Premissas!$B$8)) -> 0 | I30: =MIN(I29,MAX(I22-I24-I27+I28,0)+IF(Premissas!$B$8=0,0,MAX(I23-I26,0)/Premissas!$B$8)) -> 0 | J30: =MIN(J29,MAX(J22-J24-J27+J28,0)+IF(Premissas!$B$8=0,0,MAX(J23-J26,0)/Premissas!$B$8)) -> 0 | K30: =MIN(K29,MAX(K22-K24-K27+K28,0)+IF(Premissas!$B$8=0,0,MAX(K23-K26,0)/Premissas!$B$8)) -> 2832.836 | ... AA30: =MIN(AA29,MAX(AA22-AA24-AA27+AA28,0)+IF(Premissas!$B$8=0,0,MAX(AA23-AA26,0)/Premissas!$B$8)) -> 0
A31: ★ Banco fim mês COM Helexia (kWh) | B31: =AA31 -> 363392.8 | C31: — | D31: =MAX(D29-D30,0)+D28+MAX(D27-MAX(D22-D24,0),0)+MAX(D24-D22,0) -> 171357 | E31: =MAX(E29-E30,0)+E28+MAX(E27-MAX(E22-E24,0),0)+MAX(E24-E22,0) -> 0 | F31: =MAX(F29-F30,0)+F28+MAX(F27-MAX(F22-F24,0),0)+MAX(F24-F22,0) -> 4002.0458 | G31: =MAX(G29-G30,0)+G28+MAX(G27-MAX(G22-G24,0),0)+MAX(G24-G22,0) -> 92498.724 | H31: =MAX(H29-H30,0)+H28+MAX(H27-MAX(H22-H24,0),0)+MAX(H24-H22,0) -> 257687.36 | I31: =MAX(I29-I30,0)+I28+MAX(I27-MAX(I22-I24,0),0)+MAX(I24-I22,0) -> 424860.09 | J31: =MAX(J29-J30,0)+J28+MAX(J27-MAX(J22-J24,0),0)+MAX(J24-J22,0) -> 591796.66 | K31: =MAX(K29-K30,0)+K28+MAX(K27-MAX(K22-K24,0),0)+MAX(K24-K22,0) -> 725627.08 | ... AA31: =MAX(AA29-AA30,0)+AA28+MAX(AA27-MAX(AA22-AA24,0),0)+MAX(AA24-AA22,0) -> 363392.8
A32: Banco início mês SEM Helexia (kWh) | B32: =AA32 -> 16130.024 | C32: — | D32: =Premissas!$B$26 -> 148516 | E32: =D34 -> 80215.172 | F32: =E34 -> 0 | G32: =F34 -> 0 | H32: =G34 -> 32711.293 | I32: =H34 -> 118480.15 | J32: =I34 -> 208861.52 | K32: =J34 -> 302880.98 | L32: =K34 -> 364674.6 | ... AA32: =Z34 -> 16130.024
A33: Bank draw SEM Helexia (kWh) — gen+BAT, no CS3 | B33: =SUM(D33:AA33) -> 916134.08 | C33: =B33/24 -> 38172.253 | D33: =MIN(D32,MAX(D22-D24-D28,0)+IF(Premissas!$B$8=0,0,MAX(D23-D26-(IF(Premissas!$B$8>0,MAX(D24-D22,0)*Premissas!$B$8,0)),0)/Premissas!$B$8)) -> 68300.828 | E33: =MIN(E32,MAX(E22-E24-E28,0)+IF(Premissas!$B$8=0,0,MAX(E23-E26-(IF(Premissas!$B$8>0,MAX(E24-E22,0)*Premissas!$B$8,0)),0)/Premissas!$B$8)) -> 80215.172 | F33: =MIN(F32,MAX(F22-F24-F28,0)+IF(Premissas!$B$8=0,0,MAX(F23-F26-(IF(Premissas!$B$8>0,MAX(F24-F22,0)*Premissas!$B$8,0)),0)/Premissas!$B$8)) -> 0 | G33: =MIN(G32,MAX(G22-G24-G28,0)+IF(Premissas!$B$8=0,0,MAX(G23-G26-(IF(Premissas!$B$8>0,MAX(G24-G22,0)*Premissas!$B$8,0)),0)/Premissas!$B$8)) -> 0 | H33: =MIN(H32,MAX(H22-H24-H28,0)+IF(Premissas!$B$8=0,0,MAX(H23-H26-(IF(Premissas!$B$8>0,MAX(H24-H22,0)*Premissas!$B$8,0)),0)/Premissas!$B$8)) -> 0 | I33: =MIN(I32,MAX(I22-I24-I28,0)+IF(Premissas!$B$8=0,0,MAX(I23-I26-(IF(Premissas!$B$8>0,MAX(I24-I22,0)*Premissas!$B$8,0)),0)/Premissas!$B$8)) -> 0 | J33: =MIN(J32,MAX(J22-J24-J28,0)+IF(Premissas!$B$8=0,0,MAX(J23-J26-(IF(Premissas!$B$8>0,MAX(J24-J22,0)*Premissas!$B$8,0)),0)/Premissas!$B$8)) -> 0 | K33: =MIN(K32,MAX(K22-K24-K28,0)+IF(Premissas!$B$8=0,0,MAX(K23-K26-(IF(Premissas!$B$8>0,MAX(K24-K22,0)*Premissas!$B$8,0)),0)/Premissas!$B$8)) -> 0 | ... AA33: =MIN(AA32,MAX(AA22-AA24-AA28,0)+IF(Premissas!$B$8=0,0,MAX(AA23-AA26-(IF(Premissas!$B$8>0,MAX(AA24-AA22,0)*Premissas!$B$8,0)),0)/Premissas!$B$8)) -> 0
A34: Banco fim mês SEM Helexia (kWh) — gen+BAT, no CS3 | B34: =AA34 -> 44055.758 | C34: — | D34: =MAX(D32-D33,0)+D28+MAX(D24-D22,0) -> 80215.172 | E34: =MAX(E32-E33,0)+E28+MAX(E24-E22,0) -> 0 | F34: =MAX(F32-F33,0)+F28+MAX(F24-F22,0) -> 0 | G34: =MAX(G32-G33,0)+G28+MAX(G24-G22,0) -> 32711.293 | H34: =MAX(H32-H33,0)+H28+MAX(H24-H22,0) -> 118480.15 | I34: =MAX(I32-I33,0)+I28+MAX(I24-I22,0) -> 208861.52 | J34: =MAX(J32-J33,0)+J28+MAX(J24-J22,0) -> 302880.98 | K34: =MAX(K32-K33,0)+K28+MAX(K24-K22,0) -> 364674.6 | ... AA34: =MAX(AA32-AA33,0)+AA28+MAX(AA24-AA22,0) -> 44055.758
A35: =" Custo SEM Helexia (R$) — só gen própria, sem "&INDEX(PVSYST_Helexia!$A$5:$A$7,MATCH(Premissas!$B$13,PVSYST_Helexia!$B$5:$B$7,0))&"/BAT/banco" -> Custo SEM Helexia (R$) — só gen própria, sem HCS03/BAT/banco | B35: =SUM(D35:AA35) -> 1076040.7 | C35: =B35/24 -> 44835.031 | D35: =IF(D34>0,0,MAX(D22-D24-D28-D32,0)*Premissas!$B$5+MAX(D23-D26-(IF(Premissas!$B$8>0,MAX(D24+D28+D32-D22,0)*Premissas!$B$8,0)),0)*Premissas!$B$6) -> 0 | E35: =IF(E34>0,0,MAX(E22-E24-E28-E32,0)*Premissas!$B$5+MAX(E23-E26-(IF(Premissas!$B$8>0,MAX(E24+E28+E32-E22,0)*Premissas!$B$8,0)),0)*Premissas!$B$6) -> 199280.04 | F35: =IF(F34>0,0,MAX(F22-F24-F28-F32,0)*Premissas!$B$5+MAX(F23-F26-(IF(Premissas!$B$8>0,MAX(F24+F28+F32-F22,0)*Premissas!$B$8,0)),0)*Premissas!$B$6) -> 121596.58 | G35: =IF(G34>0,0,MAX(G22-G24-G28-G32,0)*Premissas!$B$5+MAX(G23-G26-(IF(Premissas!$B$8>0,MAX(G24+G28+G32-G22,0)*Premissas!$B$8,0)),0)*Premissas!$B$6) -> 0 | H35: =IF(H34>0,0,MAX(H22-H24-H28-H32,0)*Premissas!$B$5+MAX(H23-H26-(IF(Premissas!$B$8>0,MAX(H24+H28+H32-H22,0)*Premissas!$B$8,0)),0)*Premissas!$B$6) -> 0 | I35: =IF(I34>0,0,MAX(I22-I24-I28-I32,0)*Premissas!$B$5+MAX(I23-I26-(IF(Premissas!$B$8>0,MAX(I24+I28+I32-I22,0)*Premissas!$B$8,0)),0)*Premissas!$B$6) -> 0 | J35: =IF(J34>0,0,MAX(J22-J24-J28-J32,0)*Premissas!$B$5+MAX(J23-J26-(IF(Premissas!$B$8>0,MAX(J24+J28+J32-J22,0)*Premissas!$B$8,0)),0)*Premissas!$B$6) -> 0 | K35: =IF(K34>0,0,MAX(K22-K24-K28-K32,0)*Premissas!$B$5+MAX(K23-K26-(IF(Premissas!$B$8>0,MAX(K24+K28+K32-K22,0)*Premissas!$B$8,0)),0)*Premissas!$B$6) -> 0 | ... AA35: =IF(AA34>0,0,MAX(AA22-AA24-AA28-AA32,0)*Premissas!$B$5+MAX(AA23-AA26-(IF(Premissas!$B$8>0,MAX(AA24+AA28+AA32-AA22,0)*Premissas!$B$8,0)),0)*Premissas!$B$6) -> 0
A36: Custo COM Helexia — rede remanescente (R$) | B36: =SUM(D36:AA36) -> 81866.272 | C36: =B36/24 -> 3411.0947 | D36: =IF(D31>0,0,MAX(D22-D24-D27+D28-D29,0)*Premissas!$B$5+MAX(D23-D26-(IF(Premissas!$B$8>0,MAX(D24+D27+D28+D29-D22,0)*Premissas!$B$8,0)),0)*Premissas!$B$6) -> 0 | E36: =IF(E31>0,0,MAX(E22-E24-E27+E28-E29,0)*Premissas!$B$5+MAX(E23-E26-(IF(Premissas!$B$8>0,MAX(E24+E27+E28+E29-E22,0)*Premissas!$B$8,0)),0)*Premissas!$B$6) -> 81866.272 | F36: =IF(F31>0,0,MAX(F22-F24-F27+F28-F29,0)*Premissas!$B$5+MAX(F23-F26-(IF(Premissas!$B$8>0,MAX(F24+F27+F28+F29-F22,0)*Premissas!$B$8,0)),0)*Premissas!$B$6) -> 0 | G36: =IF(G31>0,0,MAX(G22-G24-G27+G28-G29,0)*Premissas!$B$5+MAX(G23-G26-(IF(Premissas!$B$8>0,MAX(G24+G27+G28+G29-G22,0)*Premissas!$B$8,0)),0)*Premissas!$B$6) -> 0 | H36: =IF(H31>0,0,MAX(H22-H24-H27+H28-H29,0)*Premissas!$B$5+MAX(H23-H26-(IF(Premissas!$B$8>0,MAX(H24+H27+H28+H29-H22,0)*Premissas!$B$8,0)),0)*Premissas!$B$6) -> 0 | I36: =IF(I31>0,0,MAX(I22-I24-I27+I28-I29,0)*Premissas!$B$5+MAX(I23-I26-(IF(Premissas!$B$8>0,MAX(I24+I27+I28+I29-I22,0)*Premissas!$B$8,0)),0)*Premissas!$B$6) -> 0 | J36: =IF(J31>0,0,MAX(J22-J24-J27+J28-J29,0)*Premissas!$B$5+MAX(J23-J26-(IF(Premissas!$B$8>0,MAX(J24+J27+J28+J29-J22,0)*Premissas!$B$8,0)),0)*Premissas!$B$6) -> 0 | K36: =IF(K31>0,0,MAX(K22-K24-K27+K28-K29,0)*Premissas!$B$5+MAX(K23-K26-(IF(Premissas!$B$8>0,MAX(K24+K27+K28+K29-K22,0)*Premissas!$B$8,0)),0)*Premissas!$B$6) -> 0 | ... AA36: =IF(AA31>0,0,MAX(AA22-AA24-AA27+AA28-AA29,0)*Premissas!$B$5+MAX(AA23-AA26-(IF(Premissas!$B$8>0,MAX(AA24+AA27+AA28+AA29-AA22,0)*Premissas!$B$8,0)),0)*Premissas!$B$6) -> 0
A37: ★ Economia mensal (R$) | B37: =SUM(D37:AA37) -> 994174.47 | C37: =B37/24 -> 41423.936 | D37: =MAX(D35-D36,0) -> 0 | E37: =MAX(E35-E36,0) -> 117413.77 | F37: =MAX(F35-F36,0) -> 121596.58 | G37: =MAX(G35-G36,0) -> 0 | H37: =MAX(H35-H36,0) -> 0 | I37: =MAX(I35-I36,0) -> 0 | J37: =MAX(J35-J36,0) -> 0 | K37: =MAX(K35-K36,0) -> 0 | ... AA37: =MAX(AA35-AA36,0) -> 0
A39: AMD — Amandina (A3A)
A40: Consumo FP (kWh) | B40: =SUM(D40:AA40) -> 2588129.8 | C40: =B40/24 -> 107838.74 | D40: =Input_Consumo_GrupoA!$F$9 -> 182444.7 | E40: =Input_Consumo_GrupoA!$F$10 -> 234799.2 | F40: =Input_Consumo_GrupoA!$F$11 -> 134799.3 | G40: =Input_Consumo_GrupoA!$F$12 -> 18637.2 | H40: =Input_Consumo_GrupoA!$F$13 -> 24382.8 | I40: =Input_Consumo_GrupoA!$F$14 -> 20225.7 | J40: =Input_Consumo_GrupoA!$F$15 -> 17142.3 | K40: =Input_Consumo_GrupoA!$F$4*(1+Premissas!$B$21) -> 75822.735 | L40: =Input_Consumo_GrupoA!$F$5*(1+Premissas!$B$21) -> 214709.01 | M40: =Input_Consumo_GrupoA!$F$6*(1+Premissas!$B$21) -> 177591.7 | N40: =Input_Consumo_GrupoA!$F$7*(1+Premissas!$B$21) -> 80409.61 | O40: =Input_Consumo_GrupoA!$F$8*(1+Premissas!$B$21) -> 105195.24 | P40: =Input_Consumo_GrupoA!$F$9*(1+Premissas!$B$21) -> 187005.82 | Q40: =Input_Consumo_GrupoA!$F$10*(1+Premissas!$B$21) -> 240669.18 | R40: =Input_Consumo_GrupoA!$F$11*(1+Premissas!$B$21) -> 138169.28 | S40: =Input_Consumo_GrupoA!$F$12*(1+Premissas!$B$21) -> 19103.13 | T40: =Input_Consumo_GrupoA!$F$13*(1+Premissas!$B$21) -> 24992.37 | U40: =Input_Consumo_GrupoA!$F$14*(1+Premissas!$B$21) -> 20731.342 | V40: =Input_Consumo_GrupoA!$F$15*(1+Premissas!$B$21) -> 17570.857 | W40: =Input_Consumo_GrupoA!$F$4*(1+Premissas!$B$21) -> 75822.735 | X40: =Input_Consumo_GrupoA!$F$5*(1+Premissas!$B$21) -> 214709.01 | Y40: =Input_Consumo_GrupoA!$F$6*(1+Premissas!$B$21) -> 177591.7 | Z40: =Input_Consumo_GrupoA!$F$7*(1+Premissas!$B$21) -> 80409.61 | AA40: =Input_Consumo_GrupoA!$F$8*(1+Premissas!$B$21) -> 105195.24
A41: Consumo Ponta (kWh) [via FA] | B41: =SUM(D41:AA41) -> 287570 | C41: =B41/24 -> 11982.083 | D41: =Input_Consumo_GrupoA!$G$9 -> 20271.6 | E41: =Input_Consumo_GrupoA!$G$10 -> 26088.8 | F41: =Input_Consumo_GrupoA!$G$11 -> 14977.7 | G41: =Input_Consumo_GrupoA!$G$12 -> 2070.8 | H41: =Input_Consumo_GrupoA!$G$13 -> 2709.2 | I41: =Input_Consumo_GrupoA!$G$14 -> 2247.3 | J41: =Input_Consumo_GrupoA!$G$15 -> 1904.7 | K41: =Input_Consumo_GrupoA!$G$4*(1+Premissas!$B$21) -> 8424.7825 | L41: =Input_Consumo_GrupoA!$G$5*(1+Premissas!$B$21) -> 23856.567 | M41: =Input_Consumo_GrupoA!$G$6*(1+Premissas!$B$21) -> 19732.377 | N41: =Input_Consumo_GrupoA!$G$7*(1+Premissas!$B$21) -> 8934.4125 | O41: =Input_Consumo_GrupoA!$G$8*(1+Premissas!$B$21) -> 11688.382 | P41: =Input_Consumo_GrupoA!$G$9*(1+Premissas!$B$21) -> 20778.39 | Q41: =Input_Consumo_GrupoA!$G$10*(1+Premissas!$B$21) -> 26741.02 | R41: =Input_Consumo_GrupoA!$G$11*(1+Premissas!$B$21) -> 15352.142 | S41: =Input_Consumo_GrupoA!$G$12*(1+Premissas!$B$21) -> 2122.57 | T41: =Input_Consumo_GrupoA!$G$13*(1+Premissas!$B$21) -> 2776.93 | U41: =Input_Consumo_GrupoA!$G$14*(1+Premissas!$B$21) -> 2303.4825 | V41: =Input_Consumo_GrupoA!$G$15*(1+Premissas!$B$21) -> 1952.3175 | W41: =Input_Consumo_GrupoA!$G$4*(1+Premissas!$B$21) -> 8424.7825 | X41: =Input_Consumo_GrupoA!$G$5*(1+Premissas!$B$21) -> 23856.567 | Y41: =Input_Consumo_GrupoA!$G$6*(1+Premissas!$B$21) -> 19732.377 | Z41: =Input_Consumo_GrupoA!$G$7*(1+Premissas!$B$21) -> 8934.4125 | AA41: =Input_Consumo_GrupoA!$G$8*(1+Premissas!$B$21) -> 11688.382
A42: Geração própria (kWh) | B42: =SUM(D42:AA42) -> 1805431.6 | C42: =B42/24 -> 75226.315 | D42: =IF(Premissas!$B$24="Sim",Amandina!$L$8*1000,Amandina!$I$8) -> 57829.52 | E42: =IF(Premissas!$B$24="Sim",Amandina!$L$9*1000,Amandina!$I$9) -> 70669.44 | F42: =IF(Premissas!$B$24="Sim",Amandina!$L$10*1000,Amandina!$I$10) -> 74466.16 | G42: =IF(Premissas!$B$24="Sim",Amandina!$L$11*1000,Amandina!$I$11) -> 75546.72 | H42: =IF(Premissas!$B$24="Sim",Amandina!$L$12*1000,Amandina!$I$12) -> 76725.44 | I42: =IF(Premissas!$B$24="Sim",Amandina!$L$13*1000,Amandina!$I$13) -> 86384.48 | J42: =IF(Premissas!$B$24="Sim",Amandina!$L$14*1000,Amandina!$I$14) -> 85283.12 | K42: =IF(Premissas!$B$24="Sim",Amandina!$L$3*1000*(1-Premissas!$B$23),Amandina!$I$3*(1-Premissas!$B$23)) -> 90950.164 | L42: =IF(Premissas!$B$24="Sim",Amandina!$L$4*1000*(1-Premissas!$B$23),Amandina!$I$4*(1-Premissas!$B$23)) -> 72540.992 | M42: =IF(Premissas!$B$24="Sim",Amandina!$L$5*1000*(1-Premissas!$B$23),Amandina!$I$5*(1-Premissas!$B$23)) -> 82037.272 | N42: =IF(Premissas!$B$24="Sim",Amandina!$L$6*1000*(1-Premissas!$B$23),Amandina!$I$6*(1-Premissas!$B$23)) -> 58672.921 | O42: =IF(Premissas!$B$24="Sim",Amandina!$L$7*1000*(1-Premissas!$B$23),Amandina!$I$7*(1-Premissas!$B$23)) -> 72926.814 | P42: =IF(Premissas!$B$24="Sim",Amandina!$L$8*1000*(1-Premissas!$B$23),Amandina!$I$8*(1-Premissas!$B$23)) -> 57540.372 | Q42: =IF(Premissas!$B$24="Sim",Amandina!$L$9*1000*(1-Premissas!$B$23),Amandina!$I$9*(1-Premissas!$B$23)) -> 70316.093 | R42: =IF(Premissas!$B$24="Sim",Amandina!$L$10*1000*(1-Premissas!$B$23),Amandina!$I$10*(1-Premissas!$B$23)) -> 74093.829 | S42: =IF(Premissas!$B$24="Sim",Amandina!$L$11*1000*(1-Premissas!$B$23),Amandina!$I$11*(1-Premissas!$B$23)) -> 75168.986 | T42: =IF(Premissas!$B$24="Sim",Amandina!$L$12*1000*(1-Premissas!$B$23),Amandina!$I$12*(1-Premissas!$B$23)) -> 76341.813 | U42: =IF(Premissas!$B$24="Sim",Amandina!$L$13*1000*(1-Premissas!$B$23),Amandina!$I$13*(1-Premissas!$B$23)) -> 85952.558 | V42: =IF(Premissas!$B$24="Sim",Amandina!$L$14*1000*(1-Premissas!$B$23),Amandina!$I$14*(1-Premissas!$B$23)) -> 84856.704 | W42: =IF(Premissas!$B$24="Sim",Amandina!$L$3*1000*(1-Premissas!$B$23),Amandina!$I$3*(1-Premissas!$B$23)) -> 90950.164 | X42: =IF(Premissas!$B$24="Sim",Amandina!$L$4*1000*(1-Premissas!$B$23),Amandina!$I$4*(1-Premissas!$B$23)) -> 72540.992 | Y42: =IF(Premissas!$B$24="Sim",Amandina!$L$5*1000*(1-Premissas!$B$23),Amandina!$I$5*(1-Premissas!$B$23)) -> 82037.272 | Z42: =IF(Premissas!$B$24="Sim",Amandina!$L$6*1000*(1-Premissas!$B$23),Amandina!$I$6*(1-Premissas!$B$23)) -> 58672.921 | AA42: =IF(Premissas!$B$24="Sim",Amandina!$L$7*1000*(1-Premissas!$B$23),Amandina!$I$7*(1-Premissas!$B$23)) -> 72926.814
...

Sheet Dados_Produção_Copasul

Sheet Amandina
A1: Unidade | B1: Data | C1: Geração (kWh) | D1: Yf Diário (kWh/kWp)
A2: Amandina | B2: 45716 | C2: 190.1 | D2: =IFERROR(C2/VLOOKUP(A2,Usinas!$A:$B,2,FALSE()),"") -> 0.27274032 | F2: Geração Mensal | H2: Mês | I2: Kwh | J2: MWh | L2: Proxi Bataypora | P2: proxy Rate | Q2: 0.8
A3: Amandina | B3: 45717 | C3: 249.5 | D3: =IFERROR(C3/VLOOKUP(A3,Usinas!$A:$B,2,FALSE()),"") -> 0.3579627 | F3: 45658 | G3: =+F3+30 -> 45688 | H3: =+F3 -> 45658 | I3: 0 | J3: 0 | L3: =+Batayporã!J3*Amandina!$Q$2 -> 91.4072
A4: Amandina | B4: 45718 | C4: 295.9 | D4: =IFERROR(C4/VLOOKUP(A4,Usinas!$A:$B,2,FALSE()),"") -> 0.42453372 | F4: =+B2 -> 45716 | G4: =+F4 -> 45716 | H4: =+F4 -> 45716 | I4: =SUMIFS($C$1:$C$366, $B$1:$B$366, ">="&F4, $B$1:$B$366, "<="&G4) -> 190.1 | J4: =+I4/1000 -> 0.1901 | L4: =+Batayporã!J4*Amandina!$Q$2 -> 72.90552
A5: Amandina | B5: 45719 | C5: 250.2 | D5: =IFERROR(C5/VLOOKUP(A5,Usinas!$A:$B,2,FALSE()),"") -> 0.358967 | F5: =+G4+1 -> 45717 | G5: =+F5+30 -> 45747 | H5: =+F5 -> 45717 | I5: =SUMIFS($C$1:$C$366, $B$1:$B$366, ">="&F5, $B$1:$B$366, "<="&G5) -> 7913.8 | J5: =+I5/1000 -> 7.9138 | L5: =+Batayporã!J5*Amandina!$Q$2 -> 82.44952
A6: Amandina | B6: 45720 | C6: 256.6 | D6: =IFERROR(C6/VLOOKUP(A6,Usinas!$A:$B,2,FALSE()),"") -> 0.36814921 | F6: =+G5+1 -> 45748 | G6: =+F6+29 -> 45777 | H6: =+F6 -> 45748 | I6: =SUMIFS($C$1:$C$366, $B$1:$B$366, ">="&F6, $B$1:$B$366, "<="&G6) -> 23902.8 | J6: =+I6/1000 -> 23.9028 | L6: =+Batayporã!J6*Amandina!$Q$2 -> 58.96776
A7: Amandina | B7: 45721 | C7: 241 | D7: =IFERROR(C7/VLOOKUP(A7,Usinas!$A:$B,2,FALSE()),"") -> 0.34576758 | F7: =+G6+1 -> 45778 | G7: =+F7+30 -> 45808 | H7: =+F7 -> 45778 | I7: =SUMIFS($C$1:$C$366, $B$1:$B$366, ">="&F7, $B$1:$B$366, "<="&G7) -> 28781.7 | J7: =+I7/1000 -> 28.7817 | L7: =+Batayporã!J7*Amandina!$Q$2 -> 73.29328
A8: Amandina | B8: 45722 | C8: 194.3 | D8: =IFERROR(C8/VLOOKUP(A8,Usinas!$A:$B,2,FALSE()),"") -> 0.27876614 | F8: =+G7+1 -> 45809 | G8: =+F8+29 -> 45838 | H8: =+F8 -> 45809 | I8: =SUMIFS($C$1:$C$366, $B$1:$B$366, ">="&F8, $B$1:$B$366, "<="&G8) -> 20798.2 | J8: =+I8/1000 -> 20.7982 | L8: =+Batayporã!J8*Amandina!$Q$2 -> 57.82952
A9: Amandina | B9: 45723 | C9: 89.9 | D9: =IFERROR(C9/VLOOKUP(A9,Usinas!$A:$B,2,FALSE()),"") -> 0.12898135 | F9: =+G8+1 -> 45839 | G9: =+F9+30 -> 45869 | H9: =+F9 -> 45839 | I9: =SUMIFS($C$1:$C$366, $B$1:$B$366, ">="&F9, $B$1:$B$366, "<="&G9) -> 37317.8 | J9: =+I9/1000 -> 37.3178 | L9: =+Batayporã!J9*Amandina!$Q$2 -> 70.66944
A10: Amandina | B10: 45724 | C10: 357.6 | D10: =IFERROR(C10/VLOOKUP(A10,Usinas!$A:$B,2,FALSE()),"") -> 0.51305595 | F10: =+G9+1 -> 45870 | G10: =+F10+30 -> 45900 | H10: =+F10 -> 45870 | I10: =SUMIFS($C$1:$C$366, $B$1:$B$366, ">="&F10, $B$1:$B$366, "<="&G10) -> 16177.9 | J10: =+I10/1000 -> 16.1779 | L10: =+Batayporã!J10*Amandina!$Q$2 -> 74.46616
A11: Amandina | B11: 45725 | C11: 287 | D11: =IFERROR(C11/VLOOKUP(A11,Usinas!$A:$B,2,FALSE()),"") -> 0.41176471 | F11: =+G10+1 -> 45901 | G11: =+F11+29 -> 45930 | H11: =+F11 -> 45901 | I11: =SUMIFS($C$1:$C$366, $B$1:$B$366, ">="&F11, $B$1:$B$366, "<="&G11) -> 37738.8 | J11: =+I11/1000 -> 37.7388 | L11: =+Batayporã!J11*Amandina!$Q$2 -> 75.54672
A12: Amandina | B12: 45726 | C12: 248.1 | D12: =IFERROR(C12/VLOOKUP(A12,Usinas!$A:$B,2,FALSE()),"") -> 0.35595409 | F12: =+G11+1 -> 45931 | G12: =+F12+30 -> 45961 | H12: =+F12 -> 45931 | I12: =SUMIFS($C$1:$C$366, $B$1:$B$366, ">="&F12, $B$1:$B$366, "<="&G12) -> 40322 | J12: =+I12/1000 -> 40.322 | L12: =+Batayporã!J12*Amandina!$Q$2 -> 76.72544
A13: Amandina | B13: 45727 | C13: 142.1 | D13: =IFERROR(C13/VLOOKUP(A13,Usinas!$A:$B,2,FALSE()),"") -> 0.20387374 | F13: =+G12+1 -> 45962 | G13: =+F13+29 -> 45991 | H13: =+F13 -> 45962 | I13: =SUMIFS($C$1:$C$366, $B$1:$B$366, ">="&F13, $B$1:$B$366, "<="&G13) -> 36462.9 | J13: =+I13/1000 -> 36.4629 | L13: =+Batayporã!J13*Amandina!$Q$2 -> 86.38448
A14: Amandina | B14: 45728 | C14: 224.8 | D14: =IFERROR(C14/VLOOKUP(A14,Usinas!$A:$B,2,FALSE()),"") -> 0.32252511 | F14: =+G13+1 -> 45992 | G14: =+F14+30 -> 46022 | H14: =+F14 -> 45992 | I14: =SUMIFS($C$1:$C$366, $B$1:$B$366, ">="&F14, $B$1:$B$366, "<="&G14) -> 19968.1 | J14: =+I14/1000 -> 19.9681 | L14: =+Batayporã!J14*Amandina!$Q$2 -> 85.28312
A15: Amandina | B15: 45729 | C15: 242.3 | D15: =IFERROR(C15/VLOOKUP(A15,Usinas!$A:$B,2,FALSE()),"") -> 0.34763271
A16: Amandina | B16: 45730 | C16: 288.4 | D16: =IFERROR(C16/VLOOKUP(A16,Usinas!$A:$B,2,FALSE()),"") -> 0.41377331
A17: Amandina | B17: 45731 | C17: 347.5 | D17: =IFERROR(C17/VLOOKUP(A17,Usinas!$A:$B,2,FALSE()),"") -> 0.49856528 | L17: =+SUM(L2:L14) -> 905.92816
A18: Amandina | B18: 45732 | C18: 310.4 | D18: =IFERROR(C18/VLOOKUP(A18,Usinas!$A:$B,2,FALSE()),"") -> 0.44533716
A19: Amandina | B19: 45733 | C19: 278 | D19: =IFERROR(C19/VLOOKUP(A19,Usinas!$A:$B,2,FALSE()),"") -> 0.39885222
A20: Amandina | B20: 45734 | C20: 222.1 | D20: =IFERROR(C20/VLOOKUP(A20,Usinas!$A:$B,2,FALSE()),"") -> 0.31865136
A21: Amandina | B21: 45735 | C21: 332.3 | D21: =IFERROR(C21/VLOOKUP(A21,Usinas!$A:$B,2,FALSE()),"") -> 0.47675753
A22: Amandina | B22: 45736 | C22: 318.3 | D22: =IFERROR(C22/VLOOKUP(A22,Usinas!$A:$B,2,FALSE()),"") -> 0.45667145
A23: Amandina | B23: 45737 | C23: 321.4 | D23: =IFERROR(C23/VLOOKUP(A23,Usinas!$A:$B,2,FALSE()),"") -> 0.46111908
A24: Amandina | B24: 45738 | C24: 272.8 | D24: =IFERROR(C24/VLOOKUP(A24,Usinas!$A:$B,2,FALSE()),"") -> 0.39139168
A25: Amandina | B25: 45739 | C25: 250.5 | D25: =IFERROR(C25/VLOOKUP(A25,Usinas!$A:$B,2,FALSE()),"") -> 0.35939742
A26: Amandina | B26: 45740 | C26: 281.2 | D26: =IFERROR(C26/VLOOKUP(A26,Usinas!$A:$B,2,FALSE()),"") -> 0.40344333
A27: Amandina | B27: 45741 | C27: 264.2 | D27: =IFERROR(C27/VLOOKUP(A27,Usinas!$A:$B,2,FALSE()),"") -> 0.37905308
A28: Amandina | B28: 45742 | C28: 275 | D28: =IFERROR(C28/VLOOKUP(A28,Usinas!$A:$B,2,FALSE()),"") -> 0.39454806
A29: Amandina | B29: 45743 | C29: 297 | D29: =IFERROR(C29/VLOOKUP(A29,Usinas!$A:$B,2,FALSE()),"") -> 0.42611191
... A356: Amandina | B356: 46022 | C356: 990.9 | D356: =IFERROR(C356/VLOOKUP(A356,Usinas!$A:$B,2,FALSE()),"") -> 1.4216643

Sheet Batayporã
A1: Unidade | B1: Data | C1: Geração (kWh) | D1: Yf Diário (kWh/kWp)
A2: Batayporã | B2: 45658 | C2: 3715.4 | D2: =IFERROR(C2/VLOOKUP(A2,Usinas!$A:$B,2,FALSE()),"") -> 5.2925926 | F2: Geração Mensal | H2: Mês | I2: Kwh | J2: MWh
A3: Batayporã | B3: 45659 | C3: 2498.6 | D3: =IFERROR(C3/VLOOKUP(A3,Usinas!$A:$B,2,FALSE()),"") -> 3.5592593 | F3: =+B2 -> 45658 | G3: =+B32 -> 45688 | H3: =+F3 -> 45658 | I3: =SUMIFS($C$1:$C$366, $B$1:$B$366, ">="&F3, $B$1:$B$366, "<="&G3) -> 114259 | J3: =+I3/1000 -> 114.259
A4: Batayporã | B4: 45660 | C4: 4061.9 | D4: =IFERROR(C4/VLOOKUP(A4,Usinas!$A:$B,2,FALSE()),"") -> 5.7861823 | F4: =+B33 -> 45689 | G4: =+F4+27 -> 45716 | H4: =+F4 -> 45689 | I4: =SUMIFS($C$1:$C$366, $B$1:$B$366, ">="&F4, $B$1:$B$366, "<="&G4) -> 91131.9 | J4: =+I4/1000 -> 91.1319
A5: Batayporã | B5: 45661 | C5: 3262.5 | D5: =IFERROR(C5/VLOOKUP(A5,Usinas!$A:$B,2,FALSE()),"") -> 4.6474359 | F5: =+G4+1 -> 45717 | G5: =+F5+30 -> 45747 | H5: =+F5 -> 45717 | I5: =SUMIFS($C$1:$C$366, $B$1:$B$366, ">="&F5, $B$1:$B$366, "<="&G5) -> 103061.9 | J5: =+I5/1000 -> 103.0619
A6: Batayporã | B6: 45662 | C6: 4061 | D6: =IFERROR(C6/VLOOKUP(A6,Usinas!$A:$B,2,FALSE()),"") -> 5.7849003 | F6: =+G5+1 -> 45748 | G6: =+F6+29 -> 45777 | H6: =+F6 -> 45748 | I6: =SUMIFS($C$1:$C$366, $B$1:$B$366, ">="&F6, $B$1:$B$366, "<="&G6) -> 73709.7 | J6: =+I6/1000 -> 73.7097
A7: Batayporã | B7: 45663 | C7: 4431.9 | D7: =IFERROR(C7/VLOOKUP(A7,Usinas!$A:$B,2,FALSE()),"") -> 6.3132479 | F7: =+G6+1 -> 45778 | G7: =+F7+30 -> 45808 | H7: =+F7 -> 45778 | I7: =SUMIFS($C$1:$C$366, $B$1:$B$366, ">="&F7, $B$1:$B$366, "<="&G7) -> 91616.6 | J7: =+I7/1000 -> 91.6166
A8: Batayporã | B8: 45664 | C8: 4460 | D8: =IFERROR(C8/VLOOKUP(A8,Usinas!$A:$B,2,FALSE()),"") -> 6.3532764 | F8: =+G7+1 -> 45809 | G8: =+F8+29 -> 45838 | H8: =+F8 -> 45809 | I8: =SUMIFS($C$1:$C$366, $B$1:$B$366, ">="&F8, $B$1:$B$366, "<="&G8) -> 72286.9 | J8: =+I8/1000 -> 72.2869
A9: Batayporã | B9: 45665 | C9: 3524.3 | D9: =IFERROR(C9/VLOOKUP(A9,Usinas!$A:$B,2,FALSE()),"") -> 5.0203704 | F9: =+G8+1 -> 45839 | G9: =+F9+30 -> 45869 | H9: =+F9 -> 45839 | I9: =SUMIFS($C$1:$C$366, $B$1:$B$366, ">="&F9, $B$1:$B$366, "<="&G9) -> 88336.8 | J9: =+I9/1000 -> 88.3368
A10: Batayporã | B10: 45666 | C10: 4744.5 | D10: =IFERROR(C10/VLOOKUP(A10,Usinas!$A:$B,2,FALSE()),"") -> 6.758547 | F10: =+G9+1 -> 45870 | G10: =+F10+30 -> 45900 | H10: =+F10 -> 45870 | I10: =SUMIFS($C$1:$C$366, $B$1:$B$366, ">="&F10, $B$1:$B$366, "<="&G10) -> 93082.7 | J10: =+I10/1000 -> 93.0827
A11: Batayporã | B11: 45667 | C11: 3305 | D11: =IFERROR(C11/VLOOKUP(A11,Usinas!$A:$B,2,FALSE()),"") -> 4.7079772 | F11: =+G10+1 -> 45901 | G11: =+F11+29 -> 45930 | H11: =+F11 -> 45901 | I11: =SUMIFS($C$1:$C$366, $B$1:$B$366, ">="&F11, $B$1:$B$366, "<="&G11) -> 94433.4 | J11: =+I11/1000 -> 94.4334
A12: Batayporã | B12: 45668 | C12: 4671.1 | D12: =IFERROR(C12/VLOOKUP(A12,Usinas!$A:$B,2,FALSE()),"") -> 6.6539886 | F12: =+G11+1 -> 45931 | G12: =+F12+30 -> 45961 | H12: =+F12 -> 45931 | I12: =SUMIFS($C$1:$C$366, $B$1:$B$366, ">="&F12, $B$1:$B$366, "<="&G12) -> 95906.8 | J12: =+I12/1000 -> 95.9068
A13: Batayporã | B13: 45669 | C13: 4211.9 | D13: =IFERROR(C13/VLOOKUP(A13,Usinas!$A:$B,2,FALSE()),"") -> 5.9998575 | F13: =+G12+1 -> 45962 | G13: =+F13+29 -> 45991 | H13: =+F13 -> 45962 | I13: =SUMIFS($C$1:$C$366, $B$1:$B$366, ">="&F13, $B$1:$B$366, "<="&G13) -> 107980.6 | J13: =+I13/1000 -> 107.9806
A14: Batayporã | B14: 45670 | C14: 4327.1 | D14: =IFERROR(C14/VLOOKUP(A14,Usinas!$A:$B,2,FALSE()),"") -> 6.1639601 | F14: =+G13+1 -> 45992 | G14: =+F14+30 -> 46022 | H14: =+F14 -> 45992 | I14: =SUMIFS($C$1:$C$366, $B$1:$B$366, ">="&F14, $B$1:$B$366, "<="&G14) -> 106603.9 | J14: =+I14/1000 -> 106.6039
A15: Batayporã | B15: 45671 | C15: 4370 | D15: =IFERROR(C15/VLOOKUP(A15,Usinas!$A:$B,2,FALSE()),"") -> 6.2250712
A16: Batayporã | B16: 45672 | C16: 4324 | D16: =IFERROR(C16/VLOOKUP(A16,Usinas!$A:$B,2,FALSE()),"") -> 6.1595442
A17: Batayporã | B17: 45673 | C17: 4173.6 | D17: =IFERROR(C17/VLOOKUP(A17,Usinas!$A:$B,2,FALSE()),"") -> 5.9452991
A18: Batayporã | B18: 45674 | C18: 2490.4 | D18: =IFERROR(C18/VLOOKUP(A18,Usinas!$A:$B,2,FALSE()),"") -> 3.5475783
A19: Batayporã | B19: 45675 | C19: 2419.1 | D19: =IFERROR(C19/VLOOKUP(A19,Usinas!$A:$B,2,FALSE()),"") -> 3.4460114
A20: Batayporã | B20: 45676 | C20: 3206.2 | D20: =IFERROR(C20/VLOOKUP(A20,Usinas!$A:$B,2,FALSE()),"") -> 4.5672365
A21: Batayporã | B21: 45677 | C21: 2768 | D21: =IFERROR(C21/VLOOKUP(A21,Usinas!$A:$B,2,FALSE()),"") -> 3.9430199
A22: Batayporã | B22: 45678 | C22: 3998.4 | D22: =IFERROR(C22/VLOOKUP(A22,Usinas!$A:$B,2,FALSE()),"") -> 5.6957265
A23: Batayporã | B23: 45679 | C23: 2927.9 | D23: =IFERROR(C23/VLOOKUP(A23,Usinas!$A:$B,2,FALSE()),"") -> 4.1707977
A24: Batayporã | B24: 45680 | C24: 3035.9 | D24: =IFERROR(C24/VLOOKUP(A24,Usinas!$A:$B,2,FALSE()),"") -> 4.3246439
A25: Batayporã | B25: 45681 | C25: 4013.7 | D25: =IFERROR(C25/VLOOKUP(A25,Usinas!$A:$B,2,FALSE()),"") -> 5.7175214
A26: Batayporã | B26: 45682 | C26: 3852.9 | D26: =IFERROR(C26/VLOOKUP(A26,Usinas!$A:$B,2,FALSE()),"") -> 5.4884615
... A366: Batayporã | B366: 46022 | C366: 3694.2 | D366: =IFERROR(C366/VLOOKUP(A366,Usinas!$A:$B,2,FALSE()),"") -> 5.2623932

Sheet Novo Horizonte do Sul
A1: Unidade | B1: Data | C1: Geração (kWh) | D1: Yf Diário (kWh/kWp)
A2: Novo Horizonte do Sul | B2: 45659 | C2: 1838.7 | D2: =IFERROR(C2/VLOOKUP(A2,Usinas!$A:$B,2,FALSE()),"") -> 2.9608696 | F2: Geração Mensal | H2: Mês | I2: Kwh | J2: MWh
A3: Novo Horizonte do Sul | B3: 45660 | C3: 2731.7 | D3: =IFERROR(C3/VLOOKUP(A3,Usinas!$A:$B,2,FALSE()),"") -> 4.3988728 | F3: =+B2 -> 45659 | G3: =+F3+29 -> 45688 | H3: =+F3 -> 45659 | I3: =SUMIFS($C$1:$C$366, $B$1:$B$366, ">="&F3, $B$1:$B$366, "<="&G3) -> 83461.9 | J3: =+I3/1000 -> 83.4619
A4: Novo Horizonte do Sul | B4: 45661 | C4: 3144 | D4: =IFERROR(C4/VLOOKUP(A4,Usinas!$A:$B,2,FALSE()),"") -> 5.0628019 | F4: =+G3+1 -> 45689 | G4: =+F4+27 -> 45716 | H4: =+F4 -> 45689 | I4: =SUMIFS($C$1:$C$366, $B$1:$B$366, ">="&F4, $B$1:$B$366, "<="&G4) -> 76124.4 | J4: =+I4/1000 -> 76.1244
A5: Novo Horizonte do Sul | B5: 45662 | C5: 3472.1 | D5: =IFERROR(C5/VLOOKUP(A5,Usinas!$A:$B,2,FALSE()),"") -> 5.5911433 | F5: =+G4+1 -> 45717 | G5: =+F5+30 -> 45747 | H5: =+F5 -> 45717 | I5: =SUMIFS($C$1:$C$366, $B$1:$B$366, ">="&F5, $B$1:$B$366, "<="&G5) -> 89858.2 | J5: =+I5/1000 -> 89.8582
A6: Novo Horizonte do Sul | B6: 45663 | C6: 3397.4 | D6: =IFERROR(C6/VLOOKUP(A6,Usinas!$A:$B,2,FALSE()),"") -> 5.4708535 | F6: =+G5+1 -> 45748 | G6: =+F6+29 -> 45777 | H6: =+F6 -> 45748 | I6: =SUMIFS($C$1:$C$366, $B$1:$B$366, ">="&F6, $B$1:$B$366, "<="&G6) -> 62725.4 | J6: =+I6/1000 -> 62.7254
A7: Novo Horizonte do Sul | B7: 45664 | C7: 3375.8 | D7: =IFERROR(C7/VLOOKUP(A7,Usinas!$A:$B,2,FALSE()),"") -> 5.4360709 | F7: =+G6+1 -> 45778 | G7: =+F7+30 -> 45808 | H7: =+F7 -> 45778 | I7: =SUMIFS($C$1:$C$366, $B$1:$B$366, ">="&F7, $B$1:$B$366, "<="&G7) -> 78227.5 | J7: =+I7/1000 -> 78.2275
A8: Novo Horizonte do Sul | B8: 45665 | C8: 3146.5 | D8: =IFERROR(C8/VLOOKUP(A8,Usinas!$A:$B,2,FALSE()),"") -> 5.0668277 | F8: =+G7+1 -> 45809 | G8: =+F8+29 -> 45838 | H8: =+F8 -> 45809 | I8: =SUMIFS($C$1:$C$366, $B$1:$B$366, ">="&F8, $B$1:$B$366, "<="&G8) -> 60380.6 | J8: =+I8/1000 -> 60.3806
A9: Novo Horizonte do Sul | B9: 45666 | C9: 3235.6 | D9: =IFERROR(C9/VLOOKUP(A9,Usinas!$A:$B,2,FALSE()),"") -> 5.210306 | F9: =+G8+1 -> 45839 | G9: =+F9+30 -> 45869 | H9: =+F9 -> 45839 | I9: =SUMIFS($C$1:$C$366, $B$1:$B$366, ">="&F9, $B$1:$B$366, "<="&G9) -> 76551.2 | J9: =+I9/1000 -> 76.5512
A10: Novo Horizonte do Sul | B10: 45667 | C10: 2990.9 | D10: =IFERROR(C10/VLOOKUP(A10,Usinas!$A:$B,2,FALSE()),"") -> 4.8162641 | F10: =+G9+1 -> 45870 | G10: =+F10+30 -> 45900 | H10: =+F10 -> 45870 | I10: =SUMIFS($C$1:$C$366, $B$1:$B$366, ">="&F10, $B$1:$B$366, "<="&G10) -> 79815.6 | J10: =+I10/1000 -> 79.8156
