Workbook

Sheet Resumo
B1: SIMULAÇÃO RATEIO FIXO — Cassilândia 03 × COPASUL | Resumo Executivo
B2: 18 Unidades Consumidoras · Jun/2026–Mai/2036 · Energisa MS · Usina: Cassilândia 03 · 120 meses
B4: ⚡ GERAÇÃO INJETADA | D4: 📄 PPA PAGO À HELEXIA | F4: ✅ ECONOMIA LÍQUIDA | H4: 🏦 BANCO RESIDUAL | J4: 🌟 VALOR TOTAL
B5: =Simulacao!B6 -> 9214611.7 | D5: =Simulacao!B7 -> 7326414.9 | F5: =Simulacao!B252 -> 3109848.7 | H5: =Simulacao!B273*Premissas!B17 -> 484986.05 | J5: =Simulacao!B278 -> 3579197.5
B6: 16556.870 MWh injetados em 120 meses | D6: Custo total do contrato PPA | F6: Rede evitada menos PPA pago | H6: Banco total Copasul @ PPA | J6: Economia + banco ATRIBUÍVEL a Helexia
B8: A. CUSTO COPASUL — ANÁLISE 120 MESES | I8: B. INDICADORES-CHAVE
B9: COMPONENTE | E9: R$ | F9: % | G9: R$/mês | I9: Usina contratada | K9: =Premissas!$B$13 -> Cassilândia 03
B10: Custo SEM Helexia — baseline 60m | E10: 13004941 | F10: 1 | G10: 108375 | I10: Período do contrato | K10: Jun/2026 – Mai/2036 (120 meses)
B11: Custo rede remanescente (COM Helexia) | E11: 1922842 | F11: 0.14785476 | G11: 16024 | I11: Potência contratada | K11: =VLOOKUP(Premissas!$B$13,PVSYST_Helexia!$B$5:$F$7,5,0)&" kWac" -> 625 kWac
B12: PPA pago à Helexia | E12: =Simulacao!B7 -> 7326414.9 | F12: 0.56335624 | G12: 61053 | I12: Geração P50 total | K12: 16556.87
B13: Custo total COM Helexia (rede + PPA) | E13: 9249257 | F13: 0.711211 | G13: 77077 | I13: PPA (R$/kWh) | K13: =Premissas!$B$17 -> 0.4425
B14: ★ ECONOMIA LÍQUIDA (rede − PPA) | E14: =Simulacao!B252 -> 3109848.7 | F14: 0.288789 | G14: 31297 | I14: Tarifa Grupo A FP | K14: =Premissas!$B$5 -> 0.52647111
B15: + Banco atribuível Helexia @ PPA (net NHS/AMD + Grupo B) | E15: =Simulacao!B285 -> 469348.85 | F15: 0.08868991 | G15: 9612 | I15: Tarifa Grupo B3 | K15: =Premissas!$B$7 -> 1.1568636
B16: ★ VALOR TOTAL HELEXIA (economia + banco atribuível) | E16: =Simulacao!B278 -> 3579197.5 | F16: 0.37747891 | G16: 40909 | I16: Economia média/mês | K16: =Simulacao!B252/60 -> 51830.811
I17: % redução custo Copasul | K17: =IFERROR(Simulacao!B252/Simulacao!B249,0) -> 0.40926307
I18: Banco residual (kWh) | K18: =Simulacao!B273 -> 1096013.7
B20: C. ANÁLISE VISUAL — ECONOMIA E BANCO DE CRÉDITOS
P22: Mês | Q22: SEM Helexia | R22: PPA | S22: Rede COM | T22: Eco mensal | U22: Eco acumulada | Y22: Eco acumulada
P23: Jun/26 | Q23: =Simulacao!D249 -> 29914.643 | R23: =Simulacao!D7 -> 54865.575 | S23: =Simulacao!D250 -> 2939.9665 | T23: =Simulacao!D252 -> -27890.899 | U23: =T23 -> -27890.899 | X23: Jun/26 | Y23: -27890.991
P24: Jul/26 | Q24: =Simulacao!E249 -> 231391.59 | R24: =Simulacao!E7 -> 57750.675 | S24: =Simulacao!E250 -> 82568.433 | T24: =Simulacao!E252 -> 91072.486 | U24: =U23+T24 -> 63181.588 | X24: Jul/26 | Y24: 63180.705
P25: Ago/26 | Q25: =Simulacao!F249 -> 156548.85 | R25: =Simulacao!F7 -> 69326.475 | S25: =Simulacao!F250 -> 1104.9864 | T25: =Simulacao!F252 -> 86117.386 | U25: =U24+T25 -> 149298.97 | X25: Ago/26 | Y25: 149296.8
P26: Set/26 | Q26: =Simulacao!G249 -> 42616.08 | R26: =Simulacao!G7 -> 65051.925 | S26: =Simulacao!G250 -> 2690.9343 | T26: =Simulacao!G252 -> -25126.779 | U26: =U25+T26 -> 124172.2 | X26: Set/26 | Y26: 124170.02
P27: Out/26 | Q27: =Simulacao!H249 -> 43352.771 | R27: =Simulacao!H7 -> 66852.9 | S27: =Simulacao!H250 -> 0 | T27: =Simulacao!H252 -> -23500.129 | U27: =U26+T27 -> 100672.07 | X27: Out/26 | Y27: 100669.9
P28: Nov/26 | Q28: =Simulacao!I249 -> 43210.246 | R28: =Simulacao!I7 -> 64640.4 | S28: =Simulacao!I250 -> 0 | T28: =Simulacao!I252 -> -21430.154 | U28: =U27+T28 -> 79241.912 | X28: Nov/26 | Y28: 79239.741
P29: Dez/26 | Q29: =Simulacao!J249 -> 44658.639 | R29: =Simulacao!J7 -> 61379.175 | S29: =Simulacao!J250 -> 0 | T29: =Simulacao!J252 -> -16720.536 | U29: =U28+T29 -> 62521.376 | X29: Dez/26 | Y29: 62519.298
P30: Jan/27 | Q30: =Simulacao!K249 -> 42485.586 | R30: =Simulacao!K7 -> 63022.753 | S30: =Simulacao!K250 -> 0 | T30: =Simulacao!K252 -> -20537.167 | U30: =U29+T30 -> 41984.209 | X30: Jan/27 | Y30: 41981.143
P31: Fev/27 | Q31: =Simulacao!L249 -> 45032.537 | R31: =Simulacao!L7 -> 56158.671 | S31: =Simulacao!L250 -> 0 | T31: =Simulacao!L252 -> -11126.133 | U31: =U30+T31 -> 30858.076 | X31: Fev/27 | Y31: 30854.517
P32: Mar/27 | Q32: =Simulacao!M249 -> 208537.26 | R32: =Simulacao!M7 -> 64414.061 | S32: =Simulacao!M250 -> 0 | T32: =Simulacao!M252 -> 144123.2 | U32: =U31+T32 -> 174981.27 | X32: Mar/27 | Y32: 174977.08
P33: Abr/27 | Q33: =Simulacao!N249 -> 35167.729 | R33: =Simulacao!N7 -> 64273.169 | S33: =Simulacao!N250 -> 0 | T33: =Simulacao!N252 -> -29105.44 | U33: =U32+T33 -> 145875.83 | X33: Abr/27 | Y33: 145871.45
P34: Mai/27 | Q34: =Simulacao!O249 -> 32721.657 | R34: =Simulacao!O7 -> 60152.078 | S34: =Simulacao!O250 -> 0 | T34: =Simulacao!O252 -> -27430.421 | U34: =U33+T34 -> 118445.41 | X34: Mai/27 | Y34: 118440.59
P35: Jun/27 | Q35: =Simulacao!P249 -> 70854.002 | R35: =Simulacao!P7 -> 54591.247 | S35: =Simulacao!P250 -> 0 | T35: =Simulacao!P252 -> 16262.755 | U35: =U34+T35 -> 134708.17 | X35: Jun/27 | Y35: 134702.87
P36: Jul/27 | Q36: =Simulacao!Q249 -> 281668.23 | R36: =Simulacao!Q7 -> 57461.922 | S36: =Simulacao!Q250 -> 0 | T36: =Simulacao!Q252 -> 224206.31 | U36: =U35+T36 -> 358914.47 | X36: Jul/27 | Y36: 358912.03
P37: Ago/27 | Q37: =Simulacao!R249 -> 161720.42 | R37: =Simulacao!R7 -> 68979.843 | S37: =Simulacao!R250 -> 0 | T37: =Simulacao!R252 -> 92740.58 | U37: =U36+T37 -> 451655.05 | X37: Ago/27 | Y37: 451654.05
P38: Set/27 | Q38: =Simulacao!S249 -> 43683.171 | R38: =Simulacao!S7 -> 64726.665 | S38: =Simulacao!S250 -> 0 | T38: =Simulacao!S252 -> -21043.494 | U38: =U37+T38 -> 430611.56 | X38: Set/27 | Y38: 430608.87
P39: Out/27 | Q39: =Simulacao!T249 -> 44437.446 | R39: =Simulacao!T7 -> 66518.636 | S39: =Simulacao!T250 -> 0 | T39: =Simulacao!T252 -> -22081.189 | U39: =U38+T39 -> 408530.37 | X39: Out/27 | Y39: 408526.82
P40: Nov/27 | Q40: =Simulacao!U249 -> 44288.442 | R40: =Simulacao!U7 -> 64317.198 | S40: =Simulacao!U250 -> 0 | T40: =Simulacao!U252 -> -20028.756 | U40: =U39+T40 -> 388501.61 | X40: Nov/27 | Y40: 388500.13
P41: Dez/27 | Q41: =Simulacao!V249 -> 45776.632 | R41: =Simulacao!V7 -> 61072.279 | S41: =Simulacao!V250 -> 0 | T41: =Simulacao!V252 -> -15295.647 | U41: =U40+T41 -> 373205.97 | X41: Dez/27 | Y41: 373203.05
P42: Jan/28 | Q42: =Simulacao!W249 -> 42485.586 | R42: =Simulacao!W7 -> 63022.753 | S42: =Simulacao!W250 -> 0 | T42: =Simulacao!W252 -> -20537.167 | U42: =U41+T42 -> 352668.8 | X42: Jan/28 | Y42: 352664.89
P43: Fev/28 | Q43: =Simulacao!X249 -> 45032.537 | R43: =Simulacao!X7 -> 56158.671 | S43: =Simulacao!X250 -> 0 | T43: =Simulacao!X252 -> -11126.133 | U43: =U42+T43 -> 341542.67 | X43: Fev/28 | Y43: 341538.27
P44: Mar/28 | Q44: =Simulacao!Y249 -> 212454.37 | R44: =Simulacao!Y7 -> 64414.061 | S44: =Simulacao!Y250 -> 0 | T44: =Simulacao!Y252 -> 148040.31 | U44: =U43+T44 -> 489582.97 | X44: Mar/28 | Y44: 489578.58
...

Sheet Premissas
A1: ="PREMISSAS — "&Premissas!$B$13&" × Copasul | Energisa MS" -> PREMISSAS — Cassilândia 03 × Copasul | Energisa MS | M1: 🎯 OTIMIZAÇÃO RATEIO — SOLVER CONFIG
A2: Azul = inputs editáveis | Preto = fórmulas | Verde = links entre abas | M2: Siga o passo a passo abaixo para maximizar Economia Líquida via Excel Solver
A4: A. TARIFAS ENERGISA MS (com tributos ICMS 17% + PIS/COFINS) | M4: ① CÉLULA OBJETIVO (aponte o Solver aqui): | P4: ENDEREÇO | Q4: VALOR ATUAL | R4: OBJETIVO
A5: Tarifa Grupo A FP com tributos (R$/kWh) | B5: 0.52647111 | C5: ← T_AFP: edit here | M5: Economia Líquida Copasul 24m (R$) | P5: Premissas!K5 | Q5: =Simulacao!B252 -> 3109848.7 | R5: ↑ MAXIMIZAR
A6: Tarifa Grupo A Ponta com tributos (R$/kWh) | B6: 2.9723794 | C6: ← T_APT: edit here | M6: ② ATIVAR SOLVER (se ainda não estiver ativo) | O6: Arquivo → Opções → Suplementos → Gerenciar: Suplementos do Excel → Ir... → ✓ Solver Add-in → OK
A7: Tarifa Grupo B3 com tributos (R$/kWh) | B7: 1.1568636 | C7: ← T_B3: edit here | M7: ③ ABRIR SOLVER | O7: Guia Dados → botão "Solver" (canto direito da faixa de opções)
A8: FA = TE_FP / TE_Ponta | B8: 0.60426705 | C8: ← FA: edit here | M8: ④ CONFIGURAR OBJETIVO | O8: Definir Objetivo: selecione a célula Premissas!K5 → marque ● Máx
A9: ICMS (%) | B9: 0.17 | C9: ← ICMS: edit here | M9: ⑤ DEFINIR CÉLULAS VARIÁVEIS | O9: Alterando Células de Variáveis: Premissas!$B$33:$K$50 (170 variáveis = 17 UCs × 10 períodos)
A10: PIS + COFINS (%) | B10: 0.0855 | C10: ← PIS_COFINS: edit here | M10: ⑥ ADICIONAR AS RESTRIÇÕES (Adicionar → preencher cada linha → OK)
A11: ICMS isenção autoconsumo remoto ativa? (Art. 23-A RICMS/MS) → 'Sim' = isento | 'Não' = ICMS cobrado sobre kWh compensados pelo CS3 | B11: Sim | C11: =IF($B$11="Sim",0,$B$5*$B$9/(1+$B$9)) -> 0 | D11: =IF($B$11="Sim",0,$B$6*$B$9/(1+$B$9)) -> 0 | E11: =IF($B$11="Sim",0,$B$7*$B$9/(1+$B$9)) -> 0 | F11: ← B=toggle (Sim/Não) | C=ICMS A_FP D=ICMS A_Ponta E=ICMS Grupo B (R$/kWh) — tudo 0 se Sim | M11: Célula / Intervalo | O11: Relação | P11: Valor / Restrição | Q11: Descrição
A12: B. CONDIÇÕES DO CONTRATO | M12: Premissas!$B$33:$K$50 | O12: >= | P12: 0 | Q12: Todos os rateios ≥ 0% (sem valores negativos, P1–P10)
A13: Usina | B13: Cassilândia 03 | M13: Premissas!$B$51 | O13: = | P13: 1 | Q13: Soma P1 = 100% (Jun–Set/26)
A14: Distribuidora | B14: Energisa MS | M14: Premissas!$C$51 | O14: = | P14: 1 | Q14: Soma P2 = 100% (Out/26–Mar/27)
A15: Início do contrato | B15: Jun/2026 | M15: Premissas!$D$51 | O15: = | P15: 1 | R15: Soma P3 = 100% (Abr–Set/27)
A16: Prazo (meses) | B16: 120 | M16: Premissas!$E$51 | O16: = | P16: 1 | Q16: Soma P4 = 100% (Out/27–Mai/28)
A17: PPA Helexia CS3 (R$/kWh) | B17: 0.4425 | M17: Premissas!$F$51 | O17: = | P17: 1 | Q17: Soma P5 = 100% (Jun–Nov/28)
A18: H. CENÁRIO CONCORRENTE — ENERGIA ASSINATURA GRUPO B (ex: Plin Energia) | M18: Premissas!$G$51 | O18: = | P18: 1 | Q18: Soma P6 = 100% (Dez/28–Mai/29)
A19: Grupo B tem contrato Assinatura GD concorrente? | B19: Sim | C19: Desconto (%): | D19: 0.2 | E19: Tarifa B3 SEM efetiva: | F19: =IF(B19="Sim",B7*(1-D19),B7) -> 0.92549092 | M19: Premissas!$H$51 | O19: = | P19: 1 | Q19: Soma P7 = 100% (Jun–Nov/29)
A20: C. PREMISSAS DE CRESCIMENTO E DEGRADAÇÃO | M20: Premissas!$I$51 | O20: = | P20: 1 | Q20: Soma P8 = 100% (Dez/29–Mai/30)
A21: Crescimento consumo Y2 vs Y1 (%) | B21: 0.025 | C21: ← 2.5% editável | aplica a TODOS os UCs | M21: Premissas!$J$51 | O21: = | P21: 1 | Q21: Soma P9 = 100% (Jun–Nov/30)
A22: Crescimento consumo Y3 parcial (Dez/27-Mai/28) (%) | B22: 0.025 | C22: ← mesmo % que Y2 por padrão | M22: Premissas!$K$51 | O22: = | P22: 1 | Q22: Soma P10 = 100% (Dez/30–Mai/31)
A23: Degradação geração Y2 (%) | B23: 0.005 | C23: ← 0.5%/ano editável | M23: Premissas!$B$34:$K$34 | O23: = | P23: 0 | Q23: BAT (linha 34) = 0% em todos os períodos (P1–P10)
A24: Usar proxy Batayporã p/ Amandina gen? | B24: Sim | M24: Premissas!$B$33:$E$50 | O24: <= | P24: 1 | Q24: Todos os rateios ≤ 100% (limite superior)
A25: D. BANCOS DE CRÉDITOS — SALDO INICIAL (Mai/2026, FPt GD I) | M25: ⑦ MÉTODO DE RESOLUÇÃO E OPÇÕES
A26: NHS — Silos Novo Horizonte do Sul (kWh) | B26: 148516 | M26: Método de Resolução: | O26: GRG Não-Linear | P26: O modelo tem funções IF (não-lineares). GRG é o método correto.
A27: BAT — Silos Batayporã (kWh) [stranded — não transferível CS3] | B27: 906739 | M27: Opções → Precisão: | O27: 0,000001 | P27: Maior precisão = resultado mais fino.
A28: AMD — Silos Amandina (kWh) | B28: 991029
A29: TOTAL NHS+AMD (kWh) | B29: =B26+B28 -> 1139545 | C29: ← BAT stranded bank não incluído no total
A31: ="E. RATEIO FIXO "&INDEX(PVSYST_Helexia!$A$5:$A$7,MATCH(Premissas!$B$13,PVSYST_Helexia!$B$5:$B$7,0))&" — 4 PERÍODOS (edit percentuais — devem somar 100% por período)" -> E. RATEIO FIXO HCS03 — 4 PERÍODOS (edit percentuais — devem somar 100% por período) | F31: Anos 3–10 (estado estacionário)
A32: UC / Planta | B32: P1: Jun–Set/26 | C32: P2: Out/26–Mar/27 | D32: P3: Abr/27–Set/27 | E32: P4: Out/27–Mai/28 | F32: P5: Jun–Nov/28 | G32: P6: Dez/28–Mai/29 | H32: P7: Jun–Nov/29 | I32: P8: Dez/29–Mai/30 | J32: P9: Jun–Nov/30 | K32: P10: Dez/30–Mai/31 | L32: P11: Jun–Nov/31 | M32: P12: Dez/31–Mai/32 | N32: P13: Jun–Nov/32 | O32: P14: Dez/32–Mai/33 | P32: P15: Jun–Nov/33 | Q32: P16: Dez/33–Mai/34 | R32: P17: Jun–Nov/34 | S32: P18: Dez/34–Mai/35 | T32: P19: Jun–Nov/35 | U32: P20: Dez/35–Mai/36
A33: NHS — Silos N. Horizonte (A4V) | B33: 0.738 | C33: 0.5178 | D33: 0.6714 | E33: 0.2592 | F33: 0.4741 | G33: 0.4673 | H33: 0.4724 | I33: 0.4656 | J33: 0.5826 | K33: 0.4621 | L33: 0.06904028 | M33: 0.07085343 | N33: 0.06949093 | O33: 0.07130672 | P33: 0.06994228 | Q33: 0.07176061 | R33: 0.07039425 | S33: 0.33 | T33: 0.33 | U33: 0.33
A34: BAT — Silos Batayporã (A4V) | B34: 0 | C34: 0 | D34: 0 | E34: 0 | F34: 0 | G34: 0 | H34: 0 | I34: 0 | J34: 0 | K34: 0 | L34: 0 | M34: 0 | N34: 0 | O34: 0 | P34: 0 | Q34: 0 | R34: 0 | S34: 0.33 | T34: 0.33 | U34: 0.33
A35: AMD — Silos Amandina (A3A) | B35: 0 | C35: 0 | D35: 0.0041 | E35: 0.1561 | F35: 0.3735 | G35: 0.3698 | H35: 0.3726 | I35: 0.3688 | J35: 0.2324 | K35: 0.2925 | L35: 0.34288312 | M35: 0.34120903 | N35: 0.34246707 | O35: 0.3407905 | P35: 0.34205034 | Q35: 0.34037116 | R35: 0.34163316 | S35: 0.33953066 | T35: 0.33953066 | U35: 0.33953066
A36: AREC (B3) | B36: 0.027 | C36: 0.0532 | D36: 0.0311 | E36: 0.0674 | F36: 0.0156 | G36: 0.0171 | H36: 0.016 | I36: 0.0174 | J36: 0.0304 | K36: 0.0322 | L36: 0.04656421 | M36: 0.04669989 | N36: 0.04659958 | O36: 0.04673106 | P36: 0.04663391 | Q36: 0.04676128 | R36: 0.04666718 | S36: 0 | T36: 0 | U36: 0
A37: Banheiro Motoristas (B3) | B37: 0.0033 | C37: 0.005 | D37: 0.004 | E37: 0.0045 | F37: 0.0026 | G37: 0.0027 | H37: 0.0026 | I37: 0.0027 | J37: 0.0027 | K37: 0.0034 | L37: 0.027707 | M37: 0.02794292 | N37: 0.02776621 | O37: 0.02800095 | P37: 0.02782513 | Q37: 0.02805869 | R37: 0.02788375 | S37: 0 | T37: 0 | U37: 0
A38: CTC Copasul (B3) | B38: 0.0031 | C38: 0.0077 | D38: 0.0039 | E38: 0.0072 | F38: 0.0032 | G38: 0.0034 | H38: 0.0032 | I38: 0.0034 | J38: 0.0037 | K38: 0.0043 | L38: 0.027707 | M38: 0.02794292 | N38: 0.02776621 | O38: 0.02800095 | P38: 0.02782513 | Q38: 0.02805869 | R38: 0.02788375 | S38: 0 | T38: 0 | U38: 0
A39: Depósito Irrigação (B3) | B39: 0.0064 | C39: 0.0114 | D39: 0.0081 | E39: 0.0095 | F39: 0.007 | G39: 0.0075 | H39: 0.0071 | I39: 0.0076 | J39: 0.0098 | K39: 0.0044 | L39: 0.027707 | M39: 0.02794292 | N39: 0.02776621 | O39: 0.02800095 | P39: 0.02782513 | Q39: 0.02805869 | R39: 0.02788375 | S39: 0 | T39: 0 | U39: 0
A40: Entreposto (B3) | B40: 0.059 | C40: 0.1067 | D40: 0.0727 | E40: 0.2104 | F40: 0.006 | G40: 0.0064 | H40: 0.0061 | I40: 0.0065 | J40: 0.0075 | K40: 0.0313 | L40: 0.09508557 | M40: 0.0935828 | N40: 0.09470727 | O40: 0.09321513 | P40: 0.09433155 | Q40: 0.09285003 | R40: 0.0939585 | S40: 0 | T40: 0 | U40: 0
A41: Esc. Deodápolis (B3) | B41: 0.0213 | C41: 0.0358 | D41: 0.026 | E41: 0.0439 | F41: 0.0111 | G41: 0.0121 | H41: 0.0113 | I41: 0.0123 | J41: 0.0181 | K41: 0.0212 | L41: 0.027707 | M41: 0.02794292 | N41: 0.02776621 | O41: 0.02800095 | P41: 0.02782513 | Q41: 0.02805869 | R41: 0.02788375 | S41: 0 | T41: 0 | U41: 0
A42: Esc. Nova Andradina (B3) | B42: 0.0121 | C42: 0.0296 | D42: 0.0159 | E42: 0.0286 | F42: 0.0122 | G42: 0.0133 | H42: 0.0125 | I42: 0.0136 | J42: 0.0137 | K42: 0.0177 | L42: 0.027707 | M42: 0.02794292 | N42: 0.02776621 | O42: 0.02800094 | P42: 0.02782513 | Q42: 0.02805869 | R42: 0.02788375 | S42: 0 | T42: 0 | U42: 0
...

Sheet Input_Consumo_GrupoA
A1: INPUT — CONSUMO ORÇADO GRUPO A | Fonte: Consumo_Orçado_2026_GD
A2: Azul = valores editáveis (fonte: arquivo fornecido) | Preto = fórmulas de projeção Y2/Y3
A3: Mês | B3: NHS FP (kWh) | C3: NHS Ponta (kWh) | D3: BAT FP (kWh) | E3: BAT Ponta (kWh) | F3: AMD FP (kWh) | G3: AMD Ponta (kWh)
A4: Jan | B4: 70769.9 | C4: 7863.3 | D4: 113967 | E4: 12663 | F4: 73973.4 | G4: 8219.3
A5: Fev | B5: 243719.7 | C5: 27080 | D5: 125874 | E5: 13986 | F5: 209472.2 | G5: 23274.7
A6: Mar | B6: 331874.1 | C6: 36874.9 | D6: 57499.2 | E6: 6388.8 | F6: 173260.2 | G6: 19251.1
A7: Abr | B7: 102778.3 | C7: 11419.8 | D7: 35640 | E7: 3960 | F7: 78448.4 | G7: 8716.5
A8: Mai | B8: 62814.2 | C8: 6979.4 | D8: 79603.2 | E8: 8844.8 | F8: 102629.5 | G8: 11403.3
A9: Jun | B9: 108694.9 | C9: 12077.2 | D9: 78336 | E9: 8704 | F9: 182444.7 | G9: 20271.6
A10: Jul | B10: 328938.1 | C10: 36548.7 | D10: 115718.4 | E10: 12857.6 | F10: 234799.2 | G10: 26088.8
A11: Ago | B11: 190977.6 | C11: 21219.7 | D11: 23364 | E11: 2596 | F11: 134799.3 | G11: 14977.7
A12: Set | B12: 126478.8 | C12: 14053.2 | D12: 10800 | E12: 1200 | F12: 18637.2 | G12: 2070.8
A13: Out | B13: 28215 | C13: 3135 | D13: 10800 | E13: 1200 | F13: 24382.8 | G13: 2709.2
A14: Nov | B14: 42209.6 | C14: 4690 | D14: 10800 | E14: 1200 | F14: 20225.7 | G14: 2247.3
A15: Dez | B15: 42209.6 | C15: 4690 | D15: 3402 | E15: 378 | F15: 17142.3 | G15: 1904.7
A17: Crescimento Y2 aplicado automaticamente via Premissas!$B$21 (atualmente 2,5%). Altere lá para que todos os 18 UCs sejam atualizados.

Sheet Simulacao
A1: ="SIMULAÇÃO RATEIO FIXO — "&Premissas!$B$13&" × COPASUL | 18 UCs | Jun/2026–Mai/2031" -> SIMULAÇÃO RATEIO FIXO — Cassilândia 03 × COPASUL | 18 UCs | Jun/2026–Mai/2031
A2: Energisa MS · Todas as células são fórmulas · Azul=input Premissas · Verde=link entre abas
A4: INDICADOR / UC | B4: TOTAL 60m ou SALDO FINAL | C4: MÉD/mês ou unidade | D4: Jun/26 | E4: Jul/26 | F4: Ago/26 | G4: Set/26 | H4: Out/26 | I4: Nov/26 | J4: Dez/26 | K4: Jan/27 | L4: Fev/27 | M4: Mar/27 | N4: Abr/27 | O4: Mai/27 | P4: Jun/27 | Q4: Jul/27 | R4: Ago/27 | S4: Set/27 | T4: Out/27 | U4: Nov/27 | V4: Dez/27 | W4: Jan/28 | X4: Fev/28 | Y4: Mar/28 | Z4: Abr/28 | AA4: Mai/28 | AB4: Jun/28 | AC4: Jul/28 | AD4: Ago/28 | AE4: Set/28 | AF4: Out/28 | AG4: Nov/28 | AH4: Dez/28 | AI4: Jan/29 | AJ4: Fev/29 | AK4: Mar/29 | AL4: Abr/29 | AM4: Mai/29 | AN4: Jun/29 | AO4: Jul/29 | AP4: Ago/29 | AQ4: Set/29 | AR4: Out/29 | AS4: Nov/29 | AT4: Dez/29 | AU4: Jan/30 | AV4: Fev/30 | AW4: Mar/30 | AX4: Abr/30 | AY4: Mai/30 | AZ4: Jun/30 | BA4: Jul/30 | BB4: Ago/30 | BC4: Set/30 | BD4: Out/30 | BE4: Nov/30 | BF4: Dez/30 | BG4: Jan/31 | BH4: Fev/31 | BI4: Mar/31 | BJ4: Abr/31 | BK4: Mai/31 | BL4: Jun/31 | BM4: Jul/31 | BN4: Ago/31 | BO4: Set/31 | BP4: Out/31 | BQ4: Nov/31 | BR4: Dez/31 | BS4: Jan/32 | BT4: Fev/32 | BU4: Mar/32 | BV4: Abr/32 | BW4: Mai/32 | BX4: Jun/32 | BY4: Jul/32 | BZ4: Ago/32 | CA4: Set/32 | CB4: Out/32 | CC4: Nov/32 | CD4: Dez/32 | CE4: Jan/33 | CF4: Fev/33 | CG4: Mar/33 | CH4: Abr/33 | CI4: Mai/33 | CJ4: Jun/33 | CK4: Jul/33 | CL4: Ago/33 | CM4: Set/33 | CN4: Out/33 | CO4: Nov/33 | CP4: Dez/33 | CQ4: Jan/34 | CR4: Fev/34 | CS4: Mar/34 | CT4: Abr/34 | CU4: Mai/34 | CV4: Jun/34 | CW4: Jul/34 | CX4: Ago/34 | CY4: Set/34 | CZ4: Out/34 | DA4: Nov/34 | DB4: Dez/34 | DC4: Jan/35 | DD4: Fev/35 | DE4: Mar/35 | DF4: Abr/35 | DG4: Mai/35 | DH4: Jun/35 | DI4: Jul/35 | DJ4: Ago/35 | DK4: Set/35 | DL4: Out/35 | DM4: Nov/35 | DN4: Dez/35 | DO4: Jan/36 | DP4: Fev/36 | DQ4: Mar/36 | DR4: Abr/36 | DS4: Mai/36
A5: ="0. "&Premissas!B13&" — GERAÇÃO E CUSTO PPA" -> 0. Cassilândia 03 — GERAÇÃO E CUSTO PPA
A6: =INDEX(PVSYST_Helexia!$A$5:$A$7,MATCH(Premissas!$B$13,PVSYST_Helexia!$B$5:$B$7,0))&" Geração P50 (kWh)" -> HCS03 Geração P50 (kWh) | B6: =SUM(D6:BQ6) -> 9214611.7 | C6: =B6/60 -> 153576.86 | D6: =Premissas!$B$61 -> 123990 | E6: =Premissas!$B$62 -> 130510 | F6: =Premissas!$B$63 -> 156670 | G6: =Premissas!$B$64 -> 147010 | H6: =Premissas!$B$65 -> 151080 | I6: =Premissas!$B$66 -> 146080 | J6: =Premissas!$B$67 -> 138710 | K6: =Premissas!$B$68 -> 142424.3 | L6: =Premissas!$B$69 -> 126912.25 | M6: =Premissas!$B$70 -> 145568.5 | N6: =Premissas!$B$71 -> 145250.1 | O6: =Premissas!$B$72 -> 135936.9 | P6: =Premissas!$B$73 -> 123370.05 | Q6: =Premissas!$B$74 -> 129857.45 | R6: =Premissas!$B$75 -> 155886.65 | S6: =Premissas!$B$76 -> 146274.95 | T6: =Premissas!$B$77 -> 150324.6 | U6: =Premissas!$B$78 -> 145349.6 | V6: =Premissas!$B$79 -> 138016.45 | W6: =Premissas!$B$80 -> 142424.3 | X6: =Premissas!$B$81 -> 126912.25 | Y6: =Premissas!$B$82 -> 145568.5 | Z6: =Premissas!$B$83 -> 145250.1 | AA6: =Premissas!$B$84 -> 135936.9 | AB6: =Premissas!$B$85 -> 122753.2 | AC6: =Premissas!$B$86 -> 129208.16 | AD6: =Premissas!$B$87 -> 155107.22 | AE6: =Premissas!$B$88 -> 145543.58 | AF6: =Premissas!$B$89 -> 149572.98 | AG6: =Premissas!$B$90 -> 144622.85 | AH6: =Premissas!$B$91 -> 137326.37 | AI6: =Premissas!$B$92 -> 141712.18 | AJ6: =Premissas!$B$93 -> 126277.69 | AK6: =Premissas!$B$94 -> 144840.66 | AL6: =Premissas!$B$95 -> 144523.85 | AM6: =Premissas!$B$96 -> 135257.22 | AN6: =Premissas!$B$97 -> 122139.43 | AO6: =Premissas!$B$98 -> 128562.12 | AP6: =Premissas!$B$99 -> 154331.68 | AQ6: =Premissas!$B$100 -> 144815.86 | AR6: =Premissas!$B$101 -> 148825.11 | AS6: =Premissas!$B$102 -> 143899.74 | AT6: =Premissas!$B$103 -> 136639.74 | AU6: =Premissas!$B$104 -> 141003.62 | AV6: =Premissas!$B$105 -> 125646.3 | AW6: =Premissas!$B$106 -> 144116.45 | AX6: =Premissas!$B$107 -> 143801.23 | AY6: =Premissas!$B$108 -> 134580.93 | AZ6: =Premissas!$B$109 -> 121528.74 | BA6: =Premissas!$B$110 -> 127919.31 | BB6: =Premissas!$B$111 -> 153560.02 | BC6: =Premissas!$B$112 -> 144091.78 | BD6: =Premissas!$B$113 -> 148080.99 | BE6: =Premissas!$B$114 -> 143180.24 | BF6: =Premissas!$B$115 -> 135956.54 | BG6: =Premissas!$B$116 -> 140298.6 | BH6: =Premissas!$B$117 -> 125018.07 | BI6: =Premissas!$B$118 -> 143395.87 | BJ6: =Premissas!$B$119 -> 143082.22 | BK6: =Premissas!$B$120 -> 133908.02 | BL6: =Premissas!$B$121 -> 120921.09 | BM6: =Premissas!$B$122 -> 127279.71 | BN6: =Premissas!$B$123 -> 152792.22 | BO6: =Premissas!$B$124 -> 143371.32 | BP6: =Premissas!$B$125 -> 147340.58 | BQ6: =Premissas!$B$126 -> 142464.34 | BR6: =Premissas!$B$127 -> 135276.75 | BS6: =Premissas!$B$128 -> 139597.11 | BT6: =Premissas!$B$129 -> 124392.98 | BU6: =Premissas!$B$130 -> 142678.89 | BV6: =Premissas!$B$131 -> 142366.81 | BW6: =Premissas!$B$132 -> 133238.48 | BX6: =Premissas!$B$133 -> 120316.49 | BY6: =Premissas!$B$134 -> 126643.32 | BZ6: =Premissas!$B$135 -> 152028.26 | CA6: =Premissas!$B$136 -> 142654.46 | CB6: =Premissas!$B$137 -> 146603.88 | CC6: =Premissas!$B$138 -> 141752.02 | CD6: =Premissas!$B$139 -> 134600.37 | CE6: =Premissas!$B$140 -> 138899.12 | CF6: =Premissas!$B$141 -> 123771.01 | CG6: =Premissas!$B$142 -> 141965.5 | CH6: =Premissas!$B$143 -> 141654.98 | CI6: =Premissas!$B$144 -> 132572.29 | CJ6: =Premissas!$B$145 -> 119714.9 | CK6: =Premissas!$B$146 -> 126010.1 | CL6: =Premissas!$B$147 -> 151268.12 | CM6: =Premissas!$B$148 -> 141941.19 | CN6: =Premissas!$B$149 -> 145870.86 | CO6: =Premissas!$B$150 -> 141043.26 | CP6: =Premissas!$B$151 -> 133927.37 | CQ6: =Premissas!$B$152 -> 138204.63 | CR6: =Premissas!$B$153 -> 123152.16 | CS6: =Premissas!$B$154 -> 141255.67 | CT6: =Premissas!$B$155 -> 140946.7 | CU6: =Premissas!$B$156 -> 131909.43 | CV6: =Premissas!$B$157 -> 119116.33 | CW6: =Premissas!$B$158 -> 125380.05 | CX6: =Premissas!$B$159 -> 150511.78 | CY6: =Premissas!$B$160 -> 141231.48 | CZ6: =Premissas!$B$161 -> 145141.51 | DA6: =Premissas!$B$162 -> 140338.04 | DB6: =Premissas!$B$163 -> 133257.73 | DC6: =Premissas!$B$164 -> 137513.6 | DD6: =Premissas!$B$165 -> 122536.4 | DE6: =Premissas!$B$166 -> 140549.39 | DF6: =Premissas!$B$167 -> 140241.97 | DG6: =Premissas!$B$168 -> 131249.88 | DH6: =Premissas!$B$169 -> 118520.75 | DI6: =Premissas!$B$170 -> 124753.15 | DJ6: =Premissas!$B$171 -> 149759.22 | DK6: =Premissas!$B$172 -> 140525.33 | DL6: =Premissas!$B$173 -> 144415.8 | DM6: =Premissas!$B$174 -> 139636.35 | DN6: =Premissas!$B$175 -> 132591.44 | DO6: =Premissas!$B$176 -> 136826.03 | DP6: =Premissas!$B$177 -> 121923.72 | DQ6: =Premissas!$B$178 -> 139846.65 | DR6: =Premissas!$B$179 -> 139540.76 | DS6: =Premissas!$B$180 -> 130593.63
A7: PPA Helexia — custo total (R$) | B7: =SUM(D7:DS7) -> 7326414.9 | C7: =B7/60 -> 122106.91 | D7: =D6*Premissas!$B$17 -> 54865.575 | E7: =E6*Premissas!$B$17 -> 57750.675 | F7: =F6*Premissas!$B$17 -> 69326.475 | G7: =G6*Premissas!$B$17 -> 65051.925 | H7: =H6*Premissas!$B$17 -> 66852.9 | I7: =I6*Premissas!$B$17 -> 64640.4 | J7: =J6*Premissas!$B$17 -> 61379.175 | K7: =K6*Premissas!$B$17 -> 63022.753 | ... DS7: =DS6*Premissas!$B$17 -> 57787.683
A8: 1. BAT — BATAYPORÃ — GERAÇÃO, CONSUMO E SURPLUS
A9: BAT Geração própria (kWh) | B9: =SUM(D9:BQ9) -> 6130080.1 | C9: =B9/60 -> 102168 | D9: =+Batayporã!I8 -> 72286.9 | E9: =+Batayporã!I9 -> 88336.8 | F9: =+Batayporã!I10 -> 93082.7 | G9: =+Batayporã!I11 -> 94433.4 | H9: =+Batayporã!I12 -> 95906.8 | I9: =+Batayporã!I13 -> 107980.6 | J9: =+Batayporã!I14 -> 106603.9 | K9: =+Batayporã!I3*(1-Premissas!$B$23) -> 113687.7 | L9: =+Batayporã!I4*(1-Premissas!$B$23) -> 90676.241 | M9: =+Batayporã!I5*(1-Premissas!$B$23) -> 102546.59 | N9: =+Batayporã!I6*(1-Premissas!$B$23) -> 73341.151 | O9: =+Batayporã!I7*(1-Premissas!$B$23) -> 91158.517 | P9: =D9*(1-Premissas!$B$23) -> 71925.465 | Q9: =E9*(1-Premissas!$B$23) -> 87895.116 | R9: =F9*(1-Premissas!$B$23) -> 92617.287 | S9: =G9*(1-Premissas!$B$23) -> 93961.233 | T9: =H9*(1-Premissas!$B$23) -> 95427.266 | U9: =I9*(1-Premissas!$B$23) -> 107440.7 | V9: =J9*(1-Premissas!$B$23) -> 106070.88 | W9: =K9*(1-Premissas!$B$23) -> 113119.27 | ... BK9: =AY9*(1-Premissas!$B$23) -> 89348.975 | BL9: =AY9*(1-Premissas!$B$23) -> 89348.975 | BM9: =AY9*(1-Premissas!$B$23) -> 89348.975 | BN9: =AY9*(1-Premissas!$B$23) -> 89348.975 | BO9: =AY9*(1-Premissas!$B$23) -> 89348.975 | BP9: =AY9*(1-Premissas!$B$23) -> 89348.975 | BQ9: =AY9*(1-Premissas!$B$23) -> 89348.975 | BR9: =AY9*(1-Premissas!$B$23) -> 89348.975 | BS9: =AY9*(1-Premissas!$B$23) -> 89348.975 | BT9: =AY9*(1-Premissas!$B$23) -> 89348.975 | BU9: =AY9*(1-Premissas!$B$23) -> 89348.975 | BV9: =AY9*(1-Premissas!$B$23) -> 89348.975 | BW9: =AY9*(1-Premissas!$B$23) -> 89348.975 | BX9: =AY9*(1-Premissas!$B$23) -> 89348.975 | BY9: =AY9*(1-Premissas!$B$23) -> 89348.975 | BZ9: =AY9*(1-Premissas!$B$23) -> 89348.975 | CA9: =AY9*(1-Premissas!$B$23) -> 89348.975 | CB9: =AY9*(1-Premissas!$B$23) -> 89348.975 | CC9: =AY9*(1-Premissas!$B$23) -> 89348.975 | CD9: =AY9*(1-Premissas!$B$23) -> 89348.975 | CE9: =AY9*(1-Premissas!$B$23) -> 89348.975 | CF9: =AY9*(1-Premissas!$B$23) -> 89348.975 | CG9: =AY9*(1-Premissas!$B$23) -> 89348.975 | CH9: =AY9*(1-Premissas!$B$23) -> 89348.975 | CI9: =AY9*(1-Premissas!$B$23) -> 89348.975 | CJ9: =AY9*(1-Premissas!$B$23) -> 89348.975 | CK9: =AY9*(1-Premissas!$B$23) -> 89348.975 | CL9: =AY9*(1-Premissas!$B$23) -> 89348.975 | CM9: =AY9*(1-Premissas!$B$23) -> 89348.975 | CN9: =AY9*(1-Premissas!$B$23) -> 89348.975 | CO9: =AY9*(1-Premissas!$B$23) -> 89348.975 | CP9: =AY9*(1-Premissas!$B$23) -> 89348.975 | CQ9: =AY9*(1-Premissas!$B$23) -> 89348.975 | CR9: =AY9*(1-Premissas!$B$23) -> 89348.975 | CS9: =AY9*(1-Premissas!$B$23) -> 89348.975 | CT9: =AY9*(1-Premissas!$B$23) -> 89348.975 | CU9: =AY9*(1-Premissas!$B$23) -> 89348.975 | CV9: =AY9*(1-Premissas!$B$23) -> 89348.975 | CW9: =AY9*(1-Premissas!$B$23) -> 89348.975 | CX9: =AY9*(1-Premissas!$B$23) -> 89348.975 | CY9: =AY9*(1-Premissas!$B$23) -> 89348.975 | CZ9: =AY9*(1-Premissas!$B$23) -> 89348.975 | DA9: =AY9*(1-Premissas!$B$23) -> 89348.975 | DB9: =AY9*(1-Premissas!$B$23) -> 89348.975 | DC9: =AY9*(1-Premissas!$B$23) -> 89348.975 | DD9: =AY9*(1-Premissas!$B$23) -> 89348.975 | DE9: =AY9*(1-Premissas!$B$23) -> 89348.975 | DF9: =AY9*(1-Premissas!$B$23) -> 89348.975 | DG9: =AY9*(1-Premissas!$B$23) -> 89348.975 | DH9: =AY9*(1-Premissas!$B$23) -> 89348.975 | DI9: =AY9*(1-Premissas!$B$23) -> 89348.975 | DJ9: =AY9*(1-Premissas!$B$23) -> 89348.975 | DK9: =AY9*(1-Premissas!$B$23) -> 89348.975 | DL9: =AY9*(1-Premissas!$B$23) -> 89348.975 | DM9: =AY9*(1-Premissas!$B$23) -> 89348.975 | DN9: =AY9*(1-Premissas!$B$23) -> 89348.975 | DO9: =AY9*(1-Premissas!$B$23) -> 89348.975 | DP9: =AY9*(1-Premissas!$B$23) -> 89348.975 | DQ9: =AY9*(1-Premissas!$B$23) -> 89348.975 | DR9: =AY9*(1-Premissas!$B$23) -> 89348.975 | DS9: =AY9*(1-Premissas!$B$23) -> 89348.975
A10: BAT Consumo FP (kWh) | B10: =SUM(D10:BQ10) -> 3825969 | C10: =B10/60 -> 63766.15 | D10: 78336 | E10: 115718 | F10: 23364 | G10: 10800 | H10: 10800 | I10: 10800 | J10: 3402 | K10: 116816 | L10: 129021 | M10: 58937 | N10: 36531 | O10: 81593 | P10: 80294 | Q10: 118611 | R10: 23948 | S10: 11070 | T10: 11070 | U10: 11070 | V10: 3487 | W10: 116816 | X10: 129021 | Y10: 58937 | Z10: 36531 | AA10: 81593 | AB10: 82302 | AC10: 121576 | AD10: 24547 | AE10: 11347 | AF10: 11347 | AG10: 11347 | AH10: 3574 | AI10: 122730 | AJ10: 135553 | AK10: 61921 | AL10: 38380 | AM10: 85724 | AN10: 84359 | AO10: 124616 | AP10: 25160 | AQ10: 11630 | AR10: 11630 | AS10: 11630 | AT10: 3664 | AU10: 125798 | AV10: 138942 | AW10: 63469 | AX10: 39340 | AY10: 87867 | AZ10: 86468 | BA10: 127731 | BB10: 25789 | BC10: 11921 | BD10: 11921 | BE10: 11921 | BF10: 3755 | BG10: 128943 | BH10: 142415 | BI10: 65055 | BJ10: 40323 | BK10: 90063 | BL10: 88630 | BM10: 130924 | BN10: 26434 | BO10: 12219 | BP10: 12219 | BQ10: 12219 | BR10: 3849 | BS10: 132167 | BT10: 145975 | BU10: 66682 | BV10: 41331 | BW10: 92315 | BX10: 90846 | BY10: 134197 | BZ10: 27095 | CA10: 12525 | CB10: 12525 | CC10: 12525 | CD10: 3945 | CE10: 135471 | CF10: 149625 | CG10: 68349 | CH10: 42365 | CI10: 94623 | CJ10: 93117 | CK10: 137552 | CL10: 27772 | CM10: 12838 | CN10: 12838 | CO10: 12838 | CP10: 4044 | CQ10: 138858 | CR10: 153365 | CS10: 70058 | CT10: 43424 | CU10: 96988 | CV10: 95445 | CW10: 140991 | CX10: 28467 | CY10: 13159 | CZ10: 13159 | DA10: 13159 | DB10: 4145 | DC10: 142329 | DD10: 157200 | DE10: 71809 | DF10: 44509 | DG10: 99413 | DH10: 97831 | DI10: 144516 | DJ10: 29178 | DK10: 13488 | DL10: 13488 | DM10: 13488 | DN10: 4249 | DO10: 145887 | DP10: 161130 | DQ10: 73604 | DR10: 45622 | DS10: 101898
A11: BAT Consumo Ponta (kWh) | B11: =SUM(D11:BQ11) -> 425119 | C11: =B11/60 -> 7085.3167 | D11: 8704 | E11: 12858 | F11: 2596 | G11: 1200 | H11: 1200 | I11: 1200 | J11: 378 | K11: 12980 | L11: 14336 | M11: 6549 | N11: 4059 | O11: 9066 | P11: 8922 | Q11: 13179 | R11: 2661 | S11: 1230 | T11: 1230 | U11: 1230 | V11: 387 | W11: 12980 | X11: 14336 | Y11: 6549 | Z11: 4059 | AA11: 9066 | AB11: 9145 | AC11: 13509 | AD11: 2727 | AE11: 1261 | AF11: 1261 | AG11: 1261 | AH11: 397 | AI11: 13637 | AJ11: 15062 | AK11: 6881 | AL11: 4264 | AM11: 9525 | AN11: 9373 | AO11: 13847 | AP11: 2796 | AQ11: 1292 | AR11: 1292 | AS11: 1292 | AT11: 407 | AU11: 13978 | AV11: 15438 | AW11: 7053 | AX11: 4371 | AY11: 9763 | AZ11: 9608 | BA11: 14193 | BB11: 2865 | BC11: 1325 | BD11: 1325 | BE11: 1325 | BF11: 417 | BG11: 14327 | BH11: 15824 | BI11: 7229 | BJ11: 4480 | BK11: 10007 | BL11: 9848 | BM11: 14548 | BN11: 2937 | BO11: 1358 | BP11: 1358 | BQ11: 1358 | BR11: 428 | BS11: 14686 | BT11: 16220 | BU11: 7410 | BV11: 4592 | BW11: 10257 | BX11: 10094 | BY11: 14911 | BZ11: 3011 | CA11: 1392 | CB11: 1392 | CC11: 1392 | CD11: 438 | CE11: 15053 | CF11: 16625 | CG11: 7595 | CH11: 4707 | CI11: 10514 | CJ11: 10346 | CK11: 15284 | CL11: 3086 | CM11: 1426 | CN11: 1426 | CO11: 1426 | CP11: 449 | CQ11: 15429 | CR11: 17041 | CS11: 7785 | CT11: 4825 | CU11: 10777 | CV11: 10605 | CW11: 15666 | CX11: 3163 | CY11: 1462 | CZ11: 1462 | DA11: 1462 | DB11: 461 | DC11: 15815 | DD11: 17467 | DE11: 7979 | DF11: 4945 | DG11: 11046 | DH11: 10870 | DI11: 16058 | DJ11: 3242 | DK11: 1499 | DL11: 1499 | DM11: 1499 | DN11: 472 | DO11: 16210 | DP11: 17904 | DQ11: 8179 | DR11: 5069 | DS11: 11322
A12: BAT auto-comp. FP (kWh) | B12: =SUM(D12:BQ12) -> 3284393.8 | C12: =B12/60 -> 54739.897 | D12: =MIN(D9,D10) -> 72286.9 | E12: =MIN(E9,E10) -> 88336.8 | F12: =MIN(F9,F10) -> 23364 | G12: =MIN(G9,G10) -> 10800 | H12: =MIN(H9,H10) -> 10800 | I12: =MIN(I9,I10) -> 10800 | J12: =MIN(J9,J10) -> 3402 | K12: =MIN(K9,K10) -> 113687.7 | ... DS12: =MIN(DS9,DS10) -> 89348.975
A13: BAT auto-comp. Ponta via FA (kWh) | B13: =SUM(D13:BQ13) -> 112680.54 | C13: =B13/60 -> 1878.009 | D13: =MIN((D9-D12)*Premissas!$B$8,D11) -> 0 | E13: =MIN((E9-E12)*Premissas!$B$8,E11) -> 0 | F13: =MIN((F9-F12)*Premissas!$B$8,F11) -> 2596 | G13: =MIN((G9-G12)*Premissas!$B$8,G11) -> 1200 | H13: =MIN((H9-H12)*Premissas!$B$8,H11) -> 1200 | I13: =MIN((I9-I12)*Premissas!$B$8,I11) -> 1200 | J13: =MIN((J9-J12)*Premissas!$B$8,J11) -> 378 | K13: =MIN((K9-K12)*Premissas!$B$8,K11) -> 0 | ... DS13: =MIN((DS9-DS12)*Premissas!$B$8,DS11) -> 0
A14: ★ BAT surplus líquido → rateio (kWh) | B14: =SUM(D14:BQ14) -> 2659211.6 | C14: =B14/60 -> 44320.193 | D14: =MAX(D9-D12-D11/Premissas!$B$8,0) -> 0 | E14: =MAX(E9-E12-E11/Premissas!$B$8,0) -> 0 | F14: =MAX(F9-F12-F11/Premissas!$B$8,0) -> 65422.586 | G14: =MAX(G9-G12-G11/Premissas!$B$8,0) -> 81647.523 | H14: =MAX(H9-H12-H11/Premissas!$B$8,0) -> 83120.923 | I14: =MAX(I9-I12-I11/Premissas!$B$8,0) -> 95194.723 | J14: =MAX(J9-J12-J11/Premissas!$B$8,0) -> 102576.35 | K14: =MAX(K9-K12-K11/Premissas!$B$8,0) -> 0 | ... DS14: =MAX(DS9-DS12-DS11/Premissas!$B$8,0) -> 0
A15: BAT banco stranded — depleção por consumo próprio apenas
A16: BAT banco início mês (kWh) | B16: =AA16 -> 582150.42 | C16: — | D16: =Premissas!$B$27 -> 906739 | E16: =D18 -> 886285.67 | F16: =E18 -> 837625.8 | G16: =F18 -> 837625.8 | H16: =G18 -> 837625.8 | I16: =H18 -> 837625.8 | J16: =I18 -> 837625.8 | K16: =J18 -> 837625.8 | L16: =K18 -> 813016.94 | ... DS16: =DR18 -> 0
A17: BAT banco draw (kWh) | B17: =SUM(D17:BQ17) -> 906739 | C17: =B17/60 -> 15112.317 | D17: =MIN(D16,MAX(D10-D12,0)+IF(Premissas!$B$8=0,0,MAX(D11-D13,0)/Premissas!$B$8)) -> 20453.327 | E17: =MIN(E16,MAX(E10-E12,0)+IF(Premissas!$B$8=0,0,MAX(E11-E13,0)/Premissas!$B$8)) -> 48659.871 | F17: =MIN(F16,MAX(F10-F12,0)+IF(Premissas!$B$8=0,0,MAX(F11-F13,0)/Premissas!$B$8)) -> 0 | G17: =MIN(G16,MAX(G10-G12,0)+IF(Premissas!$B$8=0,0,MAX(G11-G13,0)/Premissas!$B$8)) -> 0 | H17: =MIN(H16,MAX(H10-H12,0)+IF(Premissas!$B$8=0,0,MAX(H11-H13,0)/Premissas!$B$8)) -> 0 | I17: =MIN(I16,MAX(I10-I12,0)+IF(Premissas!$B$8=0,0,MAX(I11-I13,0)/Premissas!$B$8)) -> 0 | J17: =MIN(J16,MAX(J10-J12,0)+IF(Premissas!$B$8=0,0,MAX(J11-J13,0)/Premissas!$B$8)) -> 0 | K17: =MIN(K16,MAX(K10-K12,0)+IF(Premissas!$B$8=0,0,MAX(K11-K13,0)/Premissas!$B$8)) -> 24608.864 | ... DS17: =MIN(DS16,MAX(DS10-DS12,0)+IF(Premissas!$B$8=0,0,MAX(DS11-DS13,0)/Premissas!$B$8)) -> 0
A18: BAT banco fim mês (kWh) | B18: =AA18 -> 576256.85 | C18: — | D18: =MAX(D16-D17,0) -> 886285.67 | E18: =MAX(E16-E17,0) -> 837625.8 | F18: =MAX(F16-F17,0) -> 837625.8 | G18: =MAX(G16-G17,0) -> 837625.8 | H18: =MAX(H16-H17,0) -> 837625.8 | I18: =MAX(I16-I17,0) -> 837625.8 | J18: =MAX(J16-J17,0) -> 837625.8 | K18: =MAX(K16-K17,0) -> 813016.94 | ... DS18: =MAX(DS16-DS17,0) -> 0
A19: BAT créditos → NHS (kWh, T+1) | B19: =SUM(D19:BQ19) -> 1292164.5 | C19: =B19/60 -> 21536.074 | D19: =0 -> 0 | E19: =D14*Premissas!$B$55 -> 0 | F19: =E14*Premissas!$B$55 -> 0 | G19: =F14*Premissas!$B$55 -> 32711.293 | H19: =G14*Premissas!$B$55 -> 40823.762 | I19: =H14*Premissas!$B$55 -> 41560.462 | J19: =I14*Premissas!$B$55 -> 47597.362 | K19: =J14*Premissas!$B$55 -> 51288.174 | L19: =K14*Premissas!$B$55 -> 0 | ... DS19: =DR14*Premissas!$B$55 -> 17669.15
A20: BAT créditos → AMD (kWh, T+1) | B20: =SUM(D20:BQ20) -> 1292164.5 | C20: =B20/60 -> 21536.074 | D20: =0 -> 0 | E20: =D14*Premissas!$B$56 -> 0 | F20: =E14*Premissas!$B$56 -> 0 | G20: =F14*Premissas!$B$56 -> 32711.293 | H20: =G14*Premissas!$B$56 -> 40823.762 | I20: =H14*Premissas!$B$56 -> 41560.462 | J20: =I14*Premissas!$B$56 -> 47597.362 | K20: =J14*Premissas!$B$56 -> 51288.174 | L20: =K14*Premissas!$B$56 -> 0 | ... DS20: =DR14*Premissas!$B$56 -> 17669.15
A21: NHS — N. Horizonte do Sul (A4V)
A22: Consumo FP (kWh) | B22: =SUM(D22:BQ22) -> 9848843 | C22: =B22/60 -> 164147.38 | D22: 108695 | E22: 328938 | F22: 190978 | G22: 126479 | H22: 28215 | I22: 42210 | J22: 42210 | K22: 72539 | L22: 249813 | M22: 340171 | N22: 105348 | O22: 64385 | P22: 111412 | Q22: 337162 | R22: 195752 | S22: 129641 | T22: 28920 | U22: 43265 | V22: 43265 | W22: 72539 | X22: 249813 | Y22: 340171 | Z22: 105348 | AA22: 64385 | AB22: 114198 | AC22: 345590 | AD22: 200646 | AE22: 132882 | AF22: 29643 | AG22: 44347 | AH22: 44347 | AI22: 76211 | AJ22: 262460 | AK22: 357392 | AL22: 110681 | AM22: 67644 | AN22: 117053 | AO22: 354230 | AP22: 205662 | AQ22: 136204 | AR22: 30384 | AS22: 45456 | AT22: 45456 | AU22: 78117 | AV22: 269021 | AW22: 366327 | AX22: 113448 | AY22: 69336 | AZ22: 119979 | BA22: 363086 | BB22: 210804 | BC22: 139609 | BD22: 31144 | BE22: 46592 | BF22: 46592 | BG22: 80069 | BH22: 275747 | BI22: 375485 | BJ22: 116284 | BK22: 71069 | BL22: 122978 | BM22: 372163 | BN22: 216074 | BO22: 143099 | BP22: 31923 | BQ22: 47757 | BR22: 47757 | BS22: 82071 | BT22: 282640 | BU22: 384872 | BV22: 119192 | BW22: 72846 | BX22: 126053 | BY22: 381467 | BZ22: 221476 | CA22: 146677 | CB22: 32721 | CC22: 48951 | CD22: 48951 | CE22: 84123 | CF22: 289706 | CG22: 394494 | CH22: 122171 | CI22: 74667 | CJ22: 129204 | CK22: 391004 | CL22: 227013 | CM22: 150344 | CN22: 33539 | CO22: 50174 | CP22: 50174 | CQ22: 86226 | CR22: 296949 | CS22: 404356 | CT22: 125226 | CU22: 76534 | CV22: 132434 | CW22: 400779 | CX22: 232688 | CY22: 154102 | CZ22: 34377 | DA22: 51429 | DB22: 51429 | DC22: 88382 | DD22: 304373 | DE22: 414465 | DF22: 128356 | DG22: 78447 | DH22: 135745 | DI22: 410798 | DJ22: 238505 | DK22: 157955 | DL22: 35237 | DM22: 52715 | DN22: 52715 | DO22: 90591 | DP22: 311982 | DQ22: 424827 | DR22: 131565 | DS22: 80408
A23: Consumo Ponta (kWh) [via FA] | B23: =SUM(D23:BQ23) -> 1094316 | C23: =B23/60 -> 18238.6 | D23: 12077 | E23: 36549 | F23: 21220 | G23: 14053 | H23: 3135 | I23: 4690 | J23: 4690 | K23: 8060 | L23: 27757 | M23: 37797 | N23: 11705 | O23: 7154 | P23: 12379 | Q23: 37462 | R23: 21750 | S23: 14405 | T23: 3213 | U23: 4807 | V23: 4807 | W23: 8060 | X23: 27757 | Y23: 37797 | Z23: 11705 | AA23: 7154 | AB23: 12688 | AC23: 38399 | AD23: 22294 | AE23: 14764 | AF23: 3294 | AG23: 4927 | AH23: 4927 | AI23: 8468 | AJ23: 29162 | AK23: 39710 | AL23: 12298 | AM23: 7516 | AN23: 13006 | AO23: 39359 | AP23: 22852 | AQ23: 15134 | AR23: 3376 | AS23: 5051 | AT23: 5051 | AU23: 8680 | AV23: 29891 | AW23: 40703 | AX23: 12605 | AY23: 7704 | AZ23: 13331 | BA23: 40343 | BB23: 23423 | BC23: 15512 | BD23: 3460 | BE23: 5177 | BF23: 5177 | BG23: 8897 | BH23: 30639 | BI23: 41721 | BJ23: 12920 | BK23: 7897 | BL23: 13664 | BM23: 41352 | BN23: 24008 | BO23: 15900 | BP23: 3547 | BQ23: 5306 | BR23: 5306 | BS23: 9119 | BT23: 31404 | BU23: 42764 | BV23: 13243 | BW23: 8094 | BX23: 14006 | BY23: 42386 | BZ23: 24609 | CA23: 16297 | CB23: 3636 | CC23: 5439 | CD23: 5439 | CE23: 9347 | CF23: 32190 | CG23: 43833 | CH23: 13574 | CI23: 8296 | CJ23: 14356 | CK23: 43445 | CL23: 25224 | CM23: 16705 | CN23: 3727 | CO23: 5575 | CP23: 5575 | CQ23: 9581 | CR23: 32994 | CS23: 44929 | CT23: 13914 | CU23: 8504 | CV23: 14715 | CW23: 44531 | CX23: 25855 | CY23: 17122 | CZ23: 3820 | DA23: 5714 | DB23: 5714 | DC23: 9820 | DD23: 33819 | DE23: 46052 | DF23: 14261 | DG23: 8716 | DH23: 15083 | DI23: 45645 | DJ23: 26501 | DK23: 17550 | DL23: 3915 | DM23: 5857 | DN23: 5857 | DO23: 10066 | DP23: 34665 | DQ23: 47203 | DR23: 14618 | DS23: 8934
A24: Geração própria (kWh) | B24: =SUM(D24:BQ24) -> 5092260.8 | C24: =B24/60 -> 84871.013 | D24: =+'Novo Horizonte do Sul'!I8 -> 60380.6 | E24: =+'Novo Horizonte do Sul'!I9 -> 76551.2 | F24: =+'Novo Horizonte do Sul'!I10 -> 79815.6 | G24: =+'Novo Horizonte do Sul'!I11 -> 78203 | H24: =+'Novo Horizonte do Sul'!I12 -> 73160.1 | I24: =+'Novo Horizonte do Sul'!I13 -> 91030.5 | J24: =+'Novo Horizonte do Sul'!I14 -> 88631.7 | K24: =+'Novo Horizonte do Sul'!I3*(1-Premissas!$B$23) -> 83044.59 | L24: =+'Novo Horizonte do Sul'!I4*(1-Premissas!$B$23) -> 75743.778 | M24: =+'Novo Horizonte do Sul'!I5*(1-Premissas!$B$23) -> 89408.909 | N24: =+'Novo Horizonte do Sul'!I6*(1-Premissas!$B$23) -> 62411.773 | O24: =+'Novo Horizonte do Sul'!I7*(1-Premissas!$B$23) -> 77836.363 | P24: =D24*(1-Premissas!$B$23) -> 60078.697 | Q24: =E24*(1-Premissas!$B$23) -> 76168.444 | R24: =F24*(1-Premissas!$B$23) -> 79416.522 | S24: =G24*(1-Premissas!$B$23) -> 77811.985 | T24: =H24*(1-Premissas!$B$23) -> 72794.299 | U24: =I24*(1-Premissas!$B$23) -> 90575.348 | V24: =J24*(1-Premissas!$B$23) -> 88188.541 | W24: =K24*(1-Premissas!$B$23) -> 82629.368 | ... BK24: =AY24*(1-Premissas!$B$23) -> 76291.272 | BL24: =AY24*(1-Premissas!$B$23) -> 76291.272 | BM24: =AY24*(1-Premissas!$B$23) -> 76291.272 | BN24: =AY24*(1-Premissas!$B$23) -> 76291.272 | BO24: =AY24*(1-Premissas!$B$23) -> 76291.272 | BP24: =AY24*(1-Premissas!$B$23) -> 76291.272 | BQ24: =AY24*(1-Premissas!$B$23) -> 76291.272 | BR24: =AY24*(1-Premissas!$B$23) -> 76291.272 | BS24: =AY24*(1-Premissas!$B$23) -> 76291.272 | BT24: =AY24*(1-Premissas!$B$23) -> 76291.272 | BU24: =AY24*(1-Premissas!$B$23) -> 76291.272 | BV24: =AY24*(1-Premissas!$B$23) -> 76291.272 | BW24: =AY24*(1-Premissas!$B$23) -> 76291.272 | BX24: =AY24*(1-Premissas!$B$23) -> 76291.272 | BY24: =AY24*(1-Premissas!$B$23) -> 76291.272 | BZ24: =AY24*(1-Premissas!$B$23) -> 76291.272 | CA24: =AY24*(1-Premissas!$B$23) -> 76291.272 | CB24: =AY24*(1-Premissas!$B$23) -> 76291.272 | CC24: =AY24*(1-Premissas!$B$23) -> 76291.272 | CD24: =AY24*(1-Premissas!$B$23) -> 76291.272 | CE24: =AY24*(1-Premissas!$B$23) -> 76291.272 | CF24: =AY24*(1-Premissas!$B$23) -> 76291.272 | CG24: =AY24*(1-Premissas!$B$23) -> 76291.272 | CH24: =AY24*(1-Premissas!$B$23) -> 76291.272 | CI24: =AY24*(1-Premissas!$B$23) -> 76291.272 | CJ24: =AY24*(1-Premissas!$B$23) -> 76291.272 | CK24: =AY24*(1-Premissas!$B$23) -> 76291.272 | CL24: =AY24*(1-Premissas!$B$23) -> 76291.272 | CM24: =AY24*(1-Premissas!$B$23) -> 76291.272 | CN24: =AY24*(1-Premissas!$B$23) -> 76291.272 | CO24: =AY24*(1-Premissas!$B$23) -> 76291.272 | CP24: =AY24*(1-Premissas!$B$23) -> 76291.272 | CQ24: =AY24*(1-Premissas!$B$23) -> 76291.272 | CR24: =AY24*(1-Premissas!$B$23) -> 76291.272 | CS24: =AY24*(1-Premissas!$B$23) -> 76291.272 | CT24: =AY24*(1-Premissas!$B$23) -> 76291.272 | CU24: =AY24*(1-Premissas!$B$23) -> 76291.272 | CV24: =AY24*(1-Premissas!$B$23) -> 76291.272 | CW24: =AY24*(1-Premissas!$B$23) -> 76291.272 | CX24: =AY24*(1-Premissas!$B$23) -> 76291.272 | CY24: =AY24*(1-Premissas!$B$23) -> 76291.272 | CZ24: =AY24*(1-Premissas!$B$23) -> 76291.272 | DA24: =AY24*(1-Premissas!$B$23) -> 76291.272 | DB24: =AY24*(1-Premissas!$B$23) -> 76291.272 | DC24: =AY24*(1-Premissas!$B$23) -> 76291.272 | DD24: =AY24*(1-Premissas!$B$23) -> 76291.272 | DE24: =AY24*(1-Premissas!$B$23) -> 76291.272 | DF24: =AY24*(1-Premissas!$B$23) -> 76291.272 | DG24: =AY24*(1-Premissas!$B$23) -> 76291.272 | DH24: =AY24*(1-Premissas!$B$23) -> 76291.272 | DI24: =AY24*(1-Premissas!$B$23) -> 76291.272 | DJ24: =AY24*(1-Premissas!$B$23) -> 76291.272 | DK24: =AY24*(1-Premissas!$B$23) -> 76291.272 | DL24: =AY24*(1-Premissas!$B$23) -> 76291.272 | DM24: =AY24*(1-Premissas!$B$23) -> 76291.272 | DN24: =AY24*(1-Premissas!$B$23) -> 76291.272 | DO24: =AY24*(1-Premissas!$B$23) -> 76291.272 | DP24: =AY24*(1-Premissas!$B$23) -> 76291.272 | DQ24: =AY24*(1-Premissas!$B$23) -> 76291.272 | DR24: =AY24*(1-Premissas!$B$23) -> 76291.272 | DS24: =AY24*(1-Premissas!$B$23) -> 76291.272
A25: Auto-comp. FP (kWh) | B25: =SUM(D25:BQ25) -> 4279763.9 | C25: =B25/60 -> 71329.399 | D25: =MIN(D24,D22) -> 60380.6 | E25: =MIN(E24,E22) -> 76551.2 | F25: =MIN(F24,F22) -> 79815.6 | G25: =MIN(G24,G22) -> 78203 | H25: =MIN(H24,H22) -> 28215 | I25: =MIN(I24,I22) -> 42210 | J25: =MIN(J24,J22) -> 42210 | K25: =MIN(K24,K22) -> 72539 | ... DS25: =MIN(DS24,DS22) -> 76291.272
A26: Auto-comp. Ponta via FA (kWh) | B26: =SUM(D26:BQ26) -> 121327.66 | C26: =B26/60 -> 2022.1277 | D26: =MIN((D24-D25)*Premissas!$B$8,D23) -> 0 | E26: =MIN((E24-E25)*Premissas!$B$8,E23) -> 0 | F26: =MIN((F24-F25)*Premissas!$B$8,F23) -> 0 | G26: =MIN((G24-G25)*Premissas!$B$8,G23) -> 0 | H26: =MIN((H24-H25)*Premissas!$B$8,H23) -> 3135 | I26: =MIN((I24-I25)*Premissas!$B$8,I23) -> 4690 | J26: =MIN((J24-J25)*Premissas!$B$8,J23) -> 4690 | K26: =MIN((K24-K25)*Premissas!$B$8,K23) -> 6348.1822 | ... DS26: =MIN((DS24-DS25)*Premissas!$B$8,DS23) -> 0
A27: =" "&INDEX(PVSYST_Helexia!$A$5:$A$7,MATCH(Premissas!$B$13,PVSYST_Helexia!$B$5:$B$7,0))&" créditos recebidos (kWh)" -> HCS03 créditos recebidos (kWh) | B27: =SUM(D27:BQ27) -> 4204514.9 | C27: =B27/60 -> 70075.248 | D27: =D6*Premissas!$B$33 -> 91504.62 | E27: =E6*Premissas!$B$33 -> 96316.38 | F27: =F6*Premissas!$B$33 -> 115622.46 | G27: =G6*Premissas!$B$33 -> 108493.38 | H27: =H6*Premissas!$C$33 -> 78229.224 | I27: =I6*Premissas!$C$33 -> 75640.224 | J27: =J6*Premissas!$C$33 -> 71824.038 | K27: =K6*Premissas!$C$33 -> 73747.303 | L27: =L6*Premissas!$C$33 -> 65715.163 | M27: =M6*Premissas!$C$33 -> 75375.369 | N27: =N6*Premissas!$D$33 -> 97520.917 | O27: =O6*Premissas!$D$33 -> 91268.035 | P27: =P6*Premissas!$D$33 -> 82830.652 | Q27: =Q6*Premissas!$D$33 -> 87186.292 | R27: =R6*Premissas!$D$33 -> 104662.3 | S27: =S6*Premissas!$D$33 -> 98209.001 | T27: =T6*Premissas!$E$33 -> 38964.136 | U27: =U6*Premissas!$E$33 -> 37674.616 | V27: =V6*Premissas!$E$33 -> 35773.864 | W27: =W6*Premissas!$E$33 -> 36916.379 | X27: =X6*Premissas!$E$33 -> 32895.655 | Y27: =Y6*Premissas!$E$33 -> 37731.355 | Z27: =Z6*Premissas!$E$33 -> 37648.826 | AA27: =AA6*Premissas!$E$33 -> 35234.844 | AB27: =AB6*Premissas!$F$33 -> 58197.292 | AC27: =AC6*Premissas!$F$33 -> 61257.59 | AD27: =AD6*Premissas!$F$33 -> 73536.331 | AE27: =AE6*Premissas!$F$33 -> 69002.209 | AF27: =AF6*Premissas!$F$33 -> 70912.548 | AG27: =AG6*Premissas!$F$33 -> 68565.694 | AH27: =AH6*Premissas!$G$33 -> 64172.612 | AI27: =AI6*Premissas!$G$33 -> 66222.101 | AJ27: =AJ6*Premissas!$G$33 -> 59009.564 | AK27: =AK6*Premissas!$G$33 -> 67684.039 | AL27: =AL6*Premissas!$G$33 -> 67535.995 | AM27: =AM6*Premissas!$G$33 -> 63205.697 | AN27: =AN6*Premissas!$H$33 -> 57698.669 | AO27: =AO6*Premissas!$H$33 -> 60732.746 | AP27: =AP6*Premissas!$H$33 -> 72906.286 | AQ27: =AQ6*Premissas!$H$33 -> 68411.011 | AR27: =AR6*Premissas!$H$33 -> 70304.983 | AS27: =AS6*Premissas!$H$33 -> 67978.236 | AT27: =AT6*Premissas!$I$33 -> 63619.461 | AU27: =AU6*Premissas!$I$33 -> 65651.284 | AV27: =AV6*Premissas!$I$33 -> 58500.917 | AW27: =AW6*Premissas!$I$33 -> 67100.621 | AX27: =AX6*Premissas!$I$33 -> 66953.853 | AY27: =AY6*Premissas!$I$33 -> 62660.881 | AZ27: =AZ6*Premissas!$J$33 -> 70802.642 | BA27: =BA6*Premissas!$J$33 -> 74525.791 | BB27: =BB6*Premissas!$J$33 -> 89464.069 | BC27: =BC6*Premissas!$J$33 -> 83947.87 | BD27: =BD6*Premissas!$J$33 -> 86271.983 | BE27: =BE6*Premissas!$J$33 -> 83416.807 | BF27: =BF6*Premissas!$K$33 -> 62825.516 | BG27: =BG6*Premissas!$K$33 -> 64831.983 | BH27: =BH6*Premissas!$K$33 -> 57770.85 | BI27: =BI6*Premissas!$K$33 -> 66263.232 | BJ27: =BJ6*Premissas!$K$33 -> 66118.296 | BK27: =BK6*Premissas!$K$33 -> 61878.898 | BL27: =BL6*Premissas!$L$33 -> 8348.4261 | BM27: =BM6*Premissas!$L$33 -> 8787.4271 | BN27: =BN6*Premissas!$L$33 -> 10548.818 | BO27: =BO6*Premissas!$L$33 -> 9898.396 | BP27: =BP6*Premissas!$L$33 -> 10172.435 | BQ27: =BQ6*Premissas!$L$33 -> 9835.7778 | BR27: =BR6*Premissas!$M$33 -> 9584.8221 | BS27: =BS6*Premissas!$M$33 -> 9890.9338 | BT27: =BT6*Premissas!$M$33 -> 8813.6692 | BU27: =BU6*Premissas!$M$33 -> 10109.289 | BV27: =BV6*Premissas!$M$33 -> 10087.177 | BW27: =BW6*Premissas!$M$33 -> 9440.4036 | BX27: =BX6*Premissas!$N$33 -> 8360.9046 | BY27: =BY6*Premissas!$N$33 -> 8800.5618 | BZ27: =BZ6*Premissas!$N$33 -> 10564.585 | CA27: =CA6*Premissas!$N$33 -> 9913.1913 | CB27: =CB6*Premissas!$N$33 -> 10187.64 | CC27: =CC6*Premissas!$N$33 -> 9850.4794 | CD27: =CD6*Premissas!$O$33 -> 9597.911 | CE27: =CE6*Premissas!$O$33 -> 9904.4407 | CF27: =CF6*Premissas!$O$33 -> 8825.705 | CG27: =CG6*Premissas!$O$33 -> 10123.094 | CH27: =CH6*Premissas!$O$33 -> 10100.952 | CI27: =CI6*Premissas!$O$33 -> 9453.2953 | CJ27: =CJ6*Premissas!$P$33 -> 8373.1334 | CK27: =CK6*Premissas!$P$33 -> 8813.4337 | CL27: =CL6*Premissas!$P$33 -> 10580.037 | CM27: =CM6*Premissas!$P$33 -> 9927.6905 | CN27: =CN6*Premissas!$P$33 -> 10202.54 | CO27: =CO6*Premissas!$P$33 -> 9864.8869 | CP27: =CP6*Premissas!$Q$33 -> 9610.7097 | CQ27: =CQ6*Premissas!$Q$33 -> 9917.6482 | CR27: =CR6*Premissas!$Q$33 -> 8837.474 | CS27: =CS6*Premissas!$Q$33 -> 10136.593 | CT27: =CT6*Premissas!$Q$33 -> 10114.421 | CU27: =CU6*Premissas!$Q$33 -> 9465.9012 | CV27: =CV6*Premissas!$R$33 -> 8385.1047 | CW27: =CW6*Premissas!$R$33 -> 8826.0345 | CX27: =CX6*Premissas!$R$33 -> 10595.164 | CY27: =CY6*Premissas!$R$33 -> 9941.8844 | CZ27: =CZ6*Premissas!$R$33 -> 10217.127 | DA27: =DA6*Premissas!$R$33 -> 9878.9911 | DB27: =DB6*Premissas!$S$33 -> 43975.052 | DC27: =DC6*Premissas!$S$33 -> 45379.489 | DD27: =DD6*Premissas!$S$33 -> 40437.011 | DE27: =DE6*Premissas!$S$33 -> 46381.299 | DF27: =DF6*Premissas!$S$33 -> 46279.85 | DG27: =DG6*Premissas!$S$33 -> 43312.462 | DH27: =DH6*Premissas!$T$33 -> 39111.847 | DI27: =DI6*Premissas!$T$33 -> 41168.539 | DJ27: =DJ6*Premissas!$T$33 -> 49420.543 | DK27: =DK6*Premissas!$T$33 -> 46373.358 | DL27: =DL6*Premissas!$T$33 -> 47657.213 | DM27: =DM6*Premissas!$T$33 -> 46079.995 | DN27: =DN6*Premissas!$U$33 -> 43755.176 | DO27: =DO6*Premissas!$U$33 -> 45152.591 | DP27: =DP6*Premissas!$U$33 -> 40234.826 | DQ27: =DQ6*Premissas!$U$33 -> 46149.393 | DR27: =DR6*Premissas!$U$33 -> 46048.451 | DS27: =DS6*Premissas!$U$33 -> 43095.899
A28: BAT créditos → NHS (kWh) | B28: =SUM(D28:BQ28) -> 1292164.5 | C28: =B28/60 -> 21536.074 | D28: =D19 -> 0 | E28: =E19 -> 0 | F28: =F19 -> 0 | G28: =G19 -> 32711.293 | H28: =H19 -> 40823.762 | I28: =I19 -> 41560.462 | J28: =J19 -> 47597.362 | K28: =K19 -> 51288.174 | ... DS28: =DS19 -> 17669.15
A29: Banco início mês COM Helexia (kWh) | B29: =AA29 -> 262411.49 | C29: — | D29: =Premissas!$B$26 -> 148516 | E29: =D31 -> 171720.02 | F29: =E31 -> 0 | G29: =F31 -> 4460.06 | H29: =G31 -> 92928.673 | I29: =H31 -> 256926.76 | J29: =I31 -> 422947.94 | K29: =J31 -> 588791.04 | L29: =K31 -> 721499.23 | ... DS29: =DR31 -> 1104.7843
A30: Bank draw COM Helexia (kWh) | B30: =SUM(D30:BQ30) -> 4016807.2 | C30: =B30/60 -> 66946.786 | D30: =MIN(D29,MAX(D22-D24-D27+D28,0)+IF(Premissas!$B$8=0,0,MAX(D23-D26,0)/Premissas!$B$8)) -> 19986.197 | E30: =MIN(E29,MAX(E22-E24-E27+E28,0)+IF(Premissas!$B$8=0,0,MAX(E23-E26,0)/Premissas!$B$8)) -> 171720.02 | F30: =MIN(F29,MAX(F22-F24-F27+F28,0)+IF(Premissas!$B$8=0,0,MAX(F23-F26,0)/Premissas!$B$8)) -> 0 | G30: =MIN(G29,MAX(G22-G24-G27+G28,0)+IF(Premissas!$B$8=0,0,MAX(G23-G26,0)/Premissas!$B$8)) -> 4460.06 | H30: =MIN(H29,MAX(H22-H24-H27+H28,0)+IF(Premissas!$B$8=0,0,MAX(H23-H26,0)/Premissas!$B$8)) -> 0 | I30: =MIN(I29,MAX(I22-I24-I27+I28,0)+IF(Premissas!$B$8=0,0,MAX(I23-I26,0)/Premissas!$B$8)) -> 0 | J30: =MIN(J29,MAX(J22-J24-J27+J28,0)+IF(Premissas!$B$8=0,0,MAX(J23-J26,0)/Premissas!$B$8)) -> 0 | K30: =MIN(K29,MAX(K22-K24-K27+K28,0)+IF(Premissas!$B$8=0,0,MAX(K23-K26,0)/Premissas!$B$8)) -> 2832.883 | ... DS30: =MIN(DS29,MAX(DS22-DS24-DS27+DS28,0)+IF(Premissas!$B$8=0,0,MAX(DS23-DS26,0)/Premissas!$B$8)) -> 1104.7843
A31: ★ Banco fim mês COM Helexia (kWh) | B31: =AA31 -> 325571.63 | C31: — | D31: =MAX(D29-D30,0)+D28+MAX(D27-MAX(D22-D24,0),0)+MAX(D24-D22,0) -> 171720.02 | E31: =MAX(E29-E30,0)+E28+MAX(E27-MAX(E22-E24,0),0)+MAX(E24-E22,0) -> 0 | F31: =MAX(F29-F30,0)+F28+MAX(F27-MAX(F22-F24,0),0)+MAX(F24-F22,0) -> 4460.06 | G31: =MAX(G29-G30,0)+G28+MAX(G27-MAX(G22-G24,0),0)+MAX(G24-G22,0) -> 92928.673 | H31: =MAX(H29-H30,0)+H28+MAX(H27-MAX(H22-H24,0),0)+MAX(H24-H22,0) -> 256926.76 | I31: =MAX(I29-I30,0)+I28+MAX(I27-MAX(I22-I24,0),0)+MAX(I24-I22,0) -> 422947.94 | J31: =MAX(J29-J30,0)+J28+MAX(J27-MAX(J22-J24,0),0)+MAX(J24-J22,0) -> 588791.04 | K31: =MAX(K29-K30,0)+K28+MAX(K27-MAX(K22-K24,0),0)+MAX(K24-K22,0) -> 721499.23 | ... DS31: =MAX(DS29-DS30,0)+DS28+MAX(DS27-MAX(DS22-DS24,0),0)+MAX(DS24-DS22,0) -> 56648.321
A32: Banco início mês SEM Helexia (kWh) | B32: =AA32 -> 16129.467 | C32: — | D32: =Premissas!$B$26 -> 148516 | E32: =D34 -> 80215.403 | F32: =E34 -> 0 | G32: =F34 -> 0 | H32: =G34 -> 32711.293 | I32: =H34 -> 118480.15 | J32: =I34 -> 208861.12 | K32: =J34 -> 302880.18 | L32: =K34 -> 364673.94 | ... DS32: =DR34 -> 1104.7843
A33: Bank draw SEM Helexia (kWh) — gen+BAT, no CS3 | B33: =SUM(D33:BQ33) -> 2076364.8 | C33: =B33/60 -> 34606.081 | D33: =MIN(D32,MAX(D22-D24-D28,0)+IF(Premissas!$B$8=0,0,MAX(D23-D26-(IF(Premissas!$B$8>0,MAX(D24-D22,0)*Premissas!$B$8,0)),0)/Premissas!$B$8)) -> 68300.597 | E33: =MIN(E32,MAX(E22-E24-E28,0)+IF(Premissas!$B$8=0,0,MAX(E23-E26-(IF(Premissas!$B$8>0,MAX(E24-E22,0)*Premissas!$B$8,0)),0)/Premissas!$B$8)) -> 80215.403 | F33: =MIN(F32,MAX(F22-F24-F28,0)+IF(Premissas!$B$8=0,0,MAX(F23-F26-(IF(Premissas!$B$8>0,MAX(F24-F22,0)*Premissas!$B$8,0)),0)/Premissas!$B$8)) -> 0 | G33: =MIN(G32,MAX(G22-G24-G28,0)+IF(Premissas!$B$8=0,0,MAX(G23-G26-(IF(Premissas!$B$8>0,MAX(G24-G22,0)*Premissas!$B$8,0)),0)/Premissas!$B$8)) -> 0 | H33: =MIN(H32,MAX(H22-H24-H28,0)+IF(Premissas!$B$8=0,0,MAX(H23-H26-(IF(Premissas!$B$8>0,MAX(H24-H22,0)*Premissas!$B$8,0)),0)/Premissas!$B$8)) -> 0 | I33: =MIN(I32,MAX(I22-I24-I28,0)+IF(Premissas!$B$8=0,0,MAX(I23-I26-(IF(Premissas!$B$8>0,MAX(I24-I22,0)*Premissas!$B$8,0)),0)/Premissas!$B$8)) -> 0 | J33: =MIN(J32,MAX(J22-J24-J28,0)+IF(Premissas!$B$8=0,0,MAX(J23-J26-(IF(Premissas!$B$8>0,MAX(J24-J22,0)*Premissas!$B$8,0)),0)/Premissas!$B$8)) -> 0 | K33: =MIN(K32,MAX(K22-K24-K28,0)+IF(Premissas!$B$8=0,0,MAX(K23-K26-(IF(Premissas!$B$8>0,MAX(K24-K22,0)*Premissas!$B$8,0)),0)/Premissas!$B$8)) -> 0 | ... AA33: =MIN(AA32,MAX(AA22-AA24-AA28,0)+IF(Premissas!$B$8=0,0,MAX(AA23-AA26-(IF(Premissas!$B$8>0,MAX(AA24-AA22,0)*Premissas!$B$8,0)),0)/Premissas!$B$8)) -> 0 | AB33: =MIN(AB32,MAX(AB22-AB24-AB28,0)+IF(Premissas!$B$8=0,0,MAX(AB23-AB26-(IF(Premissas!$B$8>0,MAX(AB24-AB22,0),0))*Premissas!$B$8,0)/Premissas!$B$8)) -> 44054.756 | AC33: =MIN(AC32,MAX(AC22-AC24-AC28,0)+IF(Premissas!$B$8=0,0,MAX(AC23-AC26-(IF(Premissas!$B$8>0,MAX(AC24-AC22,0),0))*Premissas!$B$8,0)/Premissas!$B$8)) -> 0 | AD33: =MIN(AD32,MAX(AD22-AD24-AD28,0)+IF(Premissas!$B$8=0,0,MAX(AD23-AD26-(IF(Premissas!$B$8>0,MAX(AD24-AD22,0),0))*Premissas!$B$8,0)/Premissas!$B$8)) -> 0 | AE33: =MIN(AE32,MAX(AE22-AE24-AE28,0)+IF(Premissas!$B$8=0,0,MAX(AE23-AE26-(IF(Premissas!$B$8>0,MAX(AE24-AE22,0),0))*Premissas!$B$8,0)/Premissas!$B$8)) -> 0 | AF33: =MIN(AF32,MAX(AF22-AF24-AF28,0)+IF(Premissas!$B$8=0,0,MAX(AF23-AF26-(IF(Premissas!$B$8>0,MAX(AF24-AF22,0),0))*Premissas!$B$8,0)/Premissas!$B$8)) -> 0 | AG33: =MIN(AG32,MAX(AG22-AG24-AG28,0)+IF(Premissas!$B$8=0,0,MAX(AG23-AG26-(IF(Premissas!$B$8>0,MAX(AG24-AG22,0),0))*Premissas!$B$8,0)/Premissas!$B$8)) -> 0 | AH33: =MIN(AH32,MAX(AH22-AH24-AH28,0)+IF(Premissas!$B$8=0,0,MAX(AH23-AH26-(IF(Premissas!$B$8>0,MAX(AH24-AH22,0),0))*Premissas!$B$8,0)/Premissas!$B$8)) -> 0 | AI33: =MIN(AI32,MAX(AI22-AI24-AI28,0)+IF(Premissas!$B$8=0,0,MAX(AI23-AI26-(IF(Premissas!$B$8>0,MAX(AI24-AI22,0),0))*Premissas!$B$8,0)/Premissas!$B$8)) -> 2003.2302 | ... DS33: =MIN(DS32,MAX(DS22-DS24-DS28,0)+IF(Premissas!$B$8=0,0,MAX(DS23-DS26-(IF(Premissas!$B$8>0,MAX(DS24-DS22,0),0))*Premissas!$B$8,0)/Premissas!$B$8)) -> 1104.7843
A34: Banco fim mês SEM Helexia (kWh) — gen+BAT, no CS3 | B34: =AA34 -> 44054.756 | C34: — | D34: =MAX(D32-D33,0)+D28+MAX(D24-D22,0) -> 80215.403 | E34: =MAX(E32-E33,0)+E28+MAX(E24-E22,0) -> 0 | F34: =MAX(F32-F33,0)+F28+MAX(F24-F22,0) -> 0 | G34: =MAX(G32-G33,0)+G28+MAX(G24-G22,0) -> 32711.293 | H34: =MAX(H32-H33,0)+H28+MAX(H24-H22,0) -> 118480.15 | I34: =MAX(I32-I33,0)+I28+MAX(I24-I22,0) -> 208861.12 | J34: =MAX(J32-J33,0)+J28+MAX(J24-J22,0) -> 302880.18 | K34: =MAX(K32-K33,0)+K28+MAX(K24-K22,0) -> 364673.94 | ... DS34: =MAX(DS32-DS33,0)+DS28+MAX(DS24-DS22,0) -> 17669.15
A35: =" Custo SEM Helexia (R$) — só gen própria, sem "&INDEX(PVSYST_Helexia!$A$5:$A$7,MATCH(Premissas!$B$13,PVSYST_Helexia!$B$5:$B$7,0))&"/BAT/banco" -> Custo SEM Helexia (R$) — só gen própria, sem HCS03/BAT/banco | B35: =SUM(D35:BQ35) -> 3557430.3 | C35: =B35/60 -> 59290.505 | D35: =IF(D34>0,0,MAX(D22-D24-D28-D32,0)*Premissas!$B$5+MAX(D23-D26-(IF(Premissas!$B$8>0,MAX(D24+D28+D32-D22,0)*Premissas!$B$8,0)),0)*Premissas!$B$6) -> 0 | E35: =IF(E34>0,0,MAX(E22-E24-E28-E32,0)*Premissas!$B$5+MAX(E23-E26-(IF(Premissas!$B$8>0,MAX(E24+E28+E32-E22,0)*Premissas!$B$8,0)),0)*Premissas!$B$6) -> 199280.76 | F35: =IF(F34>0,0,MAX(F22-F24-F28-F32,0)*Premissas!$B$5+MAX(F23-F26-(IF(Premissas!$B$8>0,MAX(F24+F28+F32-F22,0)*Premissas!$B$8,0)),0)*Premissas!$B$6) -> 121597.68 | G35: =IF(G34>0,0,MAX(G22-G24-G28-G32,0)*Premissas!$B$5+MAX(G23-G26-(IF(Premissas!$B$8>0,MAX(G24+G28+G32-G22,0)*Premissas!$B$8,0)),0)*Premissas!$B$6) -> 0 | H35: =IF(H34>0,0,MAX(H22-H24-H28-H32,0)*Premissas!$B$5+MAX(H23-H26-(IF(Premissas!$B$8>0,MAX(H24+H28+H32-H22,0)*Premissas!$B$8,0)),0)*Premissas!$B$6) -> 0 | I35: =IF(I34>0,0,MAX(I22-I24-I28-I32,0)*Premissas!$B$5+MAX(I23-I26-(IF(Premissas!$B$8>0,MAX(I24+I28+I32-I22,0)*Premissas!$B$8,0)),0)*Premissas!$B$6) -> 0 | J35: =IF(J34>0,0,MAX(J22-J24-J28-J32,0)*Premissas!$B$5+MAX(J23-J26-(IF(Premissas!$B$8>0,MAX(J24+J28+J32-J22,0)*Premissas!$B$8,0)),0)*Premissas!$B$6) -> 0 | K35: =IF(K34>0,0,MAX(K22-K24-K28-K32,0)*Premissas!$B$5+MAX(K23-K26-(IF(Premissas!$B$8>0,MAX(K24+K28+K32-K22,0)*Premissas!$B$8,0)),0)*Premissas!$B$6) -> 0 | ... AA35: =IF(AA34>0,0,MAX(AA22-AA24-AA28-AA32,0)*Premissas!$B$5+MAX(AA23-AA26-(IF(Premissas!$B$8>0,MAX(AA24+AA28+AA32-AA22,0)*Premissas!$B$8,0)),0)*Premissas!$B$6) -> 0 | AB35: =IF(AB34>0,0,MAX(AB22-AB24-AB28-AB32,0)*Premissas!$B$5+MAX(AB23-AB26-(IF(Premissas!$B$8>0,MAX(AB24+AB26-AB22-AB23,0)*Premissas!$B$8,0)),0)*Premissas!$B$6) -> 43170.391 | AC35: =IF(AC34>0,0,MAX(AC22-AC24-AC28-AC32,0)*Premissas!$B$5+MAX(AC23-AC26-(IF(Premissas!$B$8>0,MAX(AC24+AC26-AC22-AC23,0)*Premissas!$B$8,0)),0)*Premissas!$B$6) -> 256179.57 | AD35: =IF(AD34>0,0,MAX(AD22-AD24-AD28-AD32,0)*Premissas!$B$5+MAX(AD23-AD26-(IF(Premissas!$B$8>0,MAX(AD24+AD26-AD22-AD23,0)*Premissas!$B$8,0)),0)*Premissas!$B$6) -> 130299.1 | AE35: =IF(AE34>0,0,MAX(AE22-AE24-AE28-AE32,0)*Premissas!$B$5+MAX(AE23-AE26-(IF(Premissas!$B$8>0,MAX(AE24+AE26-AE22-AE23,0)*Premissas!$B$8,0)),0)*Premissas!$B$6) -> 0 | AF35: =IF(AF34>0,0,MAX(AF22-AF24-AF28-AF32,0)*Premissas!$B$5+MAX(AF23-AF26-(IF(Premissas!$B$8>0,MAX(AF24+AF26-AF22-AF23,0)*Premissas!$B$8,0)),0)*Premissas!$B$6) -> 0 | AG35: =IF(AG34>0,0,MAX(AG22-AG24-AG28-AG32,0)*Premissas!$B$5+MAX(AG23-AG26-(IF(Premissas!$B$8>0,MAX(AG24+AG26-AG22-AG23,0)*Premissas!$B$8,0)),0)*Premissas!$B$6) -> 0 | AH35: =IF(AH34>0,0,MAX(AH22-AH24-AH28-AH32,0)*Premissas!$B$5+MAX(AH23-AH26-(IF(Premissas!$B$8>0,MAX(AH24+AH26-AH22-AH23,0)*Premissas!$B$8,0)),0)*Premissas!$B$6) -> 0 | AI35: =IF(AI34>0,0,MAX(AI22-AI24-AI28-AI32,0)*Premissas!$B$5+MAX(AI23-AI26-(IF(Premissas!$B$8>0,MAX(AI24+AI26-AI22-AI23,0)*Premissas!$B$8,0)),0)*Premissas!$B$6) -> 0 | ... DS35: =IF(DS34>0,0,MAX(DS22-DS24-DS28-DS32,0)*Premissas!$B$5+MAX(DS23-DS26-(IF(Premissas!$B$8>0,MAX(DS24+DS26-DS22-DS23,0)*Premissas!$B$8,0)),0)*Premissas!$B$6) -> 0
